
# Created by Ruins mod version 16.7 Ingame Parser
# authoring Player: lafuller

weight=1
embed_into_distance=4
acceptable_target_blocks=
unacceptable_target_blocks=flowing_water,water,flowing_lava,lava,ice,bedrock,netherrack,nether_brick,nether_brick_fence,soul_sand,quartz_ore,end_stone,obsidian,iron_bars,cloud,flesh,ash_block,slime_grass,slime_congealed,slime_dirt
biomesToSpawnIn=plains,prarie,meadow,tundra,brushland,shrubland,woodland,woodlands,lavender_fields,flower_field,sunflower_plains,ice_flats,ice_plains
dimensions=18,16,17
allowable_overhang=0
max_leveling=4
leveling_buffer=-1
preserve_water=0
preserve_lava=0

rule1=0,100,preserveBlock
rule2=0,100,minecraft:stone-6
rule3=0,100,stonebrick-0,stonebrick-0,stonebrick-0,stonebrick-0,stonebrick-1,stonebrick-2,stonebrick-2,stone-5,stone-6,cobblestone
rule4=0,100,stonebrick-0,stonebrick-2,stonebrick-2,stonebrick-2,stonebrick-1,cobblestone
rule5=0,100,stonebrick-0,stonebrick-1,stonebrick-2,stonebrick-2,stone-5,stone-5,stone-6,stone-6
rule6=0,100,stonebrick-0,stonebrick-2,stonebrick-0,stonebrick-1,stonebrick-1,cobblestone
rule7=0,100,minecraft:stone_brick_stairs-0
rule8=0,100,minecraft:dirt-0
rule9=0,100,minecraft:stone_brick_stairs-3
rule10=0,100,stonebrick-0,stonebrick-0,stonebrick-0,stonebrick-0,stonebrick-1,stonebrick-2,stonebrick-2,stone-5,stone-6,cobblestone,gravel
rule11=0,100,minecraft:cobblestone_wall-0
rule12=0,100,minecraft:wooden_slab-1
rule13=0,100,minecraft:spruce_stairs-2
rule14=0,100,minecraft:planks-0
rule15=0,100,minecraft:spruce_stairs-1
rule16=0,100,minecraft:planks-1
rule17=0,100,ChestGenHook:chests/spawn_bonus_chest:5-5
rule18=0,100,minecraft:web-0,air,air,air
rule19=0,100,minecraft:log-0
rule20=0,100,minecraft:wooden_slab-9
rule21=0,100,minecraft:stone-5
rule22=0,100,minecraft:stone_brick_stairs-2
rule23=0,100,minecraft:oak_stairs-2
rule24=0,100,minecraft:oak_stairs-4
rule25=0,100,minecraft:oak_stairs-0
rule26=0,100,minecraft:spruce_stairs-0
rule27=0,100,minecraft:stone_brick_stairs-1
rule28=0,100,minecraft:fence-0
rule29=0,100,minecraft:oak_stairs-7
rule30=0,100,minecraft:stone_brick_stairs-4
rule31=0,100,minecraft:oak_stairs-1
rule32=0,100,minecraft:stone-3
rule33=0,100,minecraft:trapdoor-8
rule34=0,100,minecraft:oak_stairs-3
rule35=0,100,minecraft:spruce_stairs-3
rule36=0,100,minecraft:spruce_stairs-5
rule37=0,100,minecraft:spruce_stairs-6
rule38=0,100,minecraft:spruce_fence_gate-6
rule39=0,100,minecraft:spruce_fence_gate-2
rule40=0,100,minecraft:spruce_fence-0
rule41=0,100,minecraft:spruce_fence_gate-3
rule42=0,100,minecraft:jungle_door-2
rule43=0,100,minecraft:spruce_fence_gate-7
rule44=0,100,minecraft:furnace-2
rule45=0,100,minecraft:oak_stairs-6
rule46=0,100,minecraft:spruce_stairs-4
rule47=0,100,minecraft:carpet-7
rule48=0,100,minecraft:oak_stairs-5
rule49=0,100,minecraft:jungle_door-9
rule50=0,100,minecraft:jungle_door-8
rule51=0,100,minecraft:wooden_slab-13
rule52=0,100,minecraft:dark_oak_stairs-7
rule53=0,100,minecraft:wooden_slab-0
rule54=0,100,minecraft:planks-5
rule55=0,100,minecraft:ladder-5
rule56=0,100,minecraft:spruce_stairs-7
rule57=0,100,minecraft:ladder-2
rule58=0,100,minecraft:dark_oak_stairs-0
rule59=0,100,minecraft:bookshelf-0
rule60=0,100,minecraft:dark_oak_stairs-1
rule61=0,100,minecraft:dark_oak_stairs-2
rule62=0,100,minecraft:spruce_fence_gate-1
rule63=0,100,minecraft:dark_oak_stairs-3
rule64=0,100,minecraft:wooden_slab-5
rule65=0,100,minecraft:stone_brick_stairs-5
rule66=0,100,minecraft:dark_oak_stairs-5
rule67=0,100,minecraft:dark_oak_stairs-4
rule68=0,100,minecraft:trapdoor-12
rule69=0,100,minecraft:log-11
rule70=0,100,minecraft:trapdoor-13
rule71=0,100,minecraft:log-7
rule72=0,100,minecraft:spruce_fence_gate-5
rule73=0,100,minecraft:dark_oak_fence-0
rule74=0,100,minecraft:jungle_door-1
rule75=0,100,minecraft:spruce_fence_gate-4
rule76=0,100,minecraft:carpet-8
rule77=0,100,minecraft:dark_oak_stairs-6
rule78=0,100,minecraft:spruce_fence_gate-0

layer
1,1,1,1,1,1,1,1,1,1,1,1,1,1,1,1,1
1,1,1,1,1,1,3,3,3,3,3,2,1,1,1,1,1
1,1,3,3,3,2,4,4,4,4,4,4,3,1,1,1,1
1,2,4,4,4,4,4,4,4,4,4,4,3,1,1,1,1
1,3,4,5,5,5,4,5,4,4,4,4,3,1,1,1,1
1,3,4,5,6,6,5,5,4,4,5,4,3,1,1,1,1
1,3,4,5,5,6,6,5,5,4,5,5,4,3,3,1,1
1,1,2,4,4,5,5,6,6,5,6,5,5,4,4,2,1
1,1,3,4,5,5,6,6,5,5,6,6,6,5,4,3,1
1,1,3,4,5,6,6,5,6,6,5,6,6,5,4,3,1
1,1,2,4,5,5,6,6,5,5,4,5,5,5,4,3,1
1,1,3,4,5,6,6,6,5,4,4,4,4,4,4,2,7
1,1,3,4,4,5,5,5,4,3,3,3,3,3,3,3,3
1,1,3,4,4,4,4,4,4,3,8,8,8,8,8,8,3
1,1,1,2,3,3,3,3,8,8,8,8,8,8,8,8,3
1,1,1,1,1,1,9,3,3,3,3,3,3,3,3,3,3
endlayer

layer
1,1,1,1,1,1,1,1,1,1,1,1,1,1,1,1,1
1,1,1,1,1,1,10,11,10,10,11,10,1,1,1,1,1
1,1,10,10,11,10,14,14,14,14,13,12,10,1,1,1,1
1,10,19,18,0,17,14,14,14,16,15,12,11,1,1,1,1
1,10,20,0,0,0,0,0,0,19,0,0,10,1,1,1,1
1,11,20,0,0,0,0,0,0,0,0,0,10,1,1,1,1
1,10,19,0,0,0,0,0,0,0,0,0,10,10,10,1,1
1,1,21,18,0,0,0,0,0,0,0,0,0,18,19,21,1
1,1,10,19,16,16,16,0,0,0,0,0,0,0,20,11,1
1,1,11,20,0,0,0,0,0,0,0,0,0,0,20,10,1
1,1,21,20,0,0,0,0,0,0,0,0,0,0,20,11,1
1,1,10,20,0,0,0,0,0,19,20,20,20,20,19,21,1
1,1,11,20,0,0,0,0,0,10,10,10,10,10,10,10,7
1,1,10,19,20,20,20,20,19,10,8,8,8,8,8,10,22
1,1,1,21,11,10,10,11,10,8,8,8,8,8,8,10,22
1,1,1,1,1,1,1,9,10,10,10,10,10,10,10,10,22
endlayer

layer
1,1,1,1,1,1,1,1,1,1,1,1,1,1,1,1,1
1,1,1,1,1,1,10,11,10,10,11,2,1,1,1,1,1
1,1,10,10,11,2,14,14,14,23,0,0,10,1,1,1,1
1,2,19,18,0,18,14,14,14,13,0,0,11,1,1,1,1
1,10,18,0,0,0,0,0,18,19,0,0,10,1,1,1,1
1,11,18,0,0,0,0,0,0,0,0,0,10,1,1,1,1
1,10,19,0,0,0,0,0,0,0,0,0,10,10,10,1,1
1,1,2,18,0,0,0,0,0,0,0,0,0,18,19,2,1
1,1,10,19,0,0,0,0,0,0,0,0,0,0,18,11,1
1,1,11,18,0,0,0,0,0,0,0,0,0,0,0,10,1
1,1,2,0,0,0,0,0,0,0,0,0,0,0,18,11,1
1,1,10,0,0,0,0,0,0,19,18,0,0,18,19,2,1
1,1,11,18,0,0,0,0,18,10,10,10,10,10,10,22,1
1,1,10,19,18,0,0,18,19,10,8,8,8,8,10,22,1
1,1,1,2,11,10,10,11,10,10,8,8,8,8,10,22,1
1,1,1,1,1,1,1,1,9,10,10,10,10,10,10,22,1
endlayer

layer
1,1,1,1,1,1,1,1,1,1,1,1,1,1,1,1,1
1,1,1,1,1,1,10,11,10,10,11,10,1,1,1,1,1
1,1,10,10,11,10,14,14,23,0,0,0,10,1,1,1,1
1,10,19,18,18,18,14,16,13,0,0,0,11,1,1,1,1
1,10,18,18,18,18,18,18,18,19,0,0,10,1,1,1,1
1,11,18,18,0,0,0,0,18,0,0,0,10,1,1,1,1
1,10,19,18,0,0,0,0,0,0,0,0,10,10,10,1,1
1,1,21,18,18,0,0,0,0,0,0,0,18,18,19,21,1
1,1,10,19,20,20,20,0,0,0,0,0,0,18,18,11,1
1,1,11,18,18,0,0,0,0,0,0,0,0,0,18,10,1
1,1,21,18,0,0,0,0,0,18,18,0,0,18,18,11,1
1,1,10,18,0,0,0,0,18,19,18,18,18,18,19,21,1
1,1,11,18,18,0,0,18,18,10,10,10,10,10,10,1,1
1,1,10,19,18,18,18,18,19,10,10,8,8,10,22,1,1
1,1,1,21,11,10,10,11,10,10,10,8,8,10,22,1,1
1,1,1,1,1,1,1,1,1,9,10,10,10,10,22,1,1
endlayer

layer
1,1,1,1,1,1,1,1,1,1,1,1,1,1,1,1,1
1,1,1,1,1,1,3,3,3,3,3,2,1,1,1,1,1
1,1,3,3,3,2,13,0,0,0,0,0,3,1,1,1,1
1,2,14,14,14,14,13,0,0,0,0,0,3,1,1,1,1
1,3,16,16,16,16,25,26,25,19,24,24,3,1,1,1,1
1,3,16,14,14,14,16,16,14,14,16,14,3,1,1,1,1
1,3,16,16,16,14,14,16,16,14,16,16,3,3,1,1,1
1,1,2,14,14,16,16,14,14,16,14,16,16,14,2,2,1
1,1,3,14,16,16,14,14,16,16,14,14,14,16,14,3,1
1,1,3,14,16,14,14,16,14,14,16,14,14,16,14,3,1
1,1,2,14,16,16,14,14,16,16,14,16,16,16,14,3,1
1,1,3,14,16,14,14,14,16,14,14,14,14,14,19,2,1
1,1,3,14,14,16,16,16,14,14,10,14,14,3,3,1,1
1,1,3,19,14,14,14,14,19,10,10,10,10,22,1,1,1
1,1,1,2,3,3,3,3,10,10,10,10,10,22,1,1,1
1,1,1,1,1,1,1,1,1,1,9,27,27,22,1,1,1
endlayer

layer
1,1,1,1,1,1,1,1,1,1,1,1,1,1,1,1,1
1,1,1,1,1,28,25,25,25,25,25,19,1,1,1,1,1
1,1,30,25,25,19,0,0,0,0,0,29,28,1,1,1,1
1,19,10,32,32,0,0,0,0,0,0,29,31,1,1,1,1
1,34,33,0,0,0,0,0,0,19,14,14,23,1,1,1,1
1,34,32,0,0,0,0,0,0,35,15,31,25,1,1,1,1
1,34,32,0,0,0,0,0,0,0,0,0,19,25,1,1,1
1,28,19,20,20,37,0,0,0,0,0,0,0,36,19,23,1
1,1,34,0,0,0,0,0,0,0,0,0,0,0,38,23,1
1,1,34,0,0,0,0,0,0,0,0,0,0,0,39,23,1
1,1,19,0,40,41,40,0,0,0,0,0,0,0,38,23,1
1,1,34,0,40,41,40,0,0,0,0,0,0,0,19,31,1
1,1,34,0,0,0,0,0,0,0,19,42,42,31,23,1,1
1,1,28,19,43,43,43,43,19,31,1,1,1,1,1,1,1
1,1,1,28,31,31,31,31,28,1,1,1,1,1,1,1,1
1,1,1,1,1,1,1,1,1,1,1,1,1,1,1,1,1
endlayer

layer
1,1,1,1,1,1,1,1,1,1,1,1,1,1,1,1,1
1,1,1,1,1,28,28,1,28,28,24,19,1,1,1,1,1
1,1,10,0,28,19,0,0,0,0,29,14,28,1,1,1,1
1,19,44,0,0,0,0,0,0,0,29,14,24,1,1,1,1
1,28,0,0,0,0,0,0,0,19,15,31,45,1,1,1,1
1,1,0,0,0,0,0,0,0,0,0,0,45,1,1,1,1
1,28,0,0,0,0,0,0,0,0,0,0,19,46,1,1,1
1,28,19,0,0,0,0,0,0,0,0,0,0,20,19,28,1
1,1,0,0,0,0,0,0,0,0,0,0,0,0,47,28,1
1,1,28,0,0,0,0,0,0,0,0,0,0,0,47,0,1
1,1,19,0,47,47,47,0,0,0,0,0,0,0,47,28,1
1,1,28,0,47,47,47,0,0,0,0,0,0,0,19,28,1
1,1,1,0,0,0,0,0,0,0,19,50,49,48,28,1,1
1,1,28,19,47,47,47,47,19,28,1,1,1,1,1,1,1
1,1,1,28,28,1,1,28,28,1,1,1,1,1,1,1,1
1,1,1,1,1,1,1,1,1,1,1,1,1,1,1,1,1
endlayer

layer
1,1,1,1,1,1,1,1,1,1,51,51,1,1,1,1,1
1,51,1,1,1,52,46,46,46,46,14,19,1,1,1,1,1
51,54,7,46,46,19,0,0,0,29,13,53,45,1,1,1,1
1,19,11,0,55,0,0,0,0,29,15,53,45,1,1,1,1
1,56,0,0,0,0,0,0,0,19,0,0,45,1,1,1,1
1,56,57,0,0,0,0,0,0,0,0,0,37,51,1,1,1
1,56,57,0,0,0,0,0,0,0,0,0,19,16,51,58,1
1,60,19,0,0,0,0,0,0,0,0,0,0,59,19,37,1
1,1,56,0,0,0,0,0,0,0,0,0,0,0,0,37,1
1,1,56,0,0,0,0,0,0,0,0,0,0,0,0,37,1
1,1,19,0,0,0,0,0,0,0,0,0,0,0,0,37,1
1,1,56,0,0,0,0,0,0,0,0,0,0,0,19,60,1
1,1,56,0,0,0,0,0,0,0,19,62,62,36,61,1,1
1,1,60,19,0,0,0,0,19,36,1,1,1,1,1,1,1
1,1,51,63,36,36,36,36,61,1,1,1,1,1,1,1,1
1,1,1,1,1,1,1,1,1,1,1,1,1,1,1,1,1
endlayer

layer
1,1,1,1,1,1,63,51,51,61,64,1,1,1,1,1,1
1,1,63,51,52,58,16,16,16,14,25,19,24,1,1,1,1
1,63,10,54,54,19,36,36,56,23,0,0,23,1,1,1,1
63,19,65,36,36,37,20,20,56,13,0,0,23,1,1,1,1
66,54,37,0,0,0,0,0,36,19,0,0,13,1,1,1,1
51,54,37,0,0,0,0,0,0,0,0,0,13,58,1,1,1
67,54,37,0,0,0,0,0,0,0,0,0,19,54,67,61,1
63,54,19,46,0,0,0,0,0,0,0,0,56,36,19,54,64
1,63,54,37,0,0,0,0,0,0,0,0,0,0,56,54,51
1,51,54,37,0,0,0,0,0,0,0,0,0,0,56,54,51
1,52,19,0,0,0,0,0,0,0,0,0,0,0,56,54,64
1,51,54,37,0,0,0,0,0,0,46,46,46,46,19,60,1
1,64,54,37,0,0,0,0,46,46,19,54,54,54,61,1,1
1,1,63,19,46,46,46,46,19,60,51,51,51,64,1,1,1
1,1,1,66,54,54,54,54,61,1,1,1,1,1,1,1,1
1,1,1,1,64,51,51,64,1,1,1,1,1,1,1,1,1
endlayer

layer
1,1,1,1,1,1,1,1,64,1,1,1,1,1,1,1,1
1,1,1,64,1,70,69,69,69,69,69,69,69,68,1,1,1
1,1,9,69,69,69,14,14,23,0,0,0,71,1,1,1,1
1,58,10,14,14,14,16,16,13,0,0,0,71,1,1,1,1
1,63,14,14,16,16,16,14,26,19,0,0,71,1,1,1,1
64,54,14,14,16,14,14,16,14,14,0,0,71,1,1,1,1
1,63,14,14,14,16,14,16,16,16,46,46,16,61,1,1,1
1,64,19,14,16,14,14,14,16,14,16,14,16,54,58,64,1
1,1,63,14,16,14,14,14,16,16,16,16,14,16,54,58,1
1,1,54,14,16,14,16,16,14,16,16,14,14,16,54,61,1
1,64,54,14,16,16,16,14,14,16,14,16,16,16,54,64,1
1,1,54,14,14,14,14,14,16,16,16,16,54,54,60,1,1
1,1,63,54,14,14,14,14,71,54,54,54,60,61,1,1,1
1,1,1,60,63,54,54,61,60,60,64,64,1,1,1,1,1
1,1,1,1,64,63,60,64,1,1,1,1,1,1,1,1,1
1,1,1,1,1,1,1,1,1,1,1,1,1,1,1,1,1
endlayer

layer
1,1,1,1,1,1,1,1,1,1,1,1,1,1,1,1,1
1,1,1,1,1,1,28,25,25,25,25,19,28,1,1,1,1
1,1,7,34,25,25,19,0,0,0,0,0,23,1,1,1,1
1,1,10,19,72,72,0,0,0,0,0,0,23,1,1,1,1
1,1,34,0,0,0,0,0,0,19,0,0,23,1,1,1,1
1,1,34,0,0,0,0,0,0,14,0,0,19,1,1,1,1
1,1,34,37,56,37,0,0,0,14,31,31,28,1,1,1,1
1,1,19,37,56,37,0,0,0,19,0,0,0,73,1,1,1
1,1,34,0,0,0,0,0,0,74,0,0,0,0,73,1,1
1,1,34,0,75,0,0,0,0,19,0,0,0,0,73,1,1
1,1,34,0,75,0,0,0,0,23,0,0,0,0,73,1,1
1,1,31,19,0,0,43,43,19,0,0,0,73,73,1,1,1
1,1,1,28,31,31,31,31,40,73,73,73,1,1,1,1,1
1,1,1,1,1,1,1,1,1,1,1,1,1,1,1,1,1
1,1,1,1,1,1,1,1,1,1,1,1,1,1,1,1,1
1,1,1,1,1,1,1,1,1,1,1,1,1,1,1,1,1
endlayer

layer
1,1,1,1,1,1,1,1,1,1,1,1,1,1,1,1,1
1,1,1,1,1,1,28,0,28,0,28,19,28,1,1,1,1
1,1,1,28,0,28,19,0,0,0,0,0,0,1,1,1,1
1,1,10,19,47,47,0,0,0,0,0,0,28,1,1,1,1
1,1,28,0,0,0,0,0,0,19,0,0,28,1,1,1,1
1,1,0,0,0,0,0,0,0,14,0,0,19,1,1,1,1
1,1,28,76,47,47,0,0,0,14,28,28,28,1,1,1,1
1,1,19,76,47,47,0,0,0,19,0,0,0,1,1,1,1
1,1,28,0,0,0,0,0,0,49,0,0,0,0,1,1,1
1,1,1,0,47,0,0,0,0,19,0,0,0,0,1,1,1
1,1,28,0,47,0,0,0,0,28,0,0,0,0,1,1,1
1,1,28,19,0,0,47,47,19,0,0,0,1,1,1,1,1
1,1,1,28,0,28,28,0,28,1,1,1,1,1,1,1,1
1,1,1,1,1,1,1,1,1,1,1,1,1,1,1,1,1
1,1,1,1,1,1,1,1,1,1,1,1,1,1,1,1,1
1,1,1,1,1,1,1,1,1,1,1,1,1,1,1,1,1
endlayer

layer
1,1,1,1,1,1,1,1,1,1,1,1,1,1,1,1,1
1,1,1,1,1,51,58,46,46,46,46,19,77,1,1,1,1
1,1,51,63,46,46,19,0,0,0,0,0,37,1,1,1,1
1,1,10,19,0,0,0,0,0,0,0,0,37,1,1,1,1
1,1,56,0,0,0,0,0,0,19,0,0,37,1,1,1,1
1,1,56,0,0,0,0,0,0,16,0,0,19,1,1,1,1
1,1,56,0,0,0,0,0,0,16,36,36,61,1,1,1,1
1,1,19,0,0,0,0,0,0,19,0,0,0,1,1,1,1
1,1,56,0,0,0,0,0,0,78,0,0,0,1,1,1,1
1,1,56,0,0,0,0,0,0,19,0,0,0,1,1,1,1
1,1,56,0,0,0,0,0,0,37,0,0,0,1,1,1,1
1,1,60,19,0,0,0,0,19,60,0,1,1,1,1,1,1
1,1,1,63,36,36,36,36,61,1,1,1,1,1,1,1,1
1,1,1,1,1,1,1,1,1,1,1,1,1,1,1,1,1
1,1,1,1,1,1,1,1,1,1,1,1,1,1,1,1,1
1,1,1,1,1,1,1,1,1,1,1,1,1,1,1,1,1
endlayer

layer
1,1,1,1,1,1,1,64,51,51,52,58,1,1,1,1,1
1,1,1,1,1,1,58,54,54,54,54,19,58,64,1,1,1
1,1,1,58,54,54,19,36,36,36,36,56,54,51,1,1,1
1,64,10,19,36,36,36,0,0,0,0,56,54,51,1,1,1
1,52,54,0,0,0,0,0,0,19,46,56,54,51,1,1,1
1,51,54,0,0,0,0,0,46,16,16,16,19,64,1,1,1
1,52,54,0,0,0,0,0,56,54,54,54,60,1,1,1,1
1,64,19,0,0,0,0,0,56,19,54,51,1,1,1,1,1
1,51,54,0,0,0,0,0,56,54,51,1,1,1,1,1,1
1,51,54,0,0,0,0,0,56,19,51,1,1,1,1,1,1
1,64,60,0,0,0,0,0,56,54,64,1,1,1,1,1,1
1,1,63,19,46,46,46,46,19,61,1,1,1,1,1,1,1
1,1,51,60,54,54,54,54,66,51,1,1,1,1,1,1,1
1,1,1,1,64,51,51,64,1,1,1,1,1,1,1,1,1
1,1,1,1,1,1,1,1,1,1,1,1,1,1,1,1,1
1,1,1,1,1,1,1,1,1,1,1,1,1,1,1,1,1
endlayer

layer
1,1,1,1,1,1,1,1,1,1,1,1,1,1,1,1,1
1,1,1,1,1,1,1,1,58,54,54,58,1,1,1,1,1
1,1,1,1,58,58,54,54,54,54,54,54,61,1,1,1,1
1,1,11,54,36,36,36,36,56,16,40,54,54,64,1,1,1
1,1,63,37,0,0,0,0,56,54,54,54,54,1,1,1,1
1,1,63,37,0,0,0,0,56,54,54,54,61,1,1,1,1
1,1,63,37,0,0,0,0,56,54,54,60,1,1,1,1,1
1,1,63,37,0,0,0,0,56,54,61,1,1,1,1,1,1
1,1,63,37,0,0,0,0,56,54,64,1,1,1,1,1,1
1,1,63,37,0,0,0,0,56,61,1,1,1,1,1,1,1
1,1,63,37,0,0,0,0,56,61,1,1,1,1,1,1,1
1,1,60,19,46,46,46,46,19,60,1,1,1,1,1,1,1
1,1,1,63,60,60,60,60,61,1,1,1,1,1,1,1,1
1,1,1,1,1,1,1,1,1,1,1,1,1,1,1,1,1
1,1,1,1,1,1,1,1,1,1,1,1,1,1,1,1,1
1,1,1,1,1,1,1,1,1,1,1,1,1,1,1,1,1
endlayer

layer
1,1,1,1,1,1,1,1,1,1,1,1,1,1,1,1,1
1,1,1,1,1,1,1,1,1,1,1,1,1,1,1,1,1
1,1,1,1,1,1,1,63,54,54,54,58,1,1,1,1,1
1,1,11,1,58,54,54,54,54,54,73,54,1,1,1,1,1
1,1,1,63,37,36,36,36,54,54,54,54,64,1,1,1,1
1,1,1,63,37,0,0,56,54,54,54,61,1,1,1,1,1
1,1,1,63,36,0,0,36,54,54,61,1,1,1,1,1,1
1,1,1,63,37,0,0,56,54,61,1,1,1,1,1,1,1
1,1,1,63,46,0,0,46,54,64,1,1,1,1,1,1,1
1,1,1,63,37,0,0,56,54,1,1,1,1,1,1,1,1
1,1,1,60,46,46,46,46,61,1,1,1,1,1,1,1,1
1,1,1,60,60,60,60,60,64,1,1,1,1,1,1,1,1
1,1,1,1,1,1,1,1,1,1,1,1,1,1,1,1,1
1,1,1,1,1,1,1,1,1,1,1,1,1,1,1,1,1
1,1,1,1,1,1,1,1,1,1,1,1,1,1,1,1,1
1,1,1,1,1,1,1,1,1,1,1,1,1,1,1,1,1
endlayer

layer
1,1,1,1,1,1,1,1,1,1,1,1,1,1,1,1,1
1,1,1,1,1,1,1,1,1,1,1,1,1,1,1,1,1
1,1,1,1,1,1,1,1,73,73,73,1,1,1,1,1,1
1,1,11,1,1,73,73,73,64,64,1,73,1,1,1,1,1
1,1,1,1,63,54,54,54,64,64,64,73,1,1,1,1,1
1,1,1,1,54,36,36,54,54,64,73,1,1,1,1,1,1
1,1,1,1,54,16,16,54,54,73,1,1,1,1,1,1,1
1,1,1,1,54,37,56,54,54,1,1,1,1,1,1,1,1
1,1,1,1,54,16,16,54,54,1,1,1,1,1,1,1,1
1,1,1,1,54,46,46,54,1,1,1,1,1,1,1,1,1
1,1,1,1,60,54,54,61,1,1,1,1,1,1,1,1,1
1,1,1,1,1,1,1,1,1,1,1,1,1,1,1,1,1
1,1,1,1,1,1,1,1,1,1,1,1,1,1,1,1,1
1,1,1,1,1,1,1,1,1,1,1,1,1,1,1,1,1
1,1,1,1,1,1,1,1,1,1,1,1,1,1,1,1,1
1,1,1,1,1,1,1,1,1,1,1,1,1,1,1,1,1
endlayer

layer
1,1,1,1,1,1,1,1,1,1,1,1,1,1,1,1,1
1,1,1,1,1,1,1,1,1,1,1,1,1,1,1,1,1
1,1,1,1,1,1,1,1,1,1,1,1,1,1,1,1,1
1,1,1,1,1,1,1,1,1,1,1,1,1,1,1,1,1
1,1,1,1,1,73,73,73,1,1,1,1,1,1,1,1,1
1,1,1,1,73,64,64,64,73,1,1,1,1,1,1,1,1
1,1,1,1,73,64,64,64,73,1,1,1,1,1,1,1,1
1,1,1,1,73,64,64,64,73,1,1,1,1,1,1,1,1
1,1,1,1,73,64,64,64,73,1,1,1,1,1,1,1,1
1,1,1,1,73,64,64,73,1,1,1,1,1,1,1,1,1
1,1,1,1,1,73,73,1,1,1,1,1,1,1,1,1,1
1,1,1,1,1,1,1,1,1,1,1,1,1,1,1,1,1
1,1,1,1,1,1,1,1,1,1,1,1,1,1,1,1,1
1,1,1,1,1,1,1,1,1,1,1,1,1,1,1,1,1
1,1,1,1,1,1,1,1,1,1,1,1,1,1,1,1,1
1,1,1,1,1,1,1,1,1,1,1,1,1,1,1,1,1
endlayer

