
# Created by Ruins mod version 16.7 Ingame Parser
# authoring Player: lafuller

weight=1
embed_into_distance=4
acceptable_target_blocks=
unacceptable_target_blocks=flowing_water,water,flowing_lava,lava,ice,bedrock,netherrack,nether_brick,nether_brick_fence,soul_sand,quartz_ore,end_stone,obsidian,iron_bars,cloud,flesh,ash_block,slime_grass,slime_congealed,slime_dirt
biomesToSpawnIn=plains,prarie,meadow,tundra,brushland,shrubland,woodland,woodlands,lavender_fields,flower_field,sunflower_plains,ice_flats,ice_plains
dimensions=13,8,9
allowable_overhang=0
max_leveling=4
leveling_buffer=-1
preserve_water=0
preserve_lava=0

rule1=0,100,preserveBlock
rule2=0,100,stonebrick-0,stonebrick-0,stonebrick-0,stonebrick-0,stonebrick-1,stonebrick-2,stonebrick-2,stone-5,stone-6,cobblestone
rule3=0,100,minecraft:dirt-0
rule4=0,100,minecraft:stone_brick_stairs-0
rule5=0,100,minecraft:stone_brick_stairs-3
rule6=0,100,stonebrick-0,stonebrick-0,stonebrick-0,stonebrick-0,stonebrick-1,stonebrick-2,stonebrick-2,stone-5,stone-6,cobblestone,gravel
rule7=0,100,minecraft:cobblestone_wall-0
rule8=0,100,minecraft:stone_brick_stairs-2
rule9=0,100,minecraft:planks-0
rule10=0,100,minecraft:planks-1
rule11=0,100,minecraft:log-0
rule12=0,100,minecraft:oak_stairs-0
rule13=0,100,minecraft:fence-0
rule14=0,100,minecraft:cauldron-0
rule15=0,100,minecraft:oak_stairs-3
rule16=0,100,minecraft:oak_stairs-2
rule17=0,100,minecraft:oak_stairs-1
rule18=0,100,minecraft:jungle_door-2
rule19=0,100,minecraft:stone_brick_stairs-4
rule20=0,100,IInventory;minecraft:furnace;minecraft:coal#2#0#1-5
rule21=0,100,minecraft:oak_stairs-5
rule22=0,100,minecraft:jungle_door-8
rule23=0,100,minecraft:oak_stairs-7
rule24=0,100,minecraft:dark_oak_stairs-0
rule25=0,100,minecraft:spruce_stairs-4
rule26=0,100,minecraft:dark_oak_stairs-7
rule27=0,100,minecraft:wooden_slab-13
rule28=0,100,minecraft:spruce_stairs-7
rule29=0,100,minecraft:spruce_stairs-6
rule30=0,100,minecraft:spruce_stairs-5
rule31=0,100,minecraft:spruce_fence_gate-1
rule32=0,100,minecraft:dark_oak_stairs-5
rule33=0,100,minecraft:wooden_slab-5
rule34=0,100,minecraft:dark_oak_stairs-2
rule35=0,100,minecraft:dark_oak_stairs-3
rule36=0,100,minecraft:planks-5
rule37=0,100,minecraft:dark_oak_stairs-1
rule38=0,100,minecraft:dark_oak_fence-0
rule39=0,100,ChestGenHook:chests/spawn_bonus_chest:5-4

layer
1,1,1,1,1,1,1,1,1
1,1,2,2,2,2,2,2,1
1,2,3,3,3,3,2,2,1
1,2,3,3,3,3,3,2,1
1,2,3,3,3,3,3,2,4
1,2,3,3,3,3,3,2,2
4,2,2,2,2,2,2,2,2
5,2,2,2,2,2,2,2,2
endlayer

layer
1,1,1,1,1,1,1,1,1
1,1,6,6,7,6,6,6,1
1,6,3,3,3,3,6,6,1
1,7,3,3,3,3,3,7,1
1,6,3,3,3,3,3,6,1
1,7,3,3,3,3,3,6,4
1,6,6,6,6,6,6,6,6
1,5,6,6,6,6,6,6,6
endlayer

layer
1,1,1,1,1,1,1,1,1
1,1,6,6,7,6,6,6,1
1,6,3,3,3,3,6,6,1
1,7,3,3,3,3,3,7,1
1,6,3,3,3,3,3,6,1
1,7,3,3,3,3,3,6,1
1,6,6,6,6,6,6,6,4
1,1,5,6,6,6,6,6,8
endlayer

layer
1,1,1,1,1,1,1,1,1
1,1,6,6,7,6,6,6,1
1,6,3,3,3,3,6,6,1
1,7,3,3,3,3,3,7,1
1,6,3,3,3,3,3,6,1
1,7,3,3,3,3,3,6,1
1,6,6,6,6,6,6,8,1
1,1,1,5,6,6,6,8,1
endlayer

layer
1,1,1,1,1,1,1,1,1
1,1,2,2,2,2,6,6,1
1,2,9,9,9,9,6,2,1
1,2,9,10,10,10,9,2,1
1,2,9,10,10,10,9,2,1
1,2,9,9,9,9,9,2,1
1,2,2,2,2,6,2,1,1
1,1,1,1,5,6,8,1,1
endlayer

layer
1,1,1,1,1,1,1,1,1
1,13,11,12,12,11,6,6,1
1,15,39,0,0,0,14,11,1
1,15,0,0,0,0,0,16,1
1,11,0,0,0,0,0,16,1
1,15,0,0,0,0,0,11,1
1,13,11,17,15,18,17,1,1
1,1,1,1,1,1,1,1,1
endlayer

layer
1,1,1,1,1,1,1,1,1
1,13,11,13,0,11,19,8,1
1,0,0,0,0,0,20,11,1
1,13,0,0,0,0,0,0,1
1,11,0,0,0,0,0,13,1
1,13,0,0,0,0,0,11,1
1,13,11,13,23,22,21,1,1
1,1,1,1,1,1,1,1,1
endlayer

layer
1,1,1,1,1,1,1,1,1
27,26,11,25,25,11,4,24,1
1,28,0,0,0,0,7,11,1
1,28,0,0,0,0,0,29,1
1,11,0,0,0,0,0,29,1
1,28,0,0,0,0,0,11,1
1,32,11,30,30,31,30,1,1
1,1,1,1,1,1,1,1,1
endlayer

layer
1,33,35,27,27,34,33,1,1
1,35,11,36,36,11,4,33,1
24,36,30,30,30,30,2,11,24
27,36,29,0,0,0,28,36,27
27,11,29,0,0,0,28,36,27
33,36,25,25,25,25,28,11,37
1,33,11,36,36,36,36,34,1
1,1,35,27,27,27,33,1,1
endlayer

layer
1,1,1,1,1,1,1,1,1
1,1,24,35,34,24,1,1,1
1,35,36,36,36,36,2,34,1
1,24,36,10,10,10,36,24,1
1,37,36,10,10,10,36,37,1
1,1,35,36,36,36,36,37,1
1,1,37,37,35,34,33,1,1
1,1,1,1,1,1,1,1,1
endlayer

layer
1,1,1,1,1,1,1,1,1
1,1,1,1,1,1,1,1,1
1,1,38,38,38,38,7,1,1
1,1,38,33,33,33,38,1,1
1,1,38,33,33,33,38,1,1
1,1,1,38,38,38,38,1,1
1,1,1,1,1,1,1,1,1
1,1,1,1,1,1,1,1,1
endlayer

layer
1,1,1,1,1,1,1,1,1
1,1,1,1,1,1,1,1,1
1,1,1,1,1,1,7,1,1
1,1,1,1,1,1,1,1,1
1,1,1,1,1,1,1,1,1
1,1,1,1,1,1,1,1,1
1,1,1,1,1,1,1,1,1
1,1,1,1,1,1,1,1,1
endlayer

layer
1,1,1,1,1,1,1,1,1
1,1,1,1,1,1,1,1,1
1,1,1,1,1,1,7,1,1
1,1,1,1,1,1,1,1,1
1,1,1,1,1,1,1,1,1
1,1,1,1,1,1,1,1,1
1,1,1,1,1,1,1,1,1
1,1,1,1,1,1,1,1,1
endlayer

