
# Created by Ruins mod version 16.7 Ingame Parser
# authoring Player: lafuller

weight=1
embed_into_distance=4
acceptable_target_blocks=
unacceptable_target_blocks=flowing_water,water,flowing_lava,lava,ice,bedrock,netherrack,nether_brick,nether_brick_fence,soul_sand,quartz_ore,end_stone,obsidian,iron_bars,cloud,flesh,ash_block,slime_grass,slime_congealed,slime_dirt
biomesToSpawnIn=plains,prarie,meadow,tundra,brushland,shrubland,woodland,woodlands,lavender_fields,flower_field,sunflower_plains,ice_flats,ice_plains
dimensions=18,16,17
allowable_overhang=0
max_leveling=4
leveling_buffer=-1
preserve_water=0
preserve_lava=0

rule1=0,100,preserveBlock
rule2=0,100,stonebrick-0,stonebrick-0,stonebrick-0,stonebrick-0,stonebrick-1,stonebrick-2,stonebrick-2,stone-5,stone-6,cobblestone
rule3=0,100,minecraft:stone-6
rule4=0,100,stonebrick-0,stonebrick-2,stonebrick-1,stonebrick-1,stonebrick-1,cobblestone
rule5=0,100,stonebrick-0,stonebrick-1,stonebrick-2,stonebrick-2,stone-5,stone-5,stone-6,stone-6
rule6=0,100,stonebrick-0,stonebrick-2,stonebrick-0,stonebrick-1,stonebrick-1,cobblestone
rule7=0,100,minecraft:stone_brick_stairs-2
rule8=0,100,minecraft:stone_brick_stairs-3
rule9=0,100,stonebrick-0,stonebrick-0,stonebrick-0,stonebrick-0,stonebrick-1,stonebrick-2,stonebrick-2,stone-5,stone-6,cobblestone,gravel
rule10=0,100,minecraft:cobblestone_wall-0
rule11=0,100,minecraft:stone-5
rule12=0,100,minecraft:log-0
rule13=0,100,minecraft:wooden_slab-9
rule14=0,100,minecraft:planks-1
rule15=0,100,minecraft:oak_stairs-0
rule16=0,100,minecraft:planks-0
rule17=0,100,ChestGenHook:chests/spawn_bonus_chest:5-3
rule18=0,100,minecraft:web-0,air,air,air
rule19=0,100,minecraft:oak_stairs-7
rule20=0,100,minecraft:oak_stairs-2
rule21=0,100,minecraft:oak_stairs-6
rule22=0,100,minecraft:spruce_fence_gate-5
rule23=0,100,minecraft:oak_stairs-3
rule24=0,100,minecraft:spruce_fence-0
rule25=0,100,minecraft:spruce_fence_gate-3
rule26=0,100,minecraft:stone-3
rule27=0,100,minecraft:spruce_fence_gate-1
rule28=0,100,minecraft:trapdoor-8
rule29=0,100,minecraft:oak_stairs-5
rule30=0,100,minecraft:oak_stairs-1
rule31=0,100,minecraft:fence-0
rule32=0,100,minecraft:jungle_door-2
rule33=0,100,minecraft:carpet-7
rule34=0,100,minecraft:furnace-2
rule35=0,100,minecraft:oak_stairs-4
rule36=0,100,minecraft:jungle_door-9
rule37=0,100,minecraft:jungle_door-8
rule38=0,100,minecraft:spruce_stairs-6
rule39=0,100,minecraft:spruce_stairs-4
rule40=0,100,minecraft:dark_oak_stairs-3
rule41=0,100,minecraft:wooden_slab-13
rule42=0,100,minecraft:dark_oak_stairs-5
rule43=0,100,minecraft:spruce_stairs-7
rule44=0,100,minecraft:dark_oak_stairs-0
rule45=0,100,minecraft:ladder-2
rule46=0,100,minecraft:dark_oak_stairs-1
rule47=0,100,minecraft:dark_oak_stairs-6
rule48=0,100,minecraft:spruce_stairs-5
rule49=0,100,minecraft:double_wooden_slab-5
rule50=0,100,minecraft:dark_oak_stairs-4
rule51=0,100,minecraft:dark_oak_stairs-2
rule52=0,100,minecraft:wooden_slab-5
rule53=0,100,minecraft:planks-5
rule54=0,100,minecraft:trapdoor-14
rule55=0,100,minecraft:log-7
rule56=0,100,minecraft:planks-2
rule57=0,100,minecraft:log-11
rule58=0,100,minecraft:trapdoor-13
rule59=0,100,minecraft:trapdoor-12
rule60=0,100,minecraft:trapdoor-15
rule61=0,100,minecraft:spruce_fence_gate-6
rule62=0,100,minecraft:spruce_fence_gate-7
rule63=0,100,minecraft:spruce_stairs-3
rule64=0,100,minecraft:spruce_stairs-1
rule65=0,100,minecraft:spruce_stairs-2
rule66=0,100,minecraft:spruce_stairs-0
rule67=0,100,minecraft:dark_oak_stairs-7
rule68=0,100,minecraft:dark_oak_fence-0
rule69=0,100,minecraft:trapdoor-9

layer
1,1,1,1,1,1,1,1,1,1,1,1,1,1,1,1,1
1,1,1,1,1,2,2,2,2,2,1,1,1,1,1,1,1
1,1,1,1,2,4,4,4,4,3,1,1,1,1,1,1,1
1,1,1,2,2,4,5,5,5,4,2,1,1,1,1,1,1
1,1,2,4,4,4,5,4,4,4,2,1,1,1,1,1,1
1,3,4,4,5,5,6,6,5,4,2,1,1,1,1,1,1
1,2,4,5,5,6,6,6,5,4,2,3,2,2,3,1,1
1,2,4,5,6,6,6,5,5,4,4,4,4,4,4,2,1
1,2,4,5,6,5,6,6,5,5,5,4,5,5,4,2,1
1,2,4,4,5,5,6,6,6,6,5,5,4,5,4,3,1
1,1,3,4,4,5,6,5,6,6,5,4,5,4,4,2,1
1,1,2,4,4,5,5,5,6,5,4,4,4,4,4,2,1
1,1,1,3,2,4,4,5,5,5,4,2,2,2,3,1,1
1,1,1,8,2,3,4,4,4,4,4,2,2,2,7,1,1
1,1,1,8,2,2,2,3,2,2,3,2,2,2,7,1,1
1,1,1,8,2,2,2,2,2,2,2,2,2,2,7,1,1
endlayer

layer
1,1,1,1,1,1,1,1,1,1,1,1,1,1,1,1,1
1,1,1,1,1,9,10,9,9,9,1,1,1,1,1,1,1
1,1,1,1,9,12,13,13,12,11,1,1,1,1,1,1,1
1,1,1,9,9,1,1,1,1,1,9,1,1,1,1,1,1
1,1,9,0,0,0,0,0,0,0,10,1,1,1,1,1,1
1,11,12,0,0,0,0,0,0,0,9,1,1,1,1,1,1
1,10,13,0,0,0,0,14,14,14,12,11,9,10,11,1,1
1,9,13,0,0,0,0,0,0,0,0,0,0,0,0,9,1
1,10,13,0,0,0,0,0,0,0,0,0,0,0,0,10,1
1,9,12,0,0,0,0,0,0,0,0,0,12,15,15,11,1
1,1,11,0,0,0,0,0,0,0,0,0,0,16,16,9,1
1,1,9,12,0,0,0,0,0,0,0,0,17,16,16,9,1
1,1,1,11,9,0,0,0,0,0,0,9,9,10,11,1,1
1,1,1,1,9,11,12,13,13,13,12,9,9,7,1,1,1
1,1,1,1,8,9,9,11,9,9,11,9,9,7,1,1,1
1,1,1,1,8,9,9,9,9,9,9,9,9,7,1,1,1
endlayer

layer
1,1,1,1,1,1,1,1,1,1,1,1,1,1,1,1,1
1,1,1,1,1,9,10,9,9,9,1,1,1,1,1,1,1
1,1,1,1,9,12,18,0,12,3,1,1,1,1,1,1,1
1,1,1,9,9,18,0,0,0,18,9,1,1,1,1,1,1
1,1,9,18,0,0,0,0,0,0,10,1,1,1,1,1,1
1,3,12,0,0,0,0,0,0,0,9,1,1,1,1,1,1
1,10,18,0,0,0,0,0,0,0,12,3,9,10,3,1,1
1,9,0,0,0,0,0,0,0,0,0,0,0,0,0,9,1
1,10,18,0,0,0,0,0,0,0,0,0,0,0,0,10,1
1,9,12,0,0,0,0,0,0,0,0,0,12,0,0,3,1
1,1,3,18,0,0,0,0,0,0,0,0,19,15,15,10,1
1,1,9,12,18,0,0,0,0,0,0,18,19,16,16,9,1
1,1,1,3,9,18,18,0,0,0,18,9,9,10,3,1,1
1,1,1,1,9,3,12,18,0,18,12,9,7,1,1,1,1
1,1,1,1,1,8,9,3,9,9,3,9,7,1,1,1,1
1,1,1,1,1,8,9,9,9,9,9,9,7,1,1,1,1
endlayer

layer
1,1,1,1,1,1,1,1,1,1,1,1,1,1,1,1,1
1,1,1,1,1,9,10,9,9,9,1,1,1,1,1,1,1
1,1,1,1,9,12,18,18,12,11,1,1,1,1,1,1,1
1,1,1,9,9,18,18,0,18,18,9,1,1,1,1,1,1
1,1,9,18,18,18,0,0,18,18,10,1,1,1,1,1,1
1,11,12,18,0,0,0,0,18,18,9,1,1,1,1,1,1
1,10,18,18,0,0,0,13,13,13,12,11,9,10,11,1,1
1,9,18,0,0,0,0,0,0,0,0,0,0,0,18,9,1
1,10,18,18,0,0,0,0,0,0,0,0,0,0,0,10,1
1,9,12,18,0,0,0,0,0,0,0,0,12,0,0,11,1
1,1,11,18,18,0,0,0,0,0,0,18,20,0,0,10,1
1,1,9,12,18,18,18,0,0,0,18,18,20,0,0,9,1
1,1,1,11,9,18,18,18,0,18,18,9,9,10,11,1,1
1,1,1,1,9,11,12,18,18,18,12,9,1,1,1,1,1
1,1,1,1,1,1,9,11,9,9,11,7,1,1,1,1,1
1,1,1,1,1,1,8,9,9,9,9,7,1,1,1,1,1
endlayer

layer
1,1,1,1,1,1,1,1,1,1,1,1,1,1,1,1,1
1,1,1,1,1,2,2,2,2,2,1,1,1,1,1,1,1
1,1,1,1,2,16,16,16,16,3,1,1,1,1,1,1,1
1,1,1,2,16,16,14,14,14,16,2,1,1,1,1,1,1
1,1,2,16,16,16,14,16,16,16,2,1,1,1,1,1,1
1,3,16,16,14,14,16,16,14,16,2,1,1,1,1,1,1
1,2,16,14,14,16,16,16,14,16,16,3,2,2,3,1,1
1,2,16,14,16,16,16,14,14,16,16,16,21,18,18,2,1
1,2,16,14,16,14,16,16,14,14,14,16,21,0,0,2,1
1,2,16,16,14,14,16,16,16,16,14,14,12,0,0,3,1
1,1,3,16,16,14,16,14,16,16,14,20,0,0,0,2,1
1,1,2,16,16,14,14,14,16,14,16,20,0,0,0,2,1
1,1,1,3,16,16,16,14,14,14,16,2,2,2,3,1,1
1,1,1,1,2,3,16,16,16,16,16,2,1,1,1,1,1
1,1,1,1,1,1,2,3,16,16,3,1,1,1,1,1,1
1,1,1,1,1,1,1,8,9,9,7,1,1,1,1,1,1
endlayer

layer
1,1,1,1,1,1,1,1,1,1,1,1,1,1,1,1,1
1,1,1,1,1,15,15,15,15,15,1,1,1,1,1,1,1
1,1,1,1,15,12,22,22,22,12,1,1,1,1,1,1,1
1,1,1,23,0,0,0,0,0,0,20,1,1,1,1,1,1
1,1,15,12,0,0,0,0,0,0,20,1,1,1,1,1,1
1,23,26,0,0,0,0,24,25,24,16,1,1,1,1,1,1
1,12,26,0,0,0,0,24,27,24,12,16,15,15,12,1,1
1,23,28,0,0,0,0,0,0,0,0,23,16,16,16,20,1
1,23,28,0,0,0,0,0,0,0,0,30,16,29,29,20,1
1,23,26,0,0,0,0,0,0,0,0,0,12,0,0,12,1
1,31,12,0,0,0,0,0,0,0,0,0,0,0,0,20,1
1,1,23,0,0,0,0,0,0,0,0,0,0,0,0,20,1
1,1,1,12,0,0,0,0,0,0,0,12,30,30,12,31,1
1,1,1,1,30,12,0,0,0,0,0,20,1,1,1,1,1
1,1,1,1,1,1,30,12,32,32,12,31,1,1,1,1,1
1,1,1,1,1,1,1,1,1,1,1,1,1,1,1,1,1
endlayer

layer
1,1,1,1,1,1,1,1,1,1,1,1,1,1,1,1,1
1,1,1,1,1,1,31,0,31,31,1,1,1,1,1,1,1
1,1,1,1,31,12,33,33,33,12,1,1,1,1,1,1,1
1,1,1,31,0,0,0,0,0,0,0,1,1,1,1,1,1
1,1,15,12,0,0,0,0,0,0,31,1,1,1,1,1,1
1,23,34,0,0,0,0,33,33,33,16,1,1,1,1,1,1
1,12,0,0,0,0,0,33,33,33,12,16,35,35,12,1,1
1,0,0,0,0,0,0,0,0,0,0,0,23,16,16,21,1
1,0,0,0,0,0,0,0,0,0,0,0,23,16,16,20,1
1,31,0,0,0,0,0,0,0,0,0,0,12,29,29,12,1
1,31,12,0,0,0,0,0,0,0,0,0,0,0,0,31,1
1,1,31,0,0,0,0,0,0,0,0,0,0,0,0,31,1
1,1,1,12,0,0,0,0,0,0,0,12,31,31,12,31,1
1,1,1,1,31,12,0,0,0,0,0,31,1,1,1,1,1
1,1,1,1,1,1,31,12,37,36,12,31,1,1,1,1,1
1,1,1,1,1,1,1,1,1,1,1,1,1,1,1,1,1
endlayer

layer
1,1,1,1,1,1,1,1,1,1,1,1,1,1,1,1,1
1,1,1,1,40,39,39,39,39,38,1,1,1,1,1,1,1
1,1,1,41,39,12,0,0,0,12,42,41,1,1,1,1,1
1,1,41,43,0,0,0,0,0,0,38,1,1,1,1,1,1
1,44,39,12,0,0,0,0,0,0,38,1,1,1,1,1,1
41,43,10,0,0,0,0,0,0,0,16,41,1,1,1,1,1
1,12,45,0,0,0,0,0,0,0,12,16,15,15,12,44,1
1,43,0,0,0,0,0,0,0,0,0,0,0,0,0,21,1
1,43,0,0,0,0,0,0,0,0,0,0,0,0,0,21,1
1,43,0,0,0,0,0,0,0,0,0,0,12,15,15,12,1
1,46,12,0,0,0,0,0,0,0,0,0,0,19,16,38,1
1,40,43,0,0,0,0,0,0,0,0,0,0,19,16,38,1
1,1,49,12,0,0,0,0,0,0,0,12,48,48,12,47,1
1,1,41,50,48,12,0,0,0,0,0,38,1,1,1,41,1
1,1,1,52,49,42,48,12,25,25,12,51,1,1,1,1,1
1,1,1,1,1,1,1,1,1,1,1,41,1,1,1,1,1
endlayer

layer
1,1,1,1,1,52,41,41,41,52,1,1,1,1,1,1,1
1,1,1,1,52,53,53,53,53,53,52,1,1,1,1,1,1
1,1,1,1,53,12,48,48,48,12,51,1,1,1,1,1,1
1,1,52,53,48,0,0,0,0,43,53,51,1,1,1,1,1
1,49,53,12,0,0,0,0,0,43,53,52,1,1,1,1,1
1,53,10,0,0,0,0,0,0,43,16,52,1,1,1,1,1
44,12,38,0,0,0,0,0,0,48,12,15,15,15,12,1,1
41,53,38,0,0,0,0,0,0,0,0,0,0,0,0,12,44
41,53,38,0,0,0,0,0,0,0,0,0,0,0,0,23,42
41,53,38,0,0,0,0,0,0,0,0,0,12,0,0,12,41
52,53,12,0,0,0,0,0,0,0,0,0,19,15,15,16,50
1,52,53,38,0,0,0,0,0,0,0,0,19,16,16,12,46
1,1,40,12,39,0,0,0,0,0,0,12,14,14,12,52,1
1,1,1,46,53,12,39,39,39,39,39,14,47,41,51,1,1
1,1,1,1,1,40,53,12,53,53,53,46,1,1,1,1,1
1,1,1,1,1,1,52,47,41,41,52,1,1,1,1,1,1
endlayer

layer
1,1,1,1,1,1,1,1,1,1,1,1,1,1,1,1,1
1,1,1,1,54,44,44,44,51,1,1,1,1,1,1,1,1
1,1,1,1,55,53,53,53,44,44,54,1,1,1,1,1,1
1,1,58,57,55,56,56,56,56,55,55,1,1,1,1,1,1
1,1,40,12,55,16,56,56,56,55,55,1,1,1,1,1,1
1,44,53,56,55,16,16,56,16,55,55,1,1,1,1,1,1
1,40,56,56,55,57,57,57,57,57,12,57,57,57,57,57,59
1,53,56,56,55,16,56,16,56,16,16,55,0,0,0,12,1
1,46,56,56,55,56,56,56,56,56,16,55,0,0,0,55,52
1,40,53,56,55,16,56,16,56,16,16,55,12,0,0,55,51
1,40,57,57,57,57,57,57,57,57,57,55,20,0,0,55,52
1,1,46,53,56,55,16,56,16,16,16,55,20,0,0,12,1
1,1,1,40,55,55,56,56,56,16,16,12,57,57,57,57,59
1,1,1,1,46,55,14,14,14,14,14,55,46,52,1,1,1
1,1,1,1,1,60,46,40,53,51,46,60,1,1,1,1,1
1,1,1,1,1,1,1,1,52,1,1,1,1,1,1,1,1
endlayer

layer
1,1,1,1,1,1,1,1,1,1,1,1,1,1,1,1,1
1,1,1,1,1,1,1,1,1,1,1,1,1,1,1,1,1
1,1,1,1,1,1,52,52,1,1,1,1,1,1,1,1,1
1,1,1,31,12,15,15,15,15,12,31,1,1,1,1,1,1
1,1,1,23,0,0,0,0,0,0,20,1,1,1,1,1,1
1,1,52,23,0,0,0,0,0,61,20,1,1,1,1,1,1
1,1,52,23,0,0,0,0,0,61,12,35,15,15,15,31,1
1,1,52,12,0,0,0,0,0,0,0,20,0,0,0,12,1
1,1,52,23,0,0,0,0,0,0,0,15,0,0,0,20,1
1,1,1,23,0,0,0,0,0,0,0,0,12,0,0,20,1
1,1,1,52,12,0,0,0,0,0,0,0,0,0,0,20,1
1,1,1,1,52,30,0,0,0,0,0,0,0,0,0,12,1
1,1,1,1,1,23,0,62,62,62,0,12,30,30,30,31,1
1,1,1,1,1,31,12,30,30,30,30,31,1,1,1,1,1
1,1,1,1,1,1,1,1,1,1,1,1,1,1,1,1,1
1,1,1,1,1,1,1,1,1,1,1,1,1,1,1,1,1
endlayer

layer
1,1,1,1,1,1,1,1,1,1,1,1,1,1,1,1,1
1,1,1,1,1,1,1,1,1,1,1,1,1,1,1,1,1
1,1,1,1,1,1,1,1,1,1,1,1,1,1,1,1,1
1,1,1,31,12,31,0,31,31,12,31,1,1,1,1,1,1
1,1,1,31,0,0,0,0,0,0,0,1,1,1,1,1,1
1,1,1,0,0,0,0,0,0,33,31,1,1,1,1,1,1
1,1,1,31,0,0,0,0,0,33,12,15,31,31,0,31,1
1,1,1,12,0,0,0,0,0,0,0,31,0,0,0,12,1
1,1,1,31,0,0,0,0,0,0,0,31,0,0,0,31,1
1,1,1,0,0,0,0,0,0,0,0,0,12,0,0,0,1
1,1,1,1,12,0,0,0,0,0,0,0,0,0,0,31,1
1,1,1,1,1,0,0,0,0,0,0,0,0,0,0,12,1
1,1,1,1,1,31,0,33,33,33,0,12,31,0,31,31,1
1,1,1,1,1,31,12,31,31,0,31,31,1,1,1,1,1
1,1,1,1,1,1,1,1,1,1,1,1,1,1,1,1,1
1,1,1,1,1,1,1,1,1,1,1,1,1,1,1,1,1
endlayer

layer
1,1,1,1,1,1,1,1,1,1,1,1,1,1,1,1,1
1,1,1,1,1,1,1,1,1,1,1,1,1,1,1,1,1
1,1,1,1,1,1,1,1,1,41,1,1,1,1,1,1,1
1,1,1,41,12,39,39,39,39,12,1,1,1,1,1,1,1
1,1,1,43,0,0,0,0,0,0,38,1,1,1,1,1,1
1,1,1,43,0,0,0,0,0,0,38,1,1,1,1,1,1
1,1,1,43,0,0,0,0,0,0,12,39,39,39,39,1,1
1,1,1,12,0,0,0,0,0,0,0,14,0,0,0,12,1
1,1,1,43,0,0,0,0,0,0,0,14,0,0,0,38,1
1,1,1,43,0,0,0,0,0,0,0,0,12,0,0,38,1
1,1,1,1,12,0,0,0,0,0,0,0,0,0,0,38,1
1,1,1,1,1,48,0,0,0,0,0,0,0,0,0,12,1
1,1,1,1,1,43,0,0,0,0,0,12,48,48,48,51,1
1,1,1,1,1,42,12,48,48,48,48,41,1,1,1,1,1
1,1,1,1,1,1,41,1,1,1,1,1,1,1,1,1,1
1,1,1,1,1,1,1,1,1,1,1,1,1,1,1,1,1
endlayer

layer
1,1,1,1,1,1,1,1,1,1,1,1,1,1,1,1,1
1,1,1,1,1,1,1,1,1,1,1,1,1,1,1,1,1
1,1,1,1,52,41,41,41,51,1,1,1,1,1,1,1,1
1,1,1,52,12,65,64,64,63,12,51,1,1,1,1,1,1
1,1,41,64,0,0,0,0,0,0,63,41,1,1,1,1,1
1,1,41,65,0,0,0,0,0,0,63,49,50,41,41,1,1
1,1,41,65,0,0,0,0,0,0,12,14,64,64,63,51,1
1,1,52,12,0,0,0,0,0,0,0,63,0,0,0,12,52
1,1,41,65,0,0,0,0,0,0,0,63,0,0,0,63,41
1,1,41,66,0,0,0,0,0,0,0,0,12,0,0,63,41
1,1,1,67,12,0,0,0,0,0,0,0,0,0,0,63,41
1,1,1,1,41,65,0,0,0,0,0,0,0,0,0,12,52
1,1,1,1,41,66,0,0,0,0,0,12,66,66,63,52,1
1,1,1,1,52,46,12,66,66,66,66,53,41,41,52,1,1
1,1,1,1,1,1,1,47,41,41,67,52,1,1,1,1,1
1,1,1,1,1,1,1,1,1,1,1,1,1,1,1,1,1
endlayer

layer
1,1,1,1,1,1,1,1,1,1,1,1,1,1,1,1,1
1,1,1,1,1,1,1,1,1,1,1,1,1,1,1,1,1
1,1,1,1,1,1,52,1,1,1,1,1,1,1,1,1,1
1,1,1,1,40,44,53,53,44,44,1,1,1,1,1,1,1
1,1,1,44,38,48,48,48,48,48,44,1,1,1,1,1,1
1,1,1,40,38,0,0,0,0,0,55,44,44,44,1,1,1
1,1,1,40,38,0,0,0,0,0,12,57,57,51,44,1,1
1,1,1,40,38,0,0,0,0,0,0,14,38,48,43,51,1
1,1,1,40,38,0,0,0,0,0,0,14,38,0,43,51,1
1,1,1,40,38,0,0,0,0,0,0,48,12,0,43,51,1
1,1,1,46,12,39,0,0,0,0,0,13,55,0,43,51,1
1,1,1,1,40,53,38,13,13,13,13,13,55,39,39,46,1
1,1,1,1,1,40,38,39,39,39,39,12,53,51,46,1,1
1,1,1,1,1,1,46,46,46,46,46,52,52,1,1,1,1
1,1,1,1,1,1,1,1,1,1,1,1,1,1,1,1,1
1,1,1,1,1,1,1,1,1,1,1,1,1,1,1,1,1
endlayer

layer
1,1,1,1,1,1,1,1,1,1,1,1,1,1,1,1,1
1,1,1,1,1,1,1,1,1,1,1,1,1,1,1,1,1
1,1,1,1,1,1,1,1,1,1,1,1,1,1,1,1,1
1,1,1,1,1,1,1,1,1,1,1,1,1,1,1,1,1
1,1,1,1,52,44,53,53,53,44,44,1,1,1,1,1,1
1,1,1,1,40,48,48,48,48,48,53,1,1,1,1,1,1
1,1,1,1,53,38,13,13,13,13,14,53,44,1,1,1,1
1,1,1,1,53,38,13,0,0,0,43,14,53,44,51,1,1
1,1,1,1,53,38,13,0,0,0,43,14,14,24,44,1,1
1,1,1,1,40,38,13,0,0,0,43,53,12,14,53,1,1
1,1,1,1,40,53,38,39,39,39,39,53,53,14,46,1,1
1,1,1,1,1,40,53,53,53,53,53,53,53,53,51,1,1
1,1,1,1,1,1,40,46,53,53,53,51,46,46,1,1,1
1,1,1,1,1,1,1,1,1,1,1,1,1,1,1,1,1
1,1,1,1,1,1,1,1,1,1,1,1,1,1,1,1,1
1,1,1,1,1,1,1,1,1,1,1,1,1,1,1,1,1
endlayer

layer
1,1,1,1,1,1,1,1,1,1,1,1,1,1,1,1,1
1,1,1,1,1,1,1,1,1,1,1,1,1,1,1,1,1
1,1,1,1,1,1,1,1,1,1,1,1,1,1,1,1,1
1,1,1,1,1,1,1,1,1,1,1,1,1,1,1,1,1
1,1,1,1,1,1,1,1,1,1,1,1,1,1,1,1,1
1,1,1,1,1,52,44,44,44,44,52,1,1,1,1,1,1
1,1,1,1,1,44,40,53,53,53,53,44,1,1,1,1,1
1,1,1,1,1,40,53,48,48,43,53,53,52,1,1,1,1
1,1,1,1,1,40,53,38,69,43,53,53,51,68,1,1,1
1,1,1,1,1,40,53,39,39,43,53,53,53,51,1,1,1
1,1,1,1,1,46,53,53,53,53,53,53,53,52,1,1,1
1,1,1,1,1,1,40,46,40,53,53,53,52,1,1,1,1
1,1,1,1,1,1,1,1,1,1,1,1,1,1,1,1,1
1,1,1,1,1,1,1,1,1,1,1,1,1,1,1,1,1
1,1,1,1,1,1,1,1,1,1,1,1,1,1,1,1,1
1,1,1,1,1,1,1,1,1,1,1,1,1,1,1,1,1
endlayer

layer
1,1,1,1,1,1,1,1,1,1,1,1,1,1,1,1,1
1,1,1,1,1,1,1,1,1,1,1,1,1,1,1,1,1
1,1,1,1,1,1,1,1,1,1,1,1,1,1,1,1,1
1,1,1,1,1,1,1,1,1,1,1,1,1,1,1,1,1
1,1,1,1,1,1,1,1,1,1,1,1,1,1,1,1,1
1,1,1,1,1,1,1,1,1,1,1,1,1,1,1,1,1
1,1,1,1,1,1,1,68,68,68,68,1,1,1,1,1,1
1,1,1,1,1,1,68,52,52,52,68,68,1,1,1,1,1
1,1,1,1,1,1,68,52,0,52,52,52,68,33,1,1,1
1,1,1,1,1,1,68,52,52,52,52,52,68,1,1,1,1
1,1,1,1,1,1,68,68,68,52,52,52,68,1,1,1,1
1,1,1,1,1,1,1,1,1,68,68,68,1,1,1,1,1
1,1,1,1,1,1,1,1,1,1,1,1,1,1,1,1,1
1,1,1,1,1,1,1,1,1,1,1,1,1,1,1,1,1
1,1,1,1,1,1,1,1,1,1,1,1,1,1,1,1,1
1,1,1,1,1,1,1,1,1,1,1,1,1,1,1,1,1
endlayer

