
# Created by Ruins mod version 16.7 Ingame Parser
# authoring Player: lafuller

weight=1
embed_into_distance=4
acceptable_target_blocks=
unacceptable_target_blocks=flowing_water,water,flowing_lava,lava,ice,bedrock,netherrack,nether_brick,nether_brick_fence,soul_sand,quartz_ore,end_stone,obsidian,iron_bars,cloud,flesh,ash_block,slime_grass,slime_congealed,slime_dirt
biomesToSpawnIn=plains,prarie,meadow,tundra,brushland,shrubland,woodland,woodlands,lavender_fields,flower_field,sunflower_plains,ice_flats,ice_plains
dimensions=13,10,12
allowable_overhang=0
max_leveling=4
leveling_buffer=-1
preserve_water=0
preserve_lava=0

rule1=0,100,preserveBlock
rule2=0,100,stonebrick-0,stonebrick-0,stonebrick-0,stonebrick-0,stonebrick-1,stonebrick-2,stonebrick-2,stone-5,stone-6,cobblestone
rule3=0,100,minecraft:dirt-0
rule4=0,100,minecraft:stone_brick_stairs-0
rule5=0,100,minecraft:stone_brick_stairs-2
rule6=0,100,stonebrick-0,stonebrick-0,stonebrick-0,stonebrick-0,stonebrick-1,stonebrick-2,stonebrick-2,stone-5,stone-6,cobblestone,gravel
rule7=0,100,minecraft:cobblestone_wall-0
rule8=0,100,minecraft:stone_brick_stairs-3
rule9=0,100,minecraft:planks-0
rule10=0,100,minecraft:planks-1
rule11=0,100,minecraft:oak_stairs-0
rule12=0,100,minecraft:stone_brick_stairs-4
rule13=0,100,minecraft:log-0
rule14=0,100,minecraft:stone_brick_stairs-5
rule15=0,100,minecraft:cauldron-0
rule16=0,100,minecraft:oak_stairs-3
rule17=0,100,minecraft:oak_stairs-2
rule18=0,100,minecraft:fence-0
rule19=0,100,minecraft:oak_stairs-1
rule20=0,100,minecraft:jungle_door-2
rule21=0,100,IInventory;minecraft:furnace;minecraft:coal#2#0#1-5
rule22=0,100,minecraft:oak_stairs-5
rule23=0,100,minecraft:jungle_door-9
rule24=0,100,minecraft:dark_oak_stairs-2
rule25=0,100,minecraft:spruce_stairs-4
rule26=0,100,minecraft:dark_oak_stairs-7
rule27=0,100,minecraft:wooden_slab-13
rule28=0,100,minecraft:dark_oak_stairs-4
rule29=0,100,minecraft:dark_oak_stairs-0
rule30=0,100,minecraft:spruce_stairs-7
rule31=0,100,minecraft:spruce_stairs-6
rule32=0,100,minecraft:dark_oak_stairs-1
rule33=0,100,minecraft:spruce_stairs-5
rule34=0,100,minecraft:spruce_fence_gate-1
rule35=0,100,minecraft:wooden_slab-5
rule36=0,100,minecraft:planks-5
rule37=0,100,minecraft:dark_oak_stairs-3
rule38=0,100,minecraft:stone_stairs-5
rule39=0,100,minecraft:dark_oak_stairs-6
rule40=0,100,minecraft:stone_stairs-2
rule41=0,100,minecraft:dark_oak_fence-0
rule42=0,100,ChestGenHook:chests/spawn_bonus_chest:5-4

layer
1,1,1,1,1,1,1,1,1,1,1,1
1,1,1,2,2,2,1,1,1,1,1,1
1,1,2,3,3,3,2,2,2,1,1,1
1,2,3,3,3,3,3,2,2,2,1,1
1,2,3,3,3,3,3,3,3,3,2,1
1,2,3,3,3,3,3,3,3,3,2,1
4,2,3,3,3,3,3,3,3,3,2,1
2,2,3,3,3,3,3,3,3,2,2,1
2,2,2,2,2,2,2,2,2,1,1,1
2,2,2,2,2,2,2,2,5,1,1,1
endlayer

layer
1,1,1,1,1,1,1,1,1,1,1,1
1,1,1,6,7,6,1,1,1,1,1,1
1,1,6,3,3,3,6,6,6,1,1,1
1,6,3,3,3,3,3,6,6,6,1,1
1,7,3,3,3,3,3,3,3,3,6,1
1,6,3,3,3,3,3,3,3,3,7,1
1,7,3,3,3,3,3,3,3,3,6,1
4,6,3,3,3,3,3,3,3,6,6,1
6,6,6,6,6,6,6,6,6,1,1,1
6,6,6,6,6,6,6,5,1,1,1,1
endlayer

layer
1,1,1,1,1,1,1,1,1,1,1,1
1,1,1,6,7,6,1,1,1,1,1,1
1,1,6,3,3,3,6,6,6,1,1,1
1,6,3,3,3,3,3,6,6,6,1,1
1,7,3,3,3,3,3,3,3,3,6,1
1,6,3,3,3,3,3,3,3,3,7,1
1,7,3,3,3,3,3,3,3,3,6,1
1,6,3,3,3,3,3,3,3,6,6,1
4,6,6,6,6,6,6,6,6,1,1,1
6,6,6,6,6,6,5,1,1,1,1,1
endlayer

layer
1,1,1,1,1,1,1,1,1,1,1,1
1,1,1,6,7,6,1,1,1,1,1,1
1,1,6,3,3,3,6,6,6,1,1,1
1,6,3,3,3,3,3,6,6,6,1,1
1,7,3,3,3,3,3,3,3,3,6,1
1,6,3,3,3,3,3,3,3,3,7,1
1,7,3,3,3,3,3,3,3,3,6,1
1,6,3,3,3,3,3,3,3,6,6,1
1,6,6,6,6,6,6,6,6,1,1,1
1,8,6,6,6,5,1,1,1,1,1,1
endlayer

layer
1,1,1,1,1,1,1,1,1,1,1,1
1,1,1,2,2,2,1,1,1,1,1,1
1,1,9,9,9,9,6,6,6,1,1,1
1,2,9,10,10,10,9,6,6,2,1,1
1,2,9,10,9,9,10,10,9,9,2,1
1,2,9,9,10,10,9,9,10,9,2,1
1,2,9,10,10,9,10,10,10,9,2,1
1,2,9,9,9,9,9,9,9,2,2,1
1,2,2,6,2,2,2,2,2,1,1,1
1,1,8,6,5,1,1,1,1,1,1,1
endlayer

layer
1,1,1,1,1,1,1,1,1,1,1,1
1,1,1,11,11,11,1,1,1,1,1,1
1,1,13,42,0,0,13,4,12,1,1,1
1,16,0,0,0,0,0,15,14,13,1,1
1,16,0,0,0,0,0,0,0,0,17,1
1,16,0,0,0,0,0,0,0,0,17,1
1,16,0,0,0,0,0,0,0,0,17,1
1,13,0,0,0,0,0,0,0,13,17,1
1,1,19,20,19,13,19,19,19,18,1,1
1,1,1,1,1,1,1,1,1,1,1,1
endlayer

layer
1,1,1,1,1,1,1,1,1,1,1,1
1,1,1,18,0,18,1,1,1,1,1,1
1,1,13,0,0,0,13,5,4,1,1,1
1,18,0,0,0,0,0,21,6,13,18,1
1,0,0,0,0,0,0,0,0,0,18,1
1,18,0,0,0,0,0,0,0,0,0,1
1,18,0,0,0,0,0,0,0,0,18,1
1,13,0,0,0,0,0,0,0,13,18,1
1,1,22,23,22,13,18,0,18,18,1,1
1,1,1,1,1,1,1,1,1,1,1,1
endlayer

layer
1,1,1,1,1,1,1,1,1,1,1,1
1,27,26,25,25,25,24,1,1,1,1,1
1,28,13,0,0,0,13,4,12,27,1,1
1,30,0,0,0,0,0,7,5,13,29,1
1,30,0,0,0,0,0,0,0,0,31,1
1,30,0,0,0,0,0,0,0,0,31,1
1,30,0,0,0,0,0,0,0,0,31,1
1,13,0,0,0,0,0,0,0,13,31,1
1,26,33,34,33,13,33,33,33,24,32,1
1,1,1,1,1,27,1,1,1,1,1,1
endlayer

layer
1,1,35,27,27,27,35,1,1,1,1,1
1,1,35,36,36,36,29,1,1,1,1,1
35,37,13,33,33,33,13,5,4,24,1,1
27,36,31,0,0,0,0,7,38,13,35,35
27,36,31,0,0,0,0,0,0,30,36,27
27,36,31,0,0,0,0,0,0,30,36,27
27,36,31,0,0,0,0,0,0,30,36,27
35,13,31,25,25,25,25,25,25,13,36,35
1,35,36,36,36,13,36,36,36,35,1,1
1,35,27,27,26,35,39,27,27,35,1,1
endlayer

layer
1,1,1,1,1,1,1,1,1,1,1,1
1,1,1,29,29,29,1,1,1,1,1,1
1,1,29,36,36,36,29,1,1,1,1,1
1,29,36,10,10,10,36,2,40,29,1,1
1,37,36,10,10,10,10,10,36,36,35,1
1,37,36,10,10,10,10,10,10,36,24,1
1,37,36,10,10,10,10,10,10,36,24,1
1,32,36,36,36,36,36,36,36,24,1,1
1,1,37,32,24,35,37,32,35,1,1,1
1,1,1,1,1,1,1,1,1,1,1,1
endlayer

layer
1,1,1,1,1,1,1,1,1,1,1,1
1,1,1,1,1,1,1,1,1,1,1,1
1,1,1,41,41,41,1,1,1,1,1,1
1,1,41,35,35,35,41,7,1,1,1,1
1,1,41,35,35,35,35,35,41,41,1,1
1,1,41,35,35,35,35,35,35,41,1,1
1,1,41,35,35,35,35,35,35,41,1,1
1,1,41,41,41,41,41,41,41,1,1,1
1,1,1,1,1,1,1,1,1,1,1,1
1,1,1,1,1,1,1,1,1,1,1,1
endlayer

layer
1,1,1,1,1,1,1,1,1,1,1,1
1,1,1,1,1,1,1,1,1,1,1,1
1,1,1,1,1,1,1,1,1,1,1,1
1,1,1,1,1,1,1,7,1,1,1,1
1,1,1,1,1,1,1,1,1,1,1,1
1,1,1,1,1,1,1,1,1,1,1,1
1,1,1,1,1,1,1,1,1,1,1,1
1,1,1,1,1,1,1,1,1,1,1,1
1,1,1,1,1,1,1,1,1,1,1,1
1,1,1,1,1,1,1,1,1,1,1,1
endlayer

layer
1,1,1,1,1,1,1,1,1,1,1,1
1,1,1,1,1,1,1,1,1,1,1,1
1,1,1,1,1,1,1,1,1,1,1,1
1,1,1,1,1,1,1,7,1,1,1,1
1,1,1,1,1,1,1,1,1,1,1,1
1,1,1,1,1,1,1,1,1,1,1,1
1,1,1,1,1,1,1,1,1,1,1,1
1,1,1,1,1,1,1,1,1,1,1,1
1,1,1,1,1,1,1,1,1,1,1,1
1,1,1,1,1,1,1,1,1,1,1,1
endlayer

