
# Created by Ruins mod version 16.7 Ingame Parser
# authoring Player: lafuller

weight=1
embed_into_distance=4
acceptable_target_blocks=
unacceptable_target_blocks=flowing_water,water,flowing_lava,lava,ice,bedrock,netherrack,nether_brick,nether_brick_fence,soul_sand,quartz_ore,end_stone,obsidian,iron_bars,cloud,flesh,ash_block,slime_grass,slime_congealed,slime_dirt
biomesToSpawnIn=plains,mutated_plains,forest,birch forest,taiga,woodland,woodlands,prarie,meadow,badlands,lavender fields,flower field,sunflower plains
dimensions=15,15,14
allowable_overhang=0
max_leveling=4
leveling_buffer=-1
preserve_water=0
preserve_lava=0

rule1=0,100,minecraft:stone-6
rule2=0,100,stonebrick-0,stonebrick-2,stonebrick-2,stonebrick-1,stonebrick-1,cobblestone
rule3=0,100,preserveBlock
rule4=0,100,stonebrick-0,stonebrick-2,stonebrick-2,stonebrick-1,stonebrick-1,cobblestone
rule5=0,100,stonebrick-0,stonebrick-1,stonebrick-2,stone-5,stone-5,stone-6
rule6=0,100,stonebrick-0,stonebrick-0,stonebrick-0,stonebrick-2
rule7=0,100,minecraft:stone-5
rule8=0,100,stonebrick-0,stonebrick-0,stonebrick-0,stonebrick-0,stonebrick-1,stonebrick-2,stonebrick-2,stone-5,stone-6,cobblestone,gravel
rule9=0,100,minecraft:cobblestone_wall-0
rule10=0,100,minecraft:log-0
rule11=0,100,minecraft:wooden_slab-9
rule12=0,100,ChestGenHook:chests/spawn_bonus_chest:5-2
rule13=0,100,planks-0,oak_stairs-0,oak_stairs-1,oak_stairs-4,oak_stairs-5,air
rule14=0,100,web-0,air,air,air
rule15=0,100,oak_stairs-2,oak_stairs-2,air
rule16=0,100,oak_stairs-1,oak_stairs-1,air
rule17=0,100,oak_stairs-6,oak_stairs-6,air
rule18=0,100,oak_stairs-3,oak_stairs-3,air
rule19=0,100,planks-1,spruce_stairs-0,spruce_stairs-1,spruce_stairs-4,spruce_stairs-5,air,air,air
rule20=0,100,oak_stairs-0,oak_stairs-0,air
rule21=0,100,oak_stairs-4,oak_stairs-4,air
rule22=0,100,minecraft:mycelium-0
rule23=0,100,stonebrick-0,stonebrick-0,stonebrick-0,stonebrick-0,stonebrick-1,stonebrick-2,stonebrick-2,stone-5,stone-6,cobblestone,stone_brick_stairs-0,stone_brick_stairs-1,stone_brick_stairs-2,stone_brick_stairs-3,stone_brick_stairs-4,stone_brick_stairs-5,stone_brick_stairs-6,stone_brick_stairs-7
rule24=0,100,log-0,log-0,air
rule25=0,100,minecraft:stone_stairs-7
rule26=0,100,minecraft:stone_stairs-4
rule27=0,100,stonebrick-0,stonebrick-1,stonebrick-2,stone-5,stone-6,cobblestone,stone_brick_stairs-0,stone_brick_stairs-1,stone_brick_stairs-2,stone_brick_stairs-3,stone_brick_stairs-4,stone_brick_stairs-5,stone_brick_stairs-6,stone_brick_stairs-7,stone_slab-5,stone_slab-5,stone_slab-5,stone_slab-5
rule28=0,100,minecraft:stone_stairs-1
rule29=0,100,minecraft:stone_stairs-0
rule30=2,100,planks-0,oak_stairs-0,oak_stairs-1,oak_stairs-4,oak_stairs-5,air,air,air,air,air,air

layer
3,3,3,3,3,3,3,1,2,2,2,2,2,1
3,3,3,1,2,2,2,2,4,4,4,4,4,2
3,3,3,2,4,4,4,4,4,5,5,4,4,2
3,3,3,2,4,5,5,5,5,6,5,5,4,2
3,3,3,2,4,5,6,5,6,6,6,5,4,2
3,1,2,2,4,5,5,6,6,6,5,5,4,2
3,2,4,4,4,5,6,6,6,5,4,4,4,2
3,2,4,4,5,5,5,6,6,5,5,4,2,1
3,2,4,5,6,5,6,6,6,6,5,4,2,3
2,2,4,5,5,4,5,6,5,6,5,4,2,3
2,2,4,4,4,4,4,5,5,5,4,2,2,2
2,1,2,2,2,2,2,4,5,4,2,2,2,2
2,2,2,2,2,2,2,4,4,4,2,2,2,2
2,2,2,2,2,2,1,2,2,2,2,2,2,2
2,2,2,2,2,2,2,2,2,3,3,3,3,3
endlayer

layer
3,3,3,3,3,3,3,7,8,9,8,9,8,7
3,3,3,7,8,9,8,8,10,11,11,11,10,8
3,3,3,8,13,13,12,0,0,0,0,0,11,9
3,3,3,9,13,13,14,0,0,0,0,0,11,8
3,3,3,8,13,13,10,0,0,0,0,0,11,8
3,7,8,8,16,16,15,0,0,0,0,0,11,9
3,8,10,0,0,0,0,0,0,0,0,0,10,8
3,9,11,0,0,0,0,0,0,0,0,0,8,7
3,8,11,0,0,0,0,0,0,0,0,0,8,3
3,9,11,0,0,0,0,0,0,0,0,10,8,3
8,8,10,11,11,11,10,0,0,0,0,8,8,8
8,7,8,8,8,8,8,0,0,0,8,8,8,8
8,8,8,8,8,8,8,10,11,10,8,8,8,8
8,8,8,8,8,8,7,8,9,8,8,8,8,8
8,8,8,8,8,8,8,8,3,3,3,3,3,3
endlayer

layer
3,3,3,3,3,3,3,1,8,9,8,9,8,1
3,3,3,1,8,9,8,8,10,14,0,14,10,8
3,3,3,8,13,13,17,14,0,0,0,0,14,9
3,3,3,9,13,13,17,14,0,0,0,0,0,8
3,3,3,8,16,16,10,0,0,0,0,0,0,8
3,1,8,8,0,0,0,0,0,0,0,0,14,9
3,8,10,14,0,0,0,0,0,0,0,0,10,8
3,9,14,0,0,0,0,0,0,0,0,0,8,1
3,8,0,0,0,0,0,0,0,0,0,14,8,3
3,9,14,0,0,0,0,0,0,0,0,10,8,3
3,8,10,14,0,14,10,0,0,0,14,8,8,8
8,1,8,8,8,8,8,14,0,14,8,8,8,8
8,8,8,8,8,8,8,10,14,10,8,8,8,8
8,8,8,8,8,8,1,8,9,8,8,8,8,8
8,8,8,8,8,8,8,3,3,3,3,3,3,3
endlayer

layer
3,3,3,3,3,3,3,7,8,9,8,9,8,7
3,3,3,7,8,9,8,8,10,14,14,14,10,8
3,3,3,8,0,0,18,17,14,14,0,14,14,9
3,3,3,9,0,0,18,17,14,0,0,0,14,8
3,3,3,8,0,0,10,14,0,0,0,0,14,8
3,7,8,8,0,0,14,0,0,0,0,14,14,9
3,8,10,14,0,0,0,0,0,0,0,0,10,8
3,9,14,14,0,0,0,0,0,0,0,14,8,7
3,8,14,0,0,0,0,0,0,0,14,14,8,3
3,9,14,14,0,14,0,0,0,0,14,10,8,3
3,8,10,14,14,14,10,14,0,14,14,8,8,8
3,7,8,8,8,8,8,14,14,14,8,8,8,8
3,8,8,8,8,8,8,10,14,10,8,8,8,8
3,8,8,8,8,8,7,8,9,8,8,8,8,8
3,3,3,3,3,3,3,3,3,3,3,3,3,3
endlayer

layer
3,3,3,3,3,3,3,1,8,8,8,8,8,1
3,3,3,1,8,8,8,8,13,13,13,13,13,8
3,3,3,8,0,0,0,18,13,19,19,19,13,8
3,3,3,8,0,0,0,18,19,30,19,13,13,8
3,3,3,8,0,0,10,20,19,30,19,19,13,8
3,1,8,8,0,0,19,19,30,30,30,19,13,8
3,8,13,13,0,0,19,30,30,19,19,13,13,8
3,8,13,13,21,21,30,30,30,19,13,13,8,1
3,8,13,19,19,13,30,30,30,30,19,13,8,3
3,8,13,19,13,19,19,30,30,19,13,13,8,3
3,8,13,13,13,13,13,19,19,19,13,8,8,8
3,1,8,13,13,8,8,13,13,13,8,22,22,8
3,3,8,8,8,8,8,13,13,13,8,22,22,8
3,3,3,3,3,3,1,8,8,8,8,8,8,8
3,3,3,3,3,3,3,3,3,3,3,3,3,3
endlayer

layer
3,3,3,3,3,3,3,3,0,0,3,3,3,3
3,3,3,3,3,3,0,0,0,0,0,0,3,3
3,3,3,3,0,0,0,0,0,0,0,0,0,3
3,3,3,0,0,0,0,0,0,0,0,0,0,3
3,3,3,0,0,0,10,0,0,0,0,0,0,0
3,3,0,0,0,0,0,0,0,0,0,0,0,0
3,3,0,0,0,0,0,0,0,0,0,0,0,3
3,0,0,0,0,0,0,0,0,0,0,0,0,3
3,0,0,0,0,0,0,0,0,0,0,0,3,3
3,3,0,0,0,0,0,0,0,0,0,0,3,3
3,3,0,0,0,0,0,0,0,0,0,0,23,23
3,3,3,0,0,0,0,0,0,0,0,0,0,23
3,3,3,3,3,3,0,0,0,0,23,0,0,23
3,3,3,3,3,3,3,3,3,3,23,23,23,3
3,3,3,3,3,3,3,3,3,3,3,3,3,3
endlayer

layer
3,3,3,3,3,3,0,0,0,0,0,0,3,3
3,3,3,3,0,0,0,0,0,0,0,0,0,3
3,3,0,0,0,0,0,0,0,0,0,0,0,0
3,3,0,0,0,0,0,0,0,0,0,0,0,0
3,0,0,0,0,0,24,0,0,0,0,0,0,0
3,0,0,0,0,0,0,0,0,0,0,0,0,0
0,0,0,0,0,0,0,0,0,0,0,0,0,0
0,0,0,0,0,0,0,0,0,0,0,0,0,3
0,0,0,0,0,0,0,0,0,0,0,0,0,3
3,0,0,0,0,0,0,0,0,0,0,0,0,3
3,0,0,0,0,0,0,0,0,0,0,0,23,23
3,3,0,0,0,0,0,0,0,0,0,0,0,23
3,3,0,0,0,0,0,0,0,0,23,0,0,23
3,3,3,3,0,0,0,0,0,0,23,23,23,3
3,3,3,3,3,3,0,0,0,3,3,3,3,3
endlayer

layer
3,3,3,3,0,0,0,0,0,0,0,0,0,3
3,3,0,0,0,0,0,0,0,0,0,0,0,0
3,0,0,0,0,0,0,0,0,0,0,0,0,0
3,0,0,0,0,0,0,0,0,0,0,0,0,0
0,0,0,0,0,0,0,0,0,0,0,0,0,0
0,0,0,0,0,0,0,0,0,0,0,0,0,0
0,0,0,0,0,0,0,0,0,0,0,0,0,0
0,0,0,0,0,0,0,0,0,0,0,0,0,0
0,0,0,0,0,0,0,0,0,0,0,0,0,3
0,0,0,0,0,0,0,0,0,0,0,0,0,3
0,0,0,0,0,0,0,0,0,0,0,0,23,23
3,0,0,0,0,0,0,0,0,0,0,0,25,23
3,0,0,0,0,0,0,0,0,0,23,26,0,23
3,3,0,0,0,0,0,0,0,0,23,23,23,3
3,3,3,3,0,0,0,0,0,0,0,3,3,3
endlayer

layer
3,3,0,0,0,0,0,0,0,0,0,0,0,0
3,0,0,0,0,0,0,0,0,0,0,0,0,0
0,0,0,0,0,0,0,0,0,0,0,0,0,0
0,0,0,0,0,0,0,0,0,0,0,0,0,0
0,0,0,0,0,0,0,0,0,0,0,0,0,0
0,0,0,0,0,0,0,0,0,0,0,0,0,0
0,0,0,0,0,0,0,0,0,0,0,0,0,0
0,0,0,0,0,0,0,0,0,0,0,0,0,0
0,0,0,0,0,0,0,0,0,0,0,0,0,0
0,0,0,0,0,0,0,0,0,0,0,0,0,0
0,0,0,0,0,0,0,0,0,0,0,25,23,23
0,0,0,0,0,0,0,0,0,0,26,26,23,23
0,0,0,0,0,0,0,0,0,0,23,23,0,23
3,0,0,0,0,0,0,0,0,0,23,23,23,3
3,3,0,0,0,0,0,0,0,0,0,0,3,3
endlayer

layer
3,0,0,0,0,0,0,0,0,0,0,0,0,0
0,0,0,0,0,0,0,0,0,0,0,0,0,0
0,0,0,0,0,0,0,0,0,0,0,0,0,0
0,0,0,0,0,0,0,0,0,0,0,0,0,0
0,0,0,0,0,0,0,0,0,0,0,0,0,0
0,0,0,0,0,0,0,0,0,0,0,0,0,0
0,0,0,0,0,0,0,0,0,0,0,0,0,0
0,0,0,0,0,0,0,0,0,0,0,0,0,0
0,0,0,0,0,0,0,0,0,0,0,0,0,0
0,0,0,0,0,0,0,0,0,0,0,0,0,0
0,0,0,0,0,0,0,0,0,0,0,0,0,0
0,0,0,0,0,0,0,0,0,0,0,0,23,23
0,0,0,0,0,0,0,0,0,0,0,23,0,23
0,0,0,0,0,0,0,0,0,0,0,23,23,0
3,0,0,0,0,0,0,0,0,0,0,0,0,3
endlayer

layer
0,0,0,0,0,0,0,0,0,0,0,0,0,0
0,0,0,0,0,0,0,0,0,0,0,0,0,0
0,0,0,0,0,0,0,0,0,0,0,0,0,0
0,0,0,0,0,0,0,0,0,0,0,0,0,0
0,0,0,0,0,0,0,0,0,0,0,0,0,0
0,0,0,0,0,0,0,0,0,0,0,0,0,0
0,0,0,0,0,0,0,0,0,0,0,0,0,0
0,0,0,0,0,0,0,0,0,0,0,0,0,0
0,0,0,0,0,0,0,0,0,0,0,0,0,0
0,0,0,0,0,0,0,0,0,0,0,0,0,0
0,0,0,0,0,0,0,0,0,0,0,0,0,0
0,0,0,0,0,0,0,0,0,0,0,0,23,23
0,0,0,0,0,0,0,0,0,0,0,23,0,23
0,0,0,0,0,0,0,0,0,0,0,23,23,0
0,0,0,0,0,0,0,0,0,0,0,0,0,0
endlayer

layer
0,0,0,0,0,0,0,0,0,0,0,0,0,0
0,0,0,0,0,0,0,0,0,0,0,0,0,0
0,0,0,0,0,0,0,0,0,0,0,0,0,0
0,0,0,0,0,0,0,0,0,0,0,0,0,0
0,0,0,0,0,0,0,0,0,0,0,0,0,0
0,0,0,0,0,0,0,0,0,0,0,0,0,0
0,0,0,0,0,0,0,0,0,0,0,0,0,0
0,0,0,0,0,0,0,0,0,0,0,0,0,0
0,0,0,0,0,0,0,0,0,0,0,0,0,0
0,0,0,0,0,0,0,0,0,0,0,0,0,0
0,0,0,0,0,0,0,0,0,0,0,0,0,0
0,0,0,0,0,0,0,0,0,0,0,0,27,23
0,0,0,0,0,0,0,0,0,0,0,23,0,23
0,0,0,0,0,0,0,0,0,0,0,28,23,0
0,0,0,0,0,0,0,0,0,0,0,0,0,0
endlayer

layer
0,0,0,0,0,0,0,0,0,0,0,0,0,0
0,0,0,0,0,0,0,0,0,0,0,0,0,0
0,0,0,0,0,0,0,0,0,0,0,0,0,0
0,0,0,0,0,0,0,0,0,0,0,0,0,0
0,0,0,0,0,0,0,0,0,0,0,0,0,0
0,0,0,0,0,0,0,0,0,0,0,0,0,0
0,0,0,0,0,0,0,0,0,0,0,0,0,0
0,0,0,0,0,0,0,0,0,0,0,0,0,0
0,0,0,0,0,0,0,0,0,0,0,0,0,0
0,0,0,0,0,0,0,0,0,0,0,0,0,0
0,0,0,0,0,0,0,0,0,0,0,0,0,0
0,0,0,0,0,0,0,0,0,0,0,0,0,29
0,0,0,0,0,0,0,0,0,0,0,27,0,23
0,0,0,0,0,0,0,0,0,0,0,0,23,0
0,0,0,0,0,0,0,0,0,0,0,0,0,0
endlayer

layer
0,0,0,0,0,0,0,0,0,0,0,0,0,0
0,0,0,0,0,0,0,0,0,0,0,0,0,0
0,0,0,0,0,0,0,0,0,0,0,0,0,0
0,0,0,0,0,0,0,0,0,0,0,0,0,0
0,0,0,0,0,0,0,0,0,0,0,0,0,0
0,0,0,0,0,0,0,0,0,0,0,0,0,0
0,0,0,0,0,0,0,0,0,0,0,0,0,0
0,0,0,0,0,0,0,0,0,0,0,0,0,0
0,0,0,0,0,0,0,0,0,0,0,0,0,0
0,0,0,0,0,0,0,0,0,0,0,0,0,0
0,0,0,0,0,0,0,0,0,0,0,0,0,0
0,0,0,0,0,0,0,0,0,0,0,0,0,0
0,0,0,0,0,0,0,0,0,0,0,0,0,23
0,0,0,0,0,0,0,0,0,0,0,0,27,0
0,0,0,0,0,0,0,0,0,0,0,0,0,0
endlayer

layer
0,0,0,0,0,0,0,0,0,0,0,0,0,0
0,0,0,0,0,0,0,0,0,0,0,0,0,0
0,0,0,0,0,0,0,0,0,0,0,0,0,0
0,0,0,0,0,0,0,0,0,0,0,0,0,0
0,0,0,0,0,0,0,0,0,0,0,0,0,0
0,0,0,0,0,0,0,0,0,0,0,0,0,0
0,0,0,0,0,0,0,0,0,0,0,0,0,0
0,0,0,0,0,0,0,0,0,0,0,0,0,0
0,0,0,0,0,0,0,0,0,0,0,0,0,0
0,0,0,0,0,0,0,0,0,0,0,0,0,0
0,0,0,0,0,0,0,0,0,0,0,0,0,0
0,0,0,0,0,0,0,0,0,0,0,0,0,0
0,0,0,0,0,0,0,0,0,0,0,0,0,27
0,0,0,0,0,0,0,0,0,0,0,0,0,0
0,0,0,0,0,0,0,0,0,0,0,0,0,0
endlayer

