
# Created by Ruins mod version 16.7 Ingame Parser
# authoring Player: lafuller

weight=1
embed_into_distance=9
acceptable_target_blocks=grass,stone,dirt
unacceptable_target_blocks=
dimensions=14,10,11
allowable_overhang=0
max_leveling=7
leveling_buffer=-1
preserve_water=0
preserve_lava=0

rule1=0,100,preserveBlock
rule2=0,100,minecraft:stone-5

layer
1,1,1,1,1,1,1,1,1,1,1
1,1,1,2,2,1,1,2,1,1,1
1,1,1,1,1,1,1,2,2,1,1
1,2,2,1,2,2,1,1,1,1,1
1,2,2,1,2,2,1,1,1,1,1
1,1,1,1,1,1,1,1,2,2,1
1,1,2,2,1,2,2,1,2,1,1
1,1,1,2,1,2,2,1,1,1,1
1,1,1,1,1,1,1,1,1,1,1
1,1,1,1,1,1,1,1,1,1,1
endlayer

layer
1,1,1,2,1,1,1,2,1,1,1
1,1,2,2,2,1,1,2,2,1,1
1,1,1,2,1,1,1,2,2,1,1
1,1,2,1,2,2,2,1,1,1,1
2,2,2,1,2,2,2,1,1,2,1
1,1,1,2,1,2,2,1,2,2,2
1,2,2,2,2,1,1,2,2,1,1
1,1,2,2,1,2,2,1,1,1,1
1,1,2,1,1,2,2,1,1,1,1
1,1,1,1,1,1,2,1,1,1,1
endlayer

layer
1,1,1,2,2,1,1,2,1,1,1
1,1,2,2,2,2,2,2,2,2,1
1,2,2,2,2,2,2,2,2,2,1
2,2,2,2,2,2,2,2,2,1,1
2,2,2,2,2,2,2,2,2,2,1
1,2,2,2,2,2,2,2,2,2,1
2,2,2,2,2,2,2,2,2,2,1
1,2,2,2,2,2,2,2,2,1,1
1,1,2,2,1,2,2,2,1,1,1
1,1,1,2,1,1,2,1,1,1,1
endlayer

layer
1,1,1,2,1,1,1,2,1,1,1
1,1,1,2,2,2,1,2,2,1,1
1,1,2,2,2,2,2,2,2,2,1
1,2,2,2,2,2,2,2,1,1,1
2,2,2,1,2,2,2,2,2,1,1
1,1,2,2,2,2,2,1,2,2,2
1,2,2,2,2,2,1,2,2,2,1
1,1,2,2,2,2,2,2,2,1,1
1,1,1,2,1,2,2,1,1,1,1
1,1,1,2,1,1,1,1,1,1,1
endlayer

layer
1,1,1,1,1,1,1,1,1,1,1
1,1,1,2,2,1,1,2,2,1,1
1,1,2,2,1,2,1,2,2,1,1
1,1,2,2,2,2,2,1,1,1,1
2,2,2,1,2,2,2,2,1,1,1
1,1,1,2,1,2,2,1,2,2,2
1,1,2,2,2,2,1,2,2,1,1
1,1,2,2,1,2,2,1,2,1,1
1,1,2,2,1,2,2,1,1,1,1
1,1,1,1,1,1,1,1,1,1,1
endlayer

layer
1,1,1,2,1,1,1,2,1,1,1
1,1,2,2,2,1,1,2,2,1,1
1,1,1,2,1,1,1,2,2,1,1
1,1,2,1,2,2,2,1,1,1,1
2,2,2,1,2,2,2,1,1,2,1
1,1,1,2,1,2,2,1,2,2,2
1,2,2,2,2,1,1,2,2,1,1
1,1,2,2,1,2,2,1,1,1,1
1,1,2,1,1,2,2,1,1,1,1
1,1,1,1,1,1,2,1,1,1,1
endlayer

layer
1,1,1,2,1,1,1,2,1,1,1
1,1,2,2,2,1,2,2,2,1,1
1,1,1,2,1,1,1,2,2,2,1
1,1,2,1,2,2,1,1,1,1,1
1,2,2,1,2,2,2,1,1,2,1
1,1,1,1,1,2,2,1,2,2,2
1,2,2,2,2,1,1,1,2,1,1
1,1,2,2,1,2,2,1,1,1,1
1,1,1,1,1,2,2,2,1,1,1
1,1,1,1,1,1,2,1,1,1,1
endlayer

layer
1,1,1,1,1,1,1,1,1,1,1
1,1,2,2,2,1,2,2,1,1,1
1,1,1,1,1,1,1,2,2,2,1
1,1,2,1,2,2,1,1,1,1,1
1,2,2,1,2,2,2,1,1,2,1
1,1,1,1,1,2,2,1,2,2,1
1,1,2,2,1,1,1,1,2,1,1
1,1,2,2,1,2,2,1,1,1,1
1,1,1,1,1,2,2,2,1,1,1
1,1,1,1,1,1,1,1,1,1,1
endlayer

layer
1,1,1,1,1,1,1,1,1,1,1
1,1,1,2,2,1,2,2,1,1,1
1,1,1,1,1,1,1,2,2,1,1
1,1,2,1,2,2,1,1,1,1,1
1,2,2,1,2,2,2,1,1,1,1
1,1,1,1,1,2,2,1,2,2,1
1,1,2,2,1,1,1,1,2,1,1
1,1,1,2,1,2,2,1,1,1,1
1,1,1,1,1,2,2,1,1,1,1
1,1,1,1,1,1,1,1,1,1,1
endlayer

layer
1,1,1,1,1,1,1,1,1,1,1
1,1,1,2,2,1,1,2,1,1,1
1,1,1,1,1,1,1,2,1,1,1
1,1,2,1,2,2,1,1,1,1,1
1,1,2,1,2,2,2,1,1,1,1
1,1,1,1,1,2,2,1,2,1,1
1,1,2,2,1,1,1,1,2,1,1
1,1,1,1,1,2,2,1,1,1,1
1,1,1,1,1,1,2,1,1,1,1
1,1,1,1,1,1,1,1,1,1,1
endlayer

layer
1,1,1,1,1,1,1,1,1,1,1
1,1,1,1,2,1,1,1,1,1,1
1,1,1,1,1,1,1,2,1,1,1
1,1,1,1,1,2,1,1,1,1,1
1,1,2,1,2,2,2,1,1,1,1
1,1,1,1,1,2,1,1,2,1,1
1,1,1,2,1,1,1,1,1,1,1
1,1,1,1,1,2,2,1,1,1,1
1,1,1,1,1,1,1,1,1,1,1
1,1,1,1,1,1,1,1,1,1,1
endlayer

layer
1,1,1,1,1,1,1,1,1,1,1
1,1,1,1,1,1,1,1,1,1,1
1,1,1,1,1,1,1,2,1,1,1
1,1,1,1,1,1,1,1,1,1,1
1,1,1,1,2,2,2,1,1,1,1
1,1,1,1,1,1,1,1,1,1,1
1,1,1,2,1,1,1,1,1,1,1
1,1,1,1,1,2,1,1,1,1,1
1,1,1,1,1,1,1,1,1,1,1
1,1,1,1,1,1,1,1,1,1,1
endlayer

layer
1,1,1,1,1,1,1,1,1,1,1
1,1,1,1,1,1,1,1,1,1,1
1,1,1,1,1,1,1,1,1,1,1
1,1,1,1,1,1,1,1,1,1,1
1,1,1,1,1,2,2,1,1,1,1
1,1,1,1,1,1,1,1,1,1,1
1,1,1,1,1,1,1,1,1,1,1
1,1,1,1,1,2,1,1,1,1,1
1,1,1,1,1,1,1,1,1,1,1
1,1,1,1,1,1,1,1,1,1,1
endlayer

layer
1,1,1,1,1,1,1,1,1,1,1
1,1,1,1,1,1,1,1,1,1,1
1,1,1,1,1,1,1,1,1,1,1
1,1,1,1,1,1,1,1,1,1,1
1,1,1,1,1,2,1,1,1,1,1
1,1,1,1,1,1,1,1,1,1,1
1,1,1,1,1,1,1,1,1,1,1
1,1,1,1,1,1,1,1,1,1,1
1,1,1,1,1,1,1,1,1,1,1
1,1,1,1,1,1,1,1,1,1,1
endlayer

