
# Created by Ruins mod version 16.7 Ingame Parser
# authoring Player: lafuller

weight=1
embed_into_distance=4
acceptable_target_blocks=
unacceptable_target_blocks=flowing_water,water,flowing_lava,lava,ice,bedrock,netherrack,nether_brick,nether_brick_fence,soul_sand,quartz_ore,end_stone,obsidian,iron_bars,cloud,flesh,ash_block,slime_grass,slime_congealed,slime_dirt
biomesToSpawnIn=plains,prarie,meadow,tundra,brushland,shrubland,woodland,woodlands,lavender_fields,flower_field,sunflower_plains,ice_flats,ice_plains
dimensions=13,11,11
allowable_overhang=0
max_leveling=4
leveling_buffer=-1
preserve_water=0
preserve_lava=0

rule1=0,100,preserveBlock
rule2=0,100,minecraft:stone_brick_stairs-2
rule3=0,100,stonebrick-0,stonebrick-0,stonebrick-0,stonebrick-0,stonebrick-1,stonebrick-2,stonebrick-2,stone-5,stone-6,cobblestone
rule4=0,100,minecraft:dirt-0
rule5=0,100,minecraft:stone_brick_stairs-1
rule6=0,100,minecraft:stone_brick_stairs-0
rule7=0,100,minecraft:stone_brick_stairs-3
rule8=0,100,stonebrick-0,stonebrick-0,stonebrick-0,stonebrick-0,stonebrick-1,stonebrick-2,stonebrick-2,stone-5,stone-6,cobblestone,gravel
rule9=0,100,minecraft:cobblestone_wall-0
rule10=0,100,minecraft:planks-0
rule11=0,100,minecraft:planks-1
rule12=0,100,minecraft:oak_stairs-2
rule13=0,100,minecraft:log-0
rule14=0,100,minecraft:oak_stairs-0
rule15=0,100,minecraft:oak_stairs-3
rule16=0,100,minecraft:fence-0
rule17=0,100,minecraft:cauldron-0
rule18=0,100,minecraft:oak_stairs-1
rule19=0,100,minecraft:jungle_door-2
rule20=0,100,IInventory;minecraft:furnace;minecraft:coal#3#0#1-4
rule21=0,100,minecraft:stone_brick_stairs-4
rule22=0,100,minecraft:stone_brick_stairs-7
rule23=0,100,minecraft:oak_stairs-5
rule24=0,100,minecraft:jungle_door-8
rule25=0,100,minecraft:wooden_slab-13
rule26=0,100,minecraft:spruce_stairs-6
rule27=0,100,minecraft:spruce_stairs-4
rule28=0,100,minecraft:dark_oak_stairs-7
rule29=0,100,minecraft:dark_oak_stairs-6
rule30=0,100,minecraft:spruce_stairs-7
rule31=0,100,minecraft:dark_oak_stairs-2
rule32=0,100,minecraft:dark_oak_stairs-1
rule33=0,100,minecraft:stone_brick_stairs-5
rule34=0,100,minecraft:dark_oak_stairs-5
rule35=0,100,minecraft:spruce_stairs-5
rule36=0,100,minecraft:spruce_fence_gate-1
rule37=0,100,minecraft:wooden_slab-5
rule38=0,100,minecraft:planks-5
rule39=0,100,minecraft:dark_oak_stairs-0
rule40=0,100,minecraft:stone_brick_stairs-6
rule41=0,100,minecraft:dark_oak_stairs-3
rule42=0,100,minecraft:dark_oak_fence-0
rule43=0,100,ChestGenHook:chests/spawn_bonus_chest:5-4

layer
3,3,3,3,3,3,3,3,2,1,1
3,3,3,3,3,3,3,3,2,1,1
3,3,4,4,4,4,4,3,2,1,1
5,3,4,4,4,4,4,4,3,3,1
1,3,4,4,4,4,4,4,4,3,1
1,3,4,4,4,4,4,4,4,3,1
1,3,4,4,4,4,4,4,4,3,1
1,3,3,3,3,4,4,4,4,3,6
1,7,3,3,3,4,4,4,3,3,3
1,7,3,3,3,3,3,3,3,3,3
1,7,3,3,3,3,3,3,3,3,3
endlayer

layer
8,8,8,8,8,8,8,2,1,1,1
8,8,8,8,8,8,8,8,1,1,1
5,8,4,4,4,4,4,8,1,1,1
1,8,4,4,4,4,4,4,8,8,1
1,8,4,4,4,4,4,4,4,9,1
1,9,4,4,4,4,4,4,4,8,1
1,8,4,4,4,4,4,4,4,9,1
1,8,8,8,8,4,4,4,4,8,1
1,1,7,8,8,4,4,4,8,8,6
1,1,7,8,8,8,8,8,8,8,2
1,1,7,8,8,8,8,8,8,8,2
endlayer

layer
8,8,8,8,8,8,2,1,1,1,1
5,8,8,8,8,8,8,8,1,1,1
1,8,4,4,4,4,4,8,1,1,1
1,8,4,4,4,4,4,4,8,8,1
1,8,4,4,4,4,4,4,4,9,1
1,9,4,4,4,4,4,4,4,8,1
1,8,4,4,4,4,4,4,4,9,1
1,8,8,8,8,4,4,4,4,8,1
1,1,1,8,8,4,4,4,8,8,1
1,1,1,7,8,8,8,8,8,2,1
1,1,1,7,8,8,8,8,8,2,1
endlayer

layer
1,7,8,8,8,2,1,1,1,1,1
1,7,8,8,8,8,8,8,1,1,1
1,8,4,4,4,4,4,8,1,1,1
1,8,4,4,4,4,4,4,8,8,1
1,8,4,4,4,4,4,4,4,9,1
1,9,4,4,4,4,4,4,4,8,1
1,8,4,4,4,4,4,4,4,9,1
1,8,8,8,8,4,4,4,4,8,1
1,1,1,8,8,4,4,4,8,8,1
1,1,1,1,7,8,8,8,2,1,1
1,1,1,1,7,8,8,8,2,1,1
endlayer

layer
1,1,7,8,2,1,1,1,1,1,1
1,1,3,3,3,3,3,3,1,1,1
1,3,10,10,10,10,10,3,1,1,1
1,3,10,10,11,11,10,10,3,3,1
1,3,10,11,10,10,11,10,10,3,1
1,3,10,11,11,10,10,11,10,3,1
1,3,10,10,10,11,10,11,10,3,1
1,3,3,8,8,10,11,11,10,3,1
1,1,1,8,8,10,10,10,3,3,1
1,1,1,1,1,3,10,8,1,1,1
1,1,1,1,1,7,8,2,1,1,1
endlayer

layer
1,1,1,1,1,1,1,1,1,1,1
1,1,14,13,14,14,13,12,1,1,1
1,15,43,0,0,0,0,14,1,1,1
1,13,0,0,0,0,0,0,13,16,1
1,15,0,0,0,0,0,0,0,12,1
1,15,0,0,0,0,0,0,0,12,1
1,15,0,0,0,0,0,0,0,12,1
1,16,13,8,17,0,0,0,0,12,1
1,1,1,5,7,0,0,0,13,16,1
1,1,1,1,1,13,19,18,1,1,1
1,1,1,1,1,1,1,1,1,1,1
endlayer

layer
1,1,1,1,1,1,1,1,1,1,1
1,1,16,13,0,0,13,16,1,1,1
1,16,0,0,0,0,0,16,1,1,1
1,13,0,0,0,0,0,0,13,16,1
1,16,0,0,0,0,0,0,0,0,1
1,0,0,0,0,0,0,0,0,16,1
1,16,0,0,0,0,0,0,0,0,1
1,16,13,21,20,0,0,0,0,16,1
1,1,1,5,22,0,0,0,13,16,1
1,1,1,1,1,13,24,23,1,1,1
1,1,1,1,1,1,1,1,1,1,1
endlayer

layer
1,1,1,1,1,1,1,25,1,1,1
1,28,27,13,27,27,13,26,25,1,1
1,30,0,0,0,0,0,27,29,1,1
1,13,0,0,0,0,0,0,13,31,1
1,30,0,0,0,0,0,0,0,26,1
1,30,0,0,0,0,0,0,0,26,1
1,30,0,0,0,0,0,0,0,26,1
1,32,13,6,9,0,0,0,0,26,1
1,1,1,33,21,0,0,0,13,32,1
1,1,1,25,25,13,36,35,34,1,1
1,1,1,1,1,1,1,1,1,1,1
endlayer

layer
1,1,37,29,25,25,37,1,1,1,1
1,1,39,13,38,38,13,31,1,1,1
37,39,35,35,35,35,35,38,39,1,1
25,13,26,0,0,0,30,35,13,31,1
25,38,26,0,0,0,0,0,30,38,37
25,38,26,0,0,0,0,0,30,38,25
37,38,26,0,0,0,0,0,30,38,25
1,1,13,22,40,0,0,0,30,38,37
1,1,1,5,7,27,27,27,38,1,1
1,1,1,1,32,38,38,38,31,1,1
1,1,1,1,1,37,25,37,1,1,1
endlayer

layer
1,1,1,1,37,1,1,1,1,1,1
1,1,1,39,41,31,39,1,1,1,1
1,1,41,38,38,38,38,31,1,1,1
1,41,38,11,11,11,38,38,37,1,1
37,41,38,11,11,11,11,38,31,1,1
1,41,38,11,11,11,11,11,38,39,1
1,1,38,38,38,11,11,11,38,32,1
1,1,32,32,8,38,11,11,38,31,1
1,1,1,1,1,38,38,38,32,1,1
1,1,1,1,1,32,41,31,1,1,1
1,1,1,1,1,1,1,1,1,1,1
endlayer

layer
1,1,1,1,1,1,1,1,1,1,1
1,1,1,1,1,1,1,1,1,1,1
1,1,1,42,42,42,42,1,1,1,1
1,1,42,37,37,37,42,42,1,1,1
1,1,42,37,37,37,37,42,1,1,1
1,1,42,37,37,37,37,37,42,1,1
1,1,42,42,42,37,37,37,42,1,1
1,1,1,1,9,42,37,37,42,1,1
1,1,1,1,1,42,42,42,1,1,1
1,1,1,1,1,1,1,1,1,1,1
1,1,1,1,1,1,1,1,1,1,1
endlayer

layer
1,1,1,1,1,1,1,1,1,1,1
1,1,1,1,1,1,1,1,1,1,1
1,1,1,1,1,1,1,1,1,1,1
1,1,1,1,1,1,1,1,1,1,1
1,1,1,1,1,1,1,1,1,1,1
1,1,1,1,1,1,1,1,1,1,1
1,1,1,1,1,1,1,1,1,1,1
1,1,1,1,9,1,1,1,1,1,1
1,1,1,1,1,1,1,1,1,1,1
1,1,1,1,1,1,1,1,1,1,1
1,1,1,1,1,1,1,1,1,1,1
endlayer

layer
1,1,1,1,1,1,1,1,1,1,1
1,1,1,1,1,1,1,1,1,1,1
1,1,1,1,1,1,1,1,1,1,1
1,1,1,1,1,1,1,1,1,1,1
1,1,1,1,1,1,1,1,1,1,1
1,1,1,1,1,1,1,1,1,1,1
1,1,1,1,1,1,1,1,1,1,1
1,1,1,1,9,1,1,1,1,1,1
1,1,1,1,1,1,1,1,1,1,1
1,1,1,1,1,1,1,1,1,1,1
1,1,1,1,1,1,1,1,1,1,1
endlayer

