
# Created by Ruins mod version 16.7 Ingame Parser
# authoring Player: lafuller

weight=1
embed_into_distance=4
acceptable_target_blocks=water
unacceptable_target_blocks=
biomesToSpawnIn=ocean,deep ocean,ocean oil field,kelp forest
dimensions=23,24,24
allowable_overhang=0
max_leveling=0
leveling_buffer=-1
preserve_water=0
preserve_lava=0

rule1=0,100,preserveBlock
rule2=0,100,minecraft:planks-5
rule3=0,100,minecraft:dark_oak_stairs-1
rule4=0,100,minecraft:dark_oak_stairs-3
rule5=1,100,minecraft:hay_block-8,air,air
rule6=1,100,minecraft:hay_block-0,air,air
rule7=1,100,minecraft:hay_block-4,air,air
rule8=1,100,minecraft:crafting_table-0,bookshelf,air,air
rule9=0,100,minecraft:dark_oak_stairs-2
rule10=0,100,minecraft:dark_oak_stairs-0
rule11=1,100,minecraft:melon_block-0,pumpkin,air,air
rule12=0,100,minecraft:planks-1
rule13=0,100,minecraft:spruce_stairs-4
rule14=0,100,minecraft:spruce_stairs-2
rule15=0,100,minecraft:spruce_stairs-6
rule16=0,100,minecraft:spruce_stairs-0
rule17=0,100,minecraft:spruce_stairs-7
rule18=0,100,minecraft:spruce_stairs-5
rule19=0,100,minecraft:spruce_stairs-3
rule20=0,100,minecraft:spruce_stairs-1
rule21=0,100,ChestGenHook:chests/stronghold_crossing:5-3
rule22=0,100,minecraft:dark_oak_stairs-4
rule23=0,100,minecraft:trapdoor-14
rule24=0,100,minecraft:trapdoor-10
rule25=0,100,minecraft:wooden_slab-1
rule26=0,100,minecraft:trapdoor-13
rule27=0,100,minecraft:wooden_slab-9
rule28=0,100,minecraft:trapdoor-8
rule29=0,100,minecraft:trapdoor-11
rule30=0,100,minecraft:trapdoor-9
rule31=0,100,minecraft:dark_oak_stairs-6
rule32=0,100,minecraft:trapdoor-12
rule33=0,100,minecraft:trapdoor-15
rule34=0,100,minecraft:spruce_fence-0
rule35=0,100,minecraft:log-0
rule36=0,100,minecraft:ladder-5
rule37=0,100,minecraft:spruce_door-1
rule38=0,100,minecraft:ladder-4
rule39=0,100,ChestGenHook:chests/stronghold_corridor:5-5
rule40=0,100,minecraft:carpet-7
rule41=0,100,minecraft:carpet-8
rule42=0,100,minecraft:dark_oak_fence-0
rule43=0,100,minecraft:wooden_slab-5
rule44=0,100,minecraft:spruce_door-9
rule45=0,100,minecraft:wool-0
rule46=0,100,minecraft:log-12
rule47=0,100,minecraft:log-8
rule48=0,100,minecraft:log-4
rule49=0,100,minecraft:trapdoor-0

layer
1,1,1,1,1,1,1,1,1,1,1,1,1,1,1,1,1,1,1,1,1,1,1,1
1,1,1,1,1,1,1,1,1,1,1,1,1,1,1,1,1,1,1,1,1,1,1,1
1,1,1,1,1,1,1,1,1,1,1,1,1,1,1,1,1,1,1,1,1,1,1,1
1,1,1,1,1,1,1,1,1,1,1,1,1,1,1,1,1,1,1,1,1,1,1,1
1,1,1,1,1,1,1,1,1,1,1,1,1,1,1,1,1,1,1,1,1,1,1,1
1,1,1,1,1,1,1,1,1,1,1,1,1,1,1,1,1,1,1,1,1,1,1,1
1,1,1,1,1,1,1,1,1,1,1,1,1,1,1,1,1,1,1,1,1,1,1,1
1,1,1,1,1,1,1,1,1,1,1,1,1,1,1,2,2,1,1,1,1,1,1,1
1,1,1,1,1,1,1,1,1,1,1,1,1,1,2,2,2,1,1,1,1,1,1,1
1,1,1,1,1,1,1,1,1,1,1,1,1,2,2,2,1,1,1,1,1,1,1,1
1,1,1,1,1,1,1,1,1,1,1,2,2,2,2,1,1,1,1,1,1,1,1,1
1,1,1,1,1,1,1,1,1,1,2,2,2,2,2,1,1,1,1,1,1,1,1,1
1,1,1,1,1,1,1,1,1,2,2,2,2,2,1,1,1,1,1,1,1,1,1,1
1,1,1,1,1,1,1,1,2,2,2,2,2,1,1,1,1,1,1,1,1,1,1,1
1,1,1,1,1,1,1,2,2,2,2,2,1,1,1,1,1,1,1,1,1,1,1,1
1,1,1,1,1,1,2,2,2,2,2,1,1,1,1,1,1,1,1,1,1,1,1,1
1,1,1,1,1,1,2,2,2,2,1,1,1,1,1,1,1,1,1,1,1,1,1,1
1,1,1,1,1,1,2,2,2,1,1,1,1,1,1,1,1,1,1,1,1,1,1,1
1,1,1,1,1,1,1,1,1,1,1,1,1,1,1,1,1,1,1,1,1,1,1,1
1,1,1,1,1,1,1,1,1,1,1,1,1,1,1,1,1,1,1,1,1,1,1,1
1,1,1,1,1,1,1,1,1,1,1,1,1,1,1,1,1,1,1,1,1,1,1,1
1,1,1,1,1,1,1,1,1,1,1,1,1,1,1,1,1,1,1,1,1,1,1,1
1,1,1,1,1,1,1,1,1,1,1,1,1,1,1,1,1,1,1,1,1,1,1,1
1,1,1,1,1,1,1,1,1,1,1,1,1,1,1,1,1,1,1,1,1,1,1,1
endlayer

layer
1,1,1,1,1,1,1,1,1,1,1,1,1,1,1,1,1,1,1,1,1,1,1,1
1,1,1,1,1,1,1,1,1,1,1,1,1,1,1,1,1,1,1,1,1,1,1,1
1,1,1,1,1,1,1,1,1,1,1,1,1,1,1,1,1,1,1,1,1,1,1,1
1,1,1,1,1,1,1,1,1,1,1,1,1,1,1,1,1,1,1,1,1,1,1,1
1,1,1,1,1,1,1,1,1,1,1,1,1,1,1,1,1,1,1,1,1,1,1,1
1,1,1,1,1,1,1,1,1,1,1,1,1,1,1,1,1,1,1,1,1,1,1,1
1,1,1,1,1,1,1,1,1,1,1,1,1,1,1,1,2,2,1,1,1,1,1,1
1,1,1,1,1,1,1,1,1,1,1,1,1,1,2,2,2,2,1,1,1,1,1,1
1,1,1,1,1,1,1,1,1,1,1,1,2,2,2,2,2,1,1,1,1,1,1,1
1,1,1,1,1,1,1,1,1,1,1,2,2,2,2,2,2,1,1,1,1,1,1,1
1,1,1,1,1,1,1,1,1,1,2,2,2,2,2,2,1,1,1,1,1,1,1,1
1,1,1,1,1,1,1,1,1,2,2,2,2,2,2,2,1,1,1,1,1,1,1,1
1,1,1,1,1,1,1,1,2,2,2,2,2,2,2,1,1,1,1,1,1,1,1,1
1,1,1,1,1,1,1,2,2,2,2,2,2,2,1,1,1,1,1,1,1,1,1,1
1,1,1,1,1,1,2,2,2,2,2,2,2,1,1,1,1,1,1,1,1,1,1,1
1,1,1,1,1,2,2,2,2,2,2,2,1,1,1,1,1,1,1,1,1,1,1,1
1,1,1,1,2,2,2,2,2,2,2,1,1,1,1,1,1,1,1,1,1,1,1,1
1,1,1,1,2,2,2,2,2,2,1,1,1,1,1,1,1,1,1,1,1,1,1,1
1,1,1,1,1,2,2,2,2,1,1,1,1,1,1,1,1,1,1,1,1,1,1,1
1,1,1,1,1,1,2,2,1,1,1,1,1,1,1,1,1,1,1,1,1,1,1,1
1,1,1,1,1,1,1,1,1,1,1,1,1,1,1,1,1,1,1,1,1,1,1,1
1,1,1,1,1,1,1,1,1,1,1,1,1,1,1,1,1,1,1,1,1,1,1,1
1,1,1,1,1,1,1,1,1,1,1,1,1,1,1,1,1,1,1,1,1,1,1,1
1,1,1,1,1,1,1,1,1,1,1,1,1,1,1,1,1,1,1,1,1,1,1,1
endlayer

layer
1,1,1,1,1,1,1,1,1,1,1,1,1,1,1,1,1,1,1,1,1,1,1,1
1,1,1,1,1,1,1,1,1,1,1,1,1,1,1,1,1,1,1,1,1,1,1,1
1,1,1,1,1,1,1,1,1,1,1,1,1,1,1,1,1,1,1,1,1,1,1,1
1,1,1,1,1,1,1,1,1,1,1,1,1,1,1,1,1,1,1,1,1,1,1,1
1,1,1,1,1,1,1,1,1,1,1,1,1,1,1,1,1,1,1,1,1,1,1,1
1,1,1,1,1,1,1,1,1,1,1,1,1,1,1,1,1,2,2,1,1,1,1,1
1,1,1,1,1,1,1,1,1,1,1,1,1,1,1,2,2,2,2,1,1,1,1,1
1,1,1,1,1,1,1,1,1,1,1,1,1,2,2,2,2,2,1,1,1,1,1,1
1,1,1,1,1,1,1,1,1,1,1,2,3,3,3,3,2,2,1,1,1,1,1,1
1,1,1,1,1,1,1,1,1,1,2,6,5,0,0,4,2,1,1,1,1,1,1,1
1,1,1,1,1,1,1,1,1,2,5,7,6,0,0,4,2,1,1,1,1,1,1,1
1,1,1,1,1,1,1,1,2,6,7,5,0,0,0,4,1,1,1,1,1,1,1,1
1,1,1,1,1,1,1,2,5,7,6,0,8,8,8,2,1,1,1,1,1,1,1,1
1,1,1,1,1,1,2,7,7,5,0,8,8,8,2,1,1,1,1,1,1,1,1,1
1,1,1,1,1,2,9,7,6,0,0,8,8,2,1,1,1,1,1,1,1,1,1,1
1,1,1,1,2,2,9,5,0,0,8,8,2,1,1,1,1,1,1,1,1,1,1,1
1,1,1,1,2,2,9,0,0,0,8,2,1,1,1,1,1,1,1,1,1,1,1,1
1,1,1,2,2,2,10,10,10,10,2,1,1,1,1,1,1,1,1,1,1,1,1,1
1,1,1,2,2,2,2,2,2,2,1,1,1,1,1,1,1,1,1,1,1,1,1,1
1,1,1,1,2,2,2,2,2,1,1,1,1,1,1,1,1,1,1,1,1,1,1,1
1,1,1,1,1,2,2,1,1,1,1,1,1,1,1,1,1,1,1,1,1,1,1,1
1,1,1,1,1,1,1,1,1,1,1,1,1,1,1,1,1,1,1,1,1,1,1,1
1,1,1,1,1,1,1,1,1,1,1,1,1,1,1,1,1,1,1,1,1,1,1,1
1,1,1,1,1,1,1,1,1,1,1,1,1,1,1,1,1,1,1,1,1,1,1,1
endlayer

layer
1,1,1,1,1,1,1,1,1,1,1,1,1,1,1,1,1,1,1,1,1,1,1,1
1,1,1,1,1,1,1,1,1,1,1,1,1,1,1,1,1,1,1,1,1,1,1,1
1,1,1,1,1,1,1,1,1,1,1,1,1,1,1,1,1,1,1,1,1,1,1,1
1,1,1,1,1,1,1,1,1,1,1,1,1,1,1,1,1,1,1,1,1,1,1,1
1,1,1,1,1,1,1,1,1,1,1,1,1,1,1,1,1,2,2,1,1,1,1,1
1,1,1,1,1,1,1,1,1,1,1,1,1,1,1,1,2,2,2,2,1,1,1,1
1,1,1,1,1,1,1,1,1,1,1,1,1,1,2,2,2,2,2,2,1,1,1,1
1,1,1,1,1,1,1,1,1,1,1,1,2,3,3,3,3,2,2,1,1,1,1,1
1,1,1,1,1,1,1,1,1,1,2,2,0,0,0,0,4,2,1,1,1,1,1,1
1,1,1,1,1,1,1,1,1,2,6,7,0,0,0,0,4,2,1,1,1,1,1,1
1,1,1,1,1,1,1,1,2,7,6,0,0,0,0,0,4,1,1,1,1,1,1,1
1,1,1,1,1,1,1,2,5,5,0,0,0,0,0,0,2,1,1,1,1,1,1,1
1,1,1,1,1,1,2,7,6,7,0,0,0,0,8,2,1,1,1,1,1,1,1,1
1,1,1,1,1,2,5,6,0,0,0,0,8,8,8,2,1,1,1,1,1,1,1,1
1,1,1,1,2,5,6,0,0,0,0,0,8,8,2,1,1,1,1,1,1,1,1,1
1,1,1,1,2,6,7,0,0,0,0,8,8,2,1,1,1,1,1,1,1,1,1,1
1,1,1,2,11,0,0,0,0,0,0,8,2,1,1,1,1,1,1,1,1,1,1,1
1,1,1,2,11,11,0,0,0,0,8,2,1,1,1,1,1,1,1,1,1,1,1,1
1,1,2,2,11,11,0,4,2,2,2,1,1,1,1,1,1,1,1,1,1,1,1,1
1,1,2,2,11,11,11,11,2,2,1,1,1,1,1,1,1,1,1,1,1,1,1,1
1,1,1,2,2,2,2,2,1,1,1,1,1,1,1,1,1,1,1,1,1,1,1,1
1,1,1,1,2,2,1,1,1,1,1,1,1,1,1,1,1,1,1,1,1,1,1,1
1,1,1,1,1,1,1,1,1,1,1,1,1,1,1,1,1,1,1,1,1,1,1,1
1,1,1,1,1,1,1,1,1,1,1,1,1,1,1,1,1,1,1,1,1,1,1,1
endlayer

layer
1,1,1,1,1,1,1,1,1,1,1,1,1,1,1,1,1,1,1,1,1,1,1,1
1,1,1,1,1,1,1,1,1,1,1,1,1,1,1,1,1,1,1,1,1,1,1,1
1,1,1,1,1,1,1,1,1,1,1,1,1,1,1,1,1,1,1,1,1,1,1,1
1,1,1,1,1,1,1,1,1,1,1,1,1,1,1,1,1,1,1,1,1,1,1,1
1,1,1,1,1,1,1,1,1,1,1,1,1,1,1,1,13,12,12,12,1,1,1,1
1,1,1,1,1,1,1,1,1,1,1,1,1,1,13,12,12,12,12,12,1,1,1,1
1,1,1,1,1,1,1,1,1,1,1,1,13,12,14,0,0,0,12,12,1,1,1,1
1,1,1,1,1,1,1,1,1,1,13,12,12,0,0,0,0,0,12,15,1,1,1,1
1,1,1,1,1,1,1,1,1,13,12,0,0,0,0,0,0,0,12,1,1,1,1,1
1,1,1,1,1,1,1,1,13,12,5,0,0,0,0,0,0,16,15,1,1,1,1,1
1,1,1,1,1,1,1,13,12,6,7,0,0,0,0,0,0,12,1,1,1,1,1,1
1,1,1,1,1,1,13,12,6,7,0,0,0,0,0,0,12,12,1,1,1,1,1,1
1,1,1,1,1,17,12,5,5,0,0,0,0,0,0,0,12,15,1,1,1,1,1,1
1,1,1,1,17,12,6,0,0,0,0,0,0,8,8,12,15,1,1,1,1,1,1,1
1,1,1,17,12,7,5,0,0,0,0,0,8,8,12,15,1,1,1,1,1,1,1,1
1,1,1,12,0,0,0,0,0,0,0,0,8,12,15,1,1,1,1,1,1,1,1,1
1,1,12,11,0,0,0,0,0,0,0,8,12,15,1,1,1,1,1,1,1,1,1,1
1,13,12,11,11,0,0,0,0,0,0,12,18,1,1,1,1,1,1,1,1,1,1,1
1,17,12,11,11,0,0,0,19,12,12,18,1,1,1,1,1,1,1,1,1,1,1,1
1,18,12,11,11,11,11,11,11,12,18,1,1,1,1,1,1,1,1,1,1,1,1,1
1,1,12,11,11,11,11,11,12,18,1,1,1,1,1,1,1,1,1,1,1,1,1,1
1,1,1,12,12,12,12,12,18,1,1,1,1,1,1,1,1,1,1,1,1,1,1,1
1,1,1,1,17,18,15,1,1,1,1,1,1,1,1,1,1,1,1,1,1,1,1,1
1,1,1,1,1,1,1,1,1,1,1,1,1,1,1,1,1,1,1,1,1,1,1,1
endlayer

layer
1,1,1,1,1,1,1,1,1,1,1,1,1,1,1,1,1,1,1,1,1,1,1,1
1,1,1,1,1,1,1,1,1,1,1,1,1,1,1,1,1,1,1,1,1,1,1,1
1,1,1,1,1,1,1,1,1,1,1,1,1,1,1,1,1,1,1,1,1,1,1,1
1,1,1,1,1,1,1,1,1,1,1,1,1,1,1,1,1,1,1,13,1,1,1,1
1,1,1,1,1,1,1,1,1,1,1,1,1,1,1,13,12,12,12,12,15,1,1,1
1,1,1,1,1,1,1,1,1,1,1,1,1,13,12,12,20,0,0,12,1,1,1,1
1,1,1,1,1,1,1,1,1,1,1,13,12,14,0,0,0,0,0,12,1,1,1,1
1,1,1,1,1,1,1,1,1,1,12,12,0,0,0,0,0,0,19,12,1,1,1,1
1,1,1,1,1,1,1,1,1,12,12,0,0,0,0,0,0,0,12,15,1,1,1,1
1,1,1,1,1,1,1,1,12,12,0,0,0,0,0,0,0,0,12,1,1,1,1,1
1,1,1,1,1,1,1,12,12,5,0,0,0,0,0,0,0,16,15,1,1,1,1,1
1,1,1,1,1,1,12,12,7,0,0,0,0,0,0,0,0,12,1,1,1,1,1,1
1,1,1,1,1,12,12,6,0,0,0,0,0,0,0,0,12,12,1,1,1,1,1,1
1,1,1,1,12,12,7,0,0,0,0,0,0,0,0,12,12,1,1,1,1,1,1,1
1,1,17,12,12,0,0,0,0,0,0,0,0,8,12,12,1,1,1,1,1,1,1,1
1,1,12,12,0,0,0,0,0,0,0,0,8,12,12,1,1,1,1,1,1,1,1,1
1,17,12,0,0,0,0,0,0,0,0,0,12,12,1,1,1,1,1,1,1,1,1,1
1,12,11,11,0,0,0,0,0,0,0,12,12,1,1,1,1,1,1,1,1,1,1,1
1,12,11,11,0,0,0,0,0,19,12,12,1,1,1,1,1,1,1,1,1,1,1,1
1,12,11,11,11,11,0,0,0,12,12,1,1,1,1,1,1,1,1,1,1,1,1,1
1,17,11,11,11,11,0,11,12,12,1,1,1,1,1,1,1,1,1,1,1,1,1,1
1,1,12,11,11,11,11,12,12,18,1,1,1,1,1,1,1,1,1,1,1,1,1,1
1,1,1,18,12,12,12,18,1,1,1,1,1,1,1,1,1,1,1,1,1,1,1,1
1,1,1,1,1,1,1,1,1,1,1,1,1,1,1,1,1,1,1,1,1,1,1,1
endlayer

layer
1,1,1,1,1,1,1,1,1,1,1,1,1,1,1,1,1,1,1,1,1,1,1,1
1,1,1,1,1,1,1,1,1,1,1,1,1,1,1,1,1,1,1,1,1,1,1,1
1,1,1,1,1,1,1,1,1,1,1,1,1,1,1,1,1,1,1,1,1,1,1,1
1,1,1,1,1,1,1,1,1,1,1,1,1,1,1,1,1,1,13,12,12,1,1,1
1,1,1,1,1,1,1,1,1,1,1,1,1,1,1,12,19,20,0,0,12,1,1,1
1,1,1,1,1,1,1,1,1,1,1,23,22,2,12,12,0,0,0,21,15,1,1,1
1,1,1,1,1,1,1,1,1,1,26,2,25,24,24,0,0,0,0,19,1,1,1,1
1,1,1,1,1,1,1,1,1,26,2,12,27,27,27,0,0,0,0,20,1,1,1,1
1,1,1,1,1,1,1,1,26,2,12,27,27,27,27,27,0,0,12,12,1,1,1,1
1,1,1,1,1,1,1,26,2,12,29,29,27,27,27,27,27,28,12,1,1,1,1,1
1,1,1,1,1,1,26,2,12,29,29,30,27,27,27,27,27,28,2,1,1,1,1,1
1,1,1,1,1,26,2,12,28,29,24,27,27,27,27,27,27,25,31,1,1,1,1,1
1,1,1,1,26,2,12,27,28,24,27,27,27,28,30,27,12,2,32,1,1,1,1,1
1,1,1,13,2,12,27,27,27,27,27,27,28,30,30,12,2,33,1,1,1,1,1,1
1,1,12,12,12,27,27,27,27,27,27,28,30,30,12,2,33,1,1,1,1,1,1,1
1,17,12,12,27,27,27,27,27,27,27,24,24,12,2,33,1,1,1,1,1,1,1,1
1,12,12,27,27,27,27,27,27,27,27,27,12,2,33,1,1,1,1,1,1,1,1,1
13,12,27,27,27,27,27,27,27,27,27,12,2,33,1,1,1,1,1,1,1,1,1,1
17,12,27,27,27,27,27,0,29,29,25,2,33,1,1,1,1,1,1,1,1,1,1,1
18,12,27,27,27,27,27,27,27,12,2,33,1,1,1,1,1,1,1,1,1,1,1,1
1,12,27,27,27,27,27,27,12,12,15,1,1,1,1,1,1,1,1,1,1,1,1,1
1,17,12,27,27,27,27,12,12,12,1,1,1,1,1,1,1,1,1,1,1,1,1,1
1,1,18,12,12,12,12,12,18,1,1,1,1,1,1,1,1,1,1,1,1,1,1,1
1,1,1,1,17,18,15,1,1,1,1,1,1,1,1,1,1,1,1,1,1,1,1,1
endlayer

layer
1,1,1,1,1,1,1,1,1,1,1,1,1,1,1,1,1,1,1,1,1,1,1,1
1,1,1,1,1,1,1,1,1,1,1,1,1,1,1,1,1,1,1,1,1,1,1,1
1,1,1,1,1,1,1,1,1,1,1,1,1,1,1,1,1,1,1,1,13,1,1,1
1,1,1,1,1,1,1,1,1,1,1,1,1,1,1,1,1,13,12,12,12,15,1,1
1,1,1,1,1,1,1,1,1,1,1,1,1,1,22,12,12,0,0,0,12,1,1,1
1,1,1,1,1,1,1,1,1,1,1,34,34,34,2,12,0,0,0,0,12,1,1,1
1,1,1,1,1,1,1,1,1,1,34,34,0,0,0,32,0,0,0,0,15,1,1,1
1,1,1,1,1,1,1,1,1,34,34,0,0,0,0,20,19,0,0,12,1,1,1,1
1,1,1,1,1,1,1,1,34,34,0,0,0,0,0,0,19,23,12,12,1,1,1,1
1,1,1,1,1,1,1,34,34,0,0,0,0,0,0,0,0,0,2,31,1,1,1,1
1,1,1,1,1,1,34,34,0,0,0,0,0,35,0,0,0,0,34,1,1,1,1,1
1,1,1,1,1,34,34,0,0,0,0,0,0,36,0,0,0,0,34,1,1,1,1,1
1,1,1,1,34,34,0,0,0,0,0,0,0,0,0,0,0,34,34,1,1,1,1,1
1,1,1,2,2,0,0,0,0,0,0,0,0,0,0,0,34,34,1,1,1,1,1,1
1,1,2,12,2,0,0,0,0,0,0,0,0,0,0,34,34,1,1,1,1,1,1,1
1,12,12,12,12,12,0,0,35,0,0,0,0,0,34,34,1,1,1,1,1,1,1,1
12,12,0,0,0,37,0,0,36,0,0,0,0,34,34,1,1,1,1,1,1,1,1,1
12,0,0,0,0,0,12,38,0,0,0,0,34,34,1,1,1,1,1,1,1,1,1,1
12,0,0,0,0,0,39,12,0,0,0,34,34,1,1,1,1,1,1,1,1,1,1,1
12,0,40,40,0,0,40,40,12,2,2,34,1,1,1,1,1,1,1,1,1,1,1,1
12,12,40,40,0,0,40,40,12,12,2,1,1,1,1,1,1,1,1,1,1,1,1,1
42,12,41,41,0,0,41,41,12,2,1,1,1,1,1,1,1,1,1,1,1,1,1,1
1,1,12,12,8,0,0,12,12,1,1,1,1,1,1,1,1,1,1,1,1,1,1,1
1,1,42,12,12,12,12,12,1,1,1,1,1,1,1,1,1,1,1,1,1,1,1,1
endlayer

layer
1,1,1,1,1,1,1,1,1,1,1,1,1,1,1,1,1,1,1,1,1,1,1,1
1,1,1,1,1,1,1,1,1,1,1,1,1,1,1,1,1,1,1,1,1,13,1,1
1,1,1,1,1,1,1,1,1,1,1,1,1,1,1,1,1,1,1,13,12,12,15,1
1,1,1,1,1,1,1,1,1,1,1,1,1,1,1,1,22,12,12,12,12,12,1,1
1,1,1,1,1,1,1,1,1,1,1,1,1,1,2,2,12,27,27,27,12,15,1,1
1,1,1,1,1,1,1,1,1,1,1,1,0,34,2,12,27,27,27,27,12,1,1,1
1,1,1,1,1,1,1,1,1,1,1,0,0,0,0,20,20,20,27,27,12,1,1,1
1,1,1,1,1,1,1,1,1,1,0,0,0,0,0,0,0,19,27,2,31,1,1,1
1,1,1,1,1,1,1,1,1,0,0,0,0,0,0,0,0,19,12,2,1,1,1,1
1,1,1,1,1,1,1,1,0,0,0,0,0,0,0,0,0,0,2,2,1,1,1,1
1,1,1,1,1,1,1,0,0,0,0,0,0,35,0,0,0,0,34,1,1,1,1,1
1,1,1,1,1,1,0,0,0,0,0,0,0,36,0,0,0,0,0,1,1,1,1,1
1,1,1,1,1,0,0,0,0,0,0,0,0,0,0,0,0,0,1,1,1,1,1,1
1,1,1,42,42,0,0,0,0,0,0,0,0,0,0,0,0,1,1,1,1,1,1,1
1,1,42,12,2,0,0,0,0,0,0,0,0,0,0,0,1,1,1,1,1,1,1,1
1,43,12,12,12,12,0,0,35,0,0,0,0,0,0,1,1,1,1,1,1,1,1,1
10,12,0,0,0,44,0,0,36,0,0,0,0,0,1,1,1,1,1,1,1,1,1,1
20,0,0,0,0,0,12,38,0,0,0,0,0,1,1,1,1,1,1,1,1,1,1,1
12,0,0,0,0,0,0,12,0,0,0,0,1,1,1,1,1,1,1,1,1,1,1,1
16,0,0,0,0,0,0,0,12,2,42,1,1,1,1,1,1,1,1,1,1,1,1,1
3,12,0,0,0,0,0,0,12,12,42,1,1,1,1,1,1,1,1,1,1,1,1,1
0,16,0,0,0,0,0,0,12,42,1,1,1,1,1,1,1,1,1,1,1,1,1,1
1,42,14,12,0,0,0,12,43,1,1,1,1,1,1,1,1,1,1,1,1,1,1,1
1,1,0,4,14,12,19,9,1,1,1,1,1,1,1,1,1,1,1,1,1,1,1,1
endlayer

layer
1,1,1,1,1,1,1,1,1,1,1,1,1,1,1,1,1,1,1,1,1,1,22,27
1,1,1,1,1,1,1,1,1,1,1,1,1,1,1,1,1,1,1,1,22,2,12,31
1,1,1,1,1,1,1,1,1,1,1,1,1,1,1,1,1,1,22,2,12,12,2,1
1,1,1,1,1,1,1,1,1,1,1,1,1,1,1,1,34,2,2,25,25,12,31,1
1,1,1,1,1,1,1,1,1,1,1,1,1,1,34,34,2,25,25,25,25,2,1,1
1,1,1,1,1,1,1,1,1,1,1,1,0,0,34,43,0,0,42,25,2,31,1,1
1,1,1,1,1,1,1,1,1,1,1,0,0,0,0,0,0,0,0,25,2,1,1,1
1,1,1,1,1,1,1,1,1,1,0,0,0,0,0,0,0,0,0,2,34,1,1,1
1,1,1,1,1,1,1,1,1,0,0,0,0,0,0,0,0,0,43,34,1,1,1,1
1,1,1,1,1,1,1,1,0,0,0,0,0,0,0,0,0,0,34,34,1,1,1,1
1,1,1,1,1,1,1,0,0,0,0,0,0,35,0,0,0,0,0,1,1,1,1,1
1,1,1,1,1,1,0,0,0,0,0,0,0,36,0,0,0,0,0,1,1,1,1,1
1,1,1,1,1,0,0,0,0,0,0,0,0,0,0,0,0,0,1,1,1,1,1,1
1,1,1,0,0,0,0,0,0,0,0,0,0,0,0,0,0,1,1,1,1,1,1,1
1,1,0,12,2,0,0,0,0,0,0,0,0,0,0,0,1,1,1,1,1,1,1,1
1,0,12,12,12,12,0,0,35,0,0,0,0,0,0,1,1,1,1,1,1,1,1,1
0,12,0,0,0,12,0,0,36,0,0,0,0,0,1,1,1,1,1,1,1,1,1,1
4,0,0,0,0,0,12,38,0,0,0,0,0,1,1,1,1,1,1,1,1,1,1,1
4,0,0,0,0,0,0,12,0,0,0,0,1,1,1,1,1,1,1,1,1,1,1,1
4,0,0,0,0,0,0,0,12,2,0,1,1,1,1,1,1,1,1,1,1,1,1,1
0,12,0,0,0,0,0,0,12,12,0,1,1,1,1,1,1,1,1,1,1,1,1,1
0,4,0,0,0,0,0,0,12,0,1,1,1,1,1,1,1,1,1,1,1,1,1,1
1,0,3,12,0,0,0,12,0,1,1,1,1,1,1,1,1,1,1,1,1,1,1,1
1,1,0,0,3,3,3,0,1,1,1,1,1,1,1,1,1,1,1,1,1,1,1,1
endlayer

layer
1,1,1,1,1,1,1,1,1,1,1,1,1,1,1,1,1,1,1,1,1,1,43,2
1,1,1,1,1,1,1,1,1,1,1,1,1,1,1,1,1,1,1,1,34,43,43,43
1,1,1,1,1,1,1,1,1,1,1,1,1,1,1,1,1,1,34,34,34,0,43,1
1,1,1,1,1,1,1,1,1,1,1,1,1,1,1,1,0,34,34,0,0,34,34,1
1,1,1,1,1,1,1,1,1,1,1,1,1,1,0,0,0,0,0,0,0,34,1,1
1,1,1,1,1,1,1,1,1,1,1,1,0,0,0,0,0,0,42,0,34,34,1,1
1,1,1,1,1,1,1,1,1,1,1,0,0,0,0,0,0,0,0,0,34,1,1,1
1,1,1,1,1,1,1,1,1,1,0,0,0,0,0,0,0,0,0,0,0,1,1,1
1,1,1,1,1,1,1,1,1,0,0,0,0,0,0,0,0,0,0,0,1,1,1,1
1,1,1,1,1,1,1,1,0,0,0,0,0,0,0,0,0,0,0,0,1,1,1,1
1,1,1,1,1,1,1,0,0,0,0,0,0,35,0,0,0,0,0,1,1,1,1,1
1,1,1,1,1,1,0,0,0,0,0,0,0,36,0,0,0,0,0,1,1,1,1,1
1,1,1,1,1,0,0,0,0,0,0,0,0,0,0,0,0,0,1,1,1,1,1,1
1,1,1,0,0,0,0,0,0,0,0,0,0,0,0,0,0,1,1,1,1,1,1,1
1,1,0,10,10,0,0,0,0,0,0,0,0,0,0,0,1,1,1,1,1,1,1,1
1,0,12,12,12,25,0,0,35,0,0,0,0,0,0,1,1,1,1,1,1,1,1,1
0,2,12,12,12,12,0,0,36,0,0,0,0,0,1,1,1,1,1,1,1,1,1,1
0,12,12,12,12,12,12,38,0,0,0,0,0,1,1,1,1,1,1,1,1,1,1,1
0,12,12,12,12,12,12,12,0,0,0,0,1,1,1,1,1,1,1,1,1,1,1,1
0,12,12,12,12,12,12,12,12,9,0,1,1,1,1,1,1,1,1,1,1,1,1,1
0,3,12,12,12,12,12,12,12,9,0,1,1,1,1,1,1,1,1,1,1,1,1,1
0,42,12,12,12,12,12,12,12,0,1,1,1,1,1,1,1,1,1,1,1,1,1,1
1,0,42,4,12,12,12,2,0,1,1,1,1,1,1,1,1,1,1,1,1,1,1,1
1,1,0,0,0,0,0,0,1,1,1,1,1,1,1,1,1,1,1,1,1,1,1,1
endlayer

layer
1,1,1,1,1,1,1,1,1,1,1,1,1,1,1,1,1,1,1,1,1,1,0,0
1,1,1,1,1,1,1,1,1,1,1,1,1,1,1,1,1,1,1,1,0,0,0,0
1,1,1,1,1,1,1,1,1,1,1,1,1,1,1,1,1,1,0,0,0,0,0,1
1,1,1,1,1,1,1,1,1,1,1,1,1,1,1,1,0,0,0,0,0,0,0,1
1,1,1,1,1,1,1,1,1,1,1,1,1,1,0,0,0,0,0,0,0,0,1,1
1,1,1,1,1,1,1,1,1,1,1,1,0,0,0,0,0,0,42,0,0,0,1,1
1,1,1,1,1,1,1,1,1,1,1,0,0,0,0,0,0,0,0,0,0,1,1,1
1,1,1,1,1,1,1,1,1,1,0,0,0,0,0,0,0,0,0,0,0,1,1,1
1,1,1,1,1,1,1,1,1,0,0,0,0,0,0,0,0,0,0,0,1,1,1,1
1,1,1,1,1,1,1,1,0,0,0,0,0,0,0,0,0,0,0,0,1,1,1,1
1,1,1,1,1,1,1,0,0,0,0,0,0,35,0,0,0,0,0,1,1,1,1,1
1,1,1,1,1,1,0,0,0,0,0,0,0,36,0,0,0,0,0,1,1,1,1,1
1,1,1,1,1,0,0,0,0,0,0,0,0,0,0,0,0,0,1,1,1,1,1,1
1,1,1,0,0,0,0,0,0,0,0,0,0,0,0,0,0,1,1,1,1,1,1,1
1,1,0,0,0,0,0,0,0,0,0,0,0,0,0,0,1,1,1,1,1,1,1,1
1,0,4,10,2,0,0,0,35,0,0,0,0,0,0,1,1,1,1,1,1,1,1,1
0,4,2,0,0,0,0,0,36,0,0,0,0,0,1,1,1,1,1,1,1,1,1,1
0,4,0,0,0,0,42,0,0,0,0,0,0,1,1,1,1,1,1,1,1,1,1,1
0,4,0,0,0,0,0,0,0,0,0,0,1,1,1,1,1,1,1,1,1,1,1,1
0,4,0,0,42,0,0,0,2,0,0,1,1,1,1,1,1,1,1,1,1,1,1,1
0,0,4,0,0,0,0,0,9,0,0,1,1,1,1,1,1,1,1,1,1,1,1,1
0,0,4,3,0,0,0,2,3,0,1,1,1,1,1,1,1,1,1,1,1,1,1,1
1,0,0,0,3,3,3,3,0,1,1,1,1,1,1,1,1,1,1,1,1,1,1,1
1,1,0,0,0,0,0,0,1,1,1,1,1,1,1,1,1,1,1,1,1,1,1,1
endlayer

layer
1,1,1,1,1,1,1,1,1,1,1,1,1,1,1,1,1,1,1,1,45,1,0,0
1,1,1,1,1,1,1,1,1,1,1,1,1,1,1,1,1,1,1,1,0,0,0,0
1,1,1,1,1,1,1,1,1,1,1,1,1,1,1,1,1,1,0,0,0,0,0,1
1,1,1,1,1,1,1,1,1,1,1,1,1,1,1,1,0,0,0,0,0,0,0,1
1,1,1,1,1,1,1,1,1,1,1,1,1,1,0,0,0,0,0,0,0,0,1,1
1,1,1,1,1,1,1,1,1,1,1,1,1,0,0,0,0,0,42,0,0,0,1,1
1,1,1,1,1,1,1,1,1,1,1,0,0,0,0,0,0,0,0,0,0,1,1,1
1,1,1,1,1,1,1,1,1,1,0,0,0,0,0,0,0,0,0,0,0,1,1,1
1,1,1,1,1,1,1,1,1,0,0,0,0,0,0,0,0,0,0,0,1,1,1,1
1,1,1,1,1,1,1,1,0,0,0,0,0,0,0,0,0,0,0,0,1,1,1,1
1,1,1,1,1,1,1,0,0,0,0,0,0,35,0,0,0,0,0,1,1,1,1,1
1,1,1,1,1,1,0,0,0,0,0,0,0,36,0,0,0,0,1,1,1,1,1,1
1,1,1,1,1,0,0,0,0,0,0,0,0,0,0,0,0,0,1,1,1,1,1,1
1,1,1,0,0,0,0,0,0,0,0,0,0,0,0,0,0,1,1,1,1,1,1,1
1,1,0,0,0,0,0,0,0,0,0,0,0,0,0,0,1,1,1,1,1,1,1,1
1,0,34,34,34,0,0,0,35,0,0,0,0,0,0,1,1,1,1,1,1,1,1,1
0,34,34,0,0,0,0,0,36,0,0,0,0,0,1,1,1,1,1,1,1,1,1,1
0,34,0,0,0,0,49,0,0,0,0,0,0,1,1,1,1,1,1,1,1,1,1,1
0,34,0,0,0,0,0,0,0,0,0,0,1,1,1,1,1,1,1,1,1,1,1,1
0,34,0,0,42,0,0,0,34,0,0,1,1,1,1,1,1,1,1,1,1,1,1,1
0,0,34,0,0,0,0,0,34,0,0,1,1,1,1,1,1,1,1,1,1,1,1,1
0,0,34,34,0,0,0,34,34,0,1,1,1,1,1,1,1,1,1,1,1,1,1,1
1,0,0,0,34,34,34,34,0,1,1,1,1,1,1,1,1,1,1,1,1,1,1,1
1,1,0,0,0,0,0,0,1,1,1,1,1,1,1,1,1,1,1,1,1,1,1,1
endlayer

layer
1,1,1,1,1,1,1,1,1,1,1,1,1,1,1,1,1,1,1,1,45,1,0,0
1,1,1,1,1,1,1,1,1,1,1,1,1,1,1,1,1,1,1,45,45,0,0,0
1,1,1,1,1,1,1,1,1,1,1,1,1,1,1,1,1,1,0,0,0,0,0,1
1,1,1,1,1,1,1,1,1,1,1,1,1,1,1,1,0,0,0,0,0,0,0,1
1,1,1,1,1,1,1,1,1,1,1,1,1,1,1,0,0,0,0,0,0,0,1,1
1,1,1,1,1,1,1,1,1,1,1,1,1,0,0,0,0,0,42,0,0,0,1,1
1,1,1,1,1,1,1,1,1,1,1,1,0,0,0,0,0,0,0,0,0,1,1,1
1,1,1,1,1,1,1,1,1,1,1,0,0,0,0,0,0,0,0,0,0,1,1,1
1,1,1,1,1,1,1,1,1,1,0,0,0,0,0,0,0,0,0,0,1,1,1,1
1,1,1,1,1,1,1,1,1,0,0,0,0,0,0,0,0,0,0,1,1,1,1,1
1,1,1,1,1,1,1,0,0,0,0,0,0,35,0,0,0,0,0,1,1,1,1,1
1,1,1,1,1,1,0,0,0,0,0,0,0,36,0,0,0,0,1,1,1,1,1,1
1,1,1,1,1,0,0,0,0,0,0,0,0,0,0,0,0,1,1,1,1,1,1,1
1,1,1,1,0,0,0,0,0,0,0,0,0,0,0,0,1,1,1,1,1,1,1,1
1,1,0,0,0,0,0,0,0,0,0,0,0,0,0,1,1,1,1,1,1,1,1,1
1,0,0,0,0,0,0,0,35,0,0,0,0,0,1,1,1,1,1,1,1,1,1,1
1,0,0,0,0,0,0,0,36,0,0,0,0,0,1,1,1,1,1,1,1,1,1,1
0,0,0,0,0,0,0,0,0,0,0,0,0,1,1,1,1,1,1,1,1,1,1,1
0,0,0,0,0,0,0,0,0,0,0,0,1,1,1,1,1,1,1,1,1,1,1,1
0,0,0,0,42,0,0,0,0,0,0,1,1,1,1,1,1,1,1,1,1,1,1,1
0,0,0,0,0,0,0,0,0,0,1,1,1,1,1,1,1,1,1,1,1,1,1,1
45,0,0,0,0,0,0,0,0,0,1,1,1,1,1,1,1,1,1,1,1,1,1,1
1,0,0,0,0,0,0,0,0,1,1,1,1,1,1,1,1,1,1,1,1,1,1,1
1,1,0,0,0,0,0,1,1,1,1,1,1,1,1,1,1,1,1,1,1,1,1,1
endlayer

layer
1,1,1,1,1,1,1,1,1,1,1,1,1,1,1,1,1,1,1,1,1,1,0,0
1,1,1,1,1,1,1,1,1,1,1,1,1,1,1,1,1,1,1,34,45,0,0,0
1,1,1,1,1,1,1,1,1,1,1,1,1,1,1,1,1,1,0,45,45,0,0,1
1,1,1,1,1,1,1,1,1,1,1,1,1,1,1,1,1,0,0,0,0,0,0,1
1,1,1,1,1,1,1,1,1,1,1,1,1,1,1,0,0,0,0,0,0,0,1,1
1,1,1,1,1,1,1,1,1,1,1,1,1,1,0,0,0,0,42,0,0,1,1,1
1,1,1,1,1,1,1,1,1,1,1,1,0,0,0,0,0,0,0,0,0,1,1,1
1,1,1,1,1,1,1,1,1,1,1,0,0,0,0,0,0,0,0,0,1,1,1,1
1,1,1,1,1,1,1,1,1,1,0,0,0,0,0,0,0,0,0,0,1,1,1,1
1,1,1,1,1,1,1,1,1,0,0,0,0,0,0,0,0,0,0,1,1,1,1,1
1,1,1,1,1,1,1,1,0,0,0,0,0,35,0,0,0,0,1,1,1,1,1,1
1,1,1,1,1,1,1,0,0,0,0,0,0,36,0,0,0,0,1,1,1,1,1,1
1,1,1,1,1,0,0,0,0,0,0,0,0,0,0,0,0,1,1,1,1,1,1,1
1,1,1,1,0,0,0,0,0,0,0,0,0,0,0,0,1,1,1,1,1,1,1,1
1,1,1,0,0,0,0,0,0,0,0,0,0,0,0,1,1,1,1,1,1,1,1,1
1,0,0,0,0,0,0,0,35,0,0,0,0,0,1,1,1,1,1,1,1,1,1,1
1,0,0,0,0,0,0,0,36,0,0,0,0,1,1,1,1,1,1,1,1,1,1,1
1,0,0,0,0,0,0,0,0,0,0,0,1,1,1,1,1,1,1,1,1,1,1,1
0,0,0,0,0,0,0,0,0,0,0,0,1,1,1,1,1,1,1,1,1,1,1,1
0,0,0,0,42,0,0,0,0,0,0,1,1,1,1,1,1,1,1,1,1,1,1,1
1,45,0,0,0,0,0,0,0,0,1,1,1,1,1,1,1,1,1,1,1,1,1,1
45,45,0,0,0,0,0,0,0,1,1,1,1,1,1,1,1,1,1,1,1,1,1,1
1,0,0,0,0,0,0,0,0,1,1,1,1,1,1,1,1,1,1,1,1,1,1,1
1,1,1,0,0,0,1,1,1,1,1,1,1,1,1,1,1,1,1,1,1,1,1,1
endlayer

layer
1,1,1,1,1,1,1,1,1,1,1,1,1,1,1,1,1,1,1,1,1,1,1,1
1,1,1,1,1,1,1,1,1,1,1,1,1,1,1,1,1,1,1,34,0,0,0,1
1,1,1,1,1,1,1,1,1,1,1,1,1,1,1,1,1,1,1,34,45,0,0,1
1,1,1,1,1,1,1,1,1,1,1,1,1,1,1,1,1,1,0,45,45,0,0,1
1,1,1,1,1,1,1,1,1,1,1,1,1,1,1,1,0,0,0,0,0,0,1,1
1,1,1,1,1,1,1,1,1,1,1,1,1,1,0,0,0,0,42,0,0,1,1,1
1,1,1,1,1,1,1,1,1,1,1,1,1,0,0,0,0,0,0,0,1,1,1,1
1,1,1,1,1,1,1,1,1,1,1,1,0,0,0,0,0,0,0,0,1,1,1,1
1,1,1,1,1,1,1,1,1,1,1,0,0,0,0,0,0,0,0,1,1,1,1,1
1,1,1,1,1,1,1,1,1,1,0,0,0,0,0,0,0,0,1,1,1,1,1,1
1,1,1,1,1,1,1,1,1,0,0,0,0,35,0,0,0,0,1,1,1,1,1,1
1,1,1,1,1,1,1,1,0,0,0,0,0,36,0,0,0,1,1,1,1,1,1,1
1,1,1,1,1,1,0,0,0,0,0,0,0,0,0,0,1,1,1,1,1,1,1,1
1,1,1,1,1,0,0,0,0,0,0,0,0,0,0,1,1,1,1,1,1,1,1,1
1,1,1,0,0,0,0,0,0,0,0,0,0,0,1,1,1,1,1,1,1,1,1,1
1,1,0,0,0,0,0,0,35,0,0,0,0,1,1,1,1,1,1,1,1,1,1,1
1,0,0,0,0,0,0,0,36,0,0,0,1,1,1,1,1,1,1,1,1,1,1,1
1,0,0,0,0,0,0,0,0,0,0,0,1,1,1,1,1,1,1,1,1,1,1,1
1,0,0,0,0,0,0,0,0,0,0,1,1,1,1,1,1,1,1,1,1,1,1,1
1,0,0,0,42,0,0,0,0,0,1,1,1,1,1,1,1,1,1,1,1,1,1,1
1,34,45,0,0,0,0,0,0,0,1,1,1,1,1,1,1,1,1,1,1,1,1,1
1,45,45,0,0,0,0,0,0,1,1,1,1,1,1,1,1,1,1,1,1,1,1,1
1,1,0,0,0,0,0,0,1,1,1,1,1,1,1,1,1,1,1,1,1,1,1,1
1,1,1,1,1,1,1,1,1,1,1,1,1,1,1,1,1,1,1,1,1,1,1,1
endlayer

layer
1,1,1,1,1,1,1,1,1,1,1,1,1,1,1,1,1,1,1,1,1,1,1,1
1,1,1,1,1,1,1,1,1,1,1,1,1,1,1,1,1,1,1,1,1,1,1,1
1,1,1,1,1,1,1,1,1,1,1,1,1,1,1,1,1,1,1,34,0,0,1,1
1,1,1,1,1,1,1,1,1,1,1,1,1,1,1,1,1,1,0,34,45,0,1,1
1,1,1,1,1,1,1,1,1,1,1,1,1,1,1,1,1,0,0,45,0,1,1,1
1,1,1,1,1,1,1,1,1,1,1,1,1,1,1,0,0,0,34,0,1,1,1,1
1,1,1,1,1,1,1,1,1,1,1,1,1,1,0,0,0,0,0,0,1,1,1,1
1,1,1,1,1,1,1,1,1,1,1,1,1,0,0,0,0,0,0,1,1,1,1,1
1,1,1,1,1,1,1,1,1,1,1,1,0,0,0,0,0,0,0,1,1,1,1,1
1,1,1,1,1,1,1,1,1,1,1,0,0,0,0,0,0,0,1,1,1,1,1,1
1,1,1,1,1,1,1,1,1,1,0,0,0,35,0,0,0,1,1,1,1,1,1,1
1,1,1,1,1,1,1,1,1,0,0,0,0,36,0,0,1,1,1,1,1,1,1,1
1,1,1,1,1,1,1,0,0,0,0,0,0,0,0,1,1,1,1,1,1,1,1,1
1,1,1,1,1,1,0,0,0,0,0,0,0,0,1,1,1,1,1,1,1,1,1,1
1,1,1,1,0,0,0,0,0,0,0,0,0,1,1,1,1,1,1,1,1,1,1,1
1,1,1,0,0,0,0,0,35,0,0,0,1,1,1,1,1,1,1,1,1,1,1,1
1,1,0,0,0,0,0,0,36,0,0,0,1,1,1,1,1,1,1,1,1,1,1,1
1,1,0,0,0,0,0,0,0,0,0,0,1,1,1,1,1,1,1,1,1,1,1,1
1,1,0,0,0,0,0,0,0,0,1,1,1,1,1,1,1,1,1,1,1,1,1,1
1,1,0,0,42,0,0,0,0,0,1,1,1,1,1,1,1,1,1,1,1,1,1,1
1,34,34,45,0,0,0,0,0,1,1,1,1,1,1,1,1,1,1,1,1,1,1,1
1,1,45,45,0,0,0,0,1,1,1,1,1,1,1,1,1,1,1,1,1,1,1,1
1,1,1,1,1,1,1,1,1,1,1,1,1,1,1,1,1,1,1,1,1,1,1,1
1,1,1,1,1,1,1,1,1,1,1,1,1,1,1,1,1,1,1,1,1,1,1,1
endlayer

layer
1,1,1,1,1,1,1,1,1,1,1,1,1,1,1,1,1,1,1,1,1,1,1,1
1,1,1,1,1,1,1,1,1,1,1,1,1,1,1,1,1,1,1,1,1,1,1,1
1,1,1,1,1,1,1,1,1,1,1,1,1,1,1,1,1,1,1,1,1,1,1,1
1,1,1,1,1,1,1,1,1,1,1,1,1,1,1,1,1,1,1,34,0,1,1,1
1,1,1,1,1,1,1,1,1,45,45,1,1,1,1,1,1,1,0,34,45,1,1,1
1,1,1,1,1,1,1,1,1,1,45,45,1,1,1,1,0,0,34,45,1,1,1,1
1,1,1,1,1,1,1,1,1,1,1,45,45,1,1,0,0,0,0,1,1,1,1,1
1,1,1,1,1,1,1,1,1,1,1,1,45,45,0,0,0,0,0,1,1,1,1,1
1,1,1,1,1,1,1,1,1,1,1,1,1,45,45,0,0,0,1,1,1,1,1,1
1,1,1,1,45,45,1,1,1,1,1,1,0,0,45,45,0,1,1,1,1,1,1,1
1,1,1,1,1,45,45,1,1,1,1,0,0,35,0,45,45,1,1,1,1,1,1,1
1,1,1,1,1,1,45,45,1,1,0,0,0,36,0,1,45,45,1,1,1,1,1,1
1,1,1,1,1,1,1,45,45,0,0,0,0,0,1,1,1,45,45,1,1,1,1,1
1,1,1,1,1,1,1,0,45,45,0,0,0,1,1,1,1,1,45,45,1,1,1,1
1,1,1,1,1,0,0,0,0,45,45,0,1,1,1,1,1,1,1,45,1,1,1,1
1,1,1,1,0,0,0,0,35,0,45,45,1,1,1,1,1,1,1,1,1,1,1,1
1,1,1,0,0,0,0,0,36,0,0,45,45,1,1,1,1,1,1,1,1,1,1,1
1,1,1,0,0,0,0,0,0,0,0,1,45,45,1,1,1,1,1,1,1,1,1,1
1,1,1,0,0,0,0,0,0,0,1,1,1,45,45,1,1,1,1,1,1,1,1,1
1,1,1,0,34,0,0,0,0,1,1,1,1,1,45,1,1,1,1,1,1,1,1,1
1,1,34,34,45,0,0,0,1,1,1,1,1,1,1,1,1,1,1,1,1,1,1,1
1,1,1,45,1,1,1,1,1,1,1,1,1,1,1,1,1,1,1,1,1,1,1,1
1,1,1,1,1,1,1,1,1,1,1,1,1,1,1,1,1,1,1,1,1,1,1,1
1,1,1,1,1,1,1,1,1,1,1,1,1,1,1,1,1,1,1,1,1,1,1,1
endlayer

layer
1,1,1,1,1,1,1,1,1,1,1,1,1,1,1,1,1,1,1,1,1,1,1,1
1,1,1,1,1,1,1,1,1,1,1,1,1,1,1,1,1,1,1,1,1,1,1,1
1,1,1,1,1,1,1,1,1,1,1,1,1,1,1,1,1,1,1,1,1,1,1,1
1,1,1,1,1,1,1,1,1,1,1,1,1,1,1,1,1,1,1,1,1,1,1,1
1,1,1,1,1,1,1,1,45,45,1,1,1,1,1,1,1,1,1,34,1,1,1,1
1,1,1,1,1,1,1,1,1,45,45,1,1,1,1,1,1,1,34,34,45,1,1,1
1,1,1,1,1,1,1,1,1,1,45,45,1,1,1,1,0,0,1,45,1,1,1,1
1,1,1,1,1,1,1,1,1,1,1,45,45,1,1,0,0,0,1,1,1,1,1,1
1,1,1,1,1,1,1,1,1,1,1,1,45,45,0,0,0,1,1,1,1,1,1,1
1,1,1,45,45,1,1,1,1,1,1,1,1,45,45,0,1,1,1,1,1,1,1,1
1,1,1,1,45,45,1,1,1,1,1,1,0,35,45,45,1,1,1,1,1,1,1,1
1,1,1,1,1,45,45,1,1,1,1,0,0,36,1,45,45,1,1,1,1,1,1,1
1,1,1,1,1,1,45,45,1,1,0,0,0,1,1,1,45,45,1,1,1,1,1,1
1,1,1,1,1,1,1,45,45,0,0,0,1,1,1,1,1,45,45,1,1,1,1,1
1,1,1,1,1,1,0,0,45,45,0,1,1,1,1,1,1,1,45,45,1,1,1,1
1,1,1,1,1,0,0,0,35,45,45,1,1,1,1,1,1,1,1,45,1,1,1,1
1,1,1,1,0,0,0,0,36,0,45,45,1,1,1,1,1,1,1,1,1,1,1,1
1,1,1,1,0,0,0,0,0,0,1,45,45,1,1,1,1,1,1,1,1,1,1,1
1,1,1,1,0,0,0,0,0,1,1,1,45,45,1,1,1,1,1,1,1,1,1,1
1,1,1,1,34,0,0,0,1,1,1,1,1,45,45,1,1,1,1,1,1,1,1,1
1,1,1,34,34,45,1,1,1,1,1,1,1,1,45,1,1,1,1,1,1,1,1,1
1,1,1,1,45,1,1,1,1,1,1,1,1,1,1,1,1,1,1,1,1,1,1,1
1,1,1,1,1,1,1,1,1,1,1,1,1,1,1,1,1,1,1,1,1,1,1,1
1,1,1,1,1,1,1,1,1,1,1,1,1,1,1,1,1,1,1,1,1,1,1,1
endlayer

layer
1,1,1,1,1,1,1,1,1,1,1,1,1,1,1,1,1,1,1,1,1,1,1,1
1,1,1,1,1,1,1,1,1,1,1,1,1,1,1,1,1,1,1,1,1,1,1,1
1,1,1,1,1,1,1,1,1,1,1,1,1,1,1,1,1,1,1,1,1,1,1,1
1,1,1,1,1,1,1,1,1,1,1,1,1,1,1,1,1,1,1,1,1,1,1,1
1,1,1,1,1,1,1,1,1,42,1,1,1,1,1,1,1,1,1,1,1,1,1,1
1,1,1,1,1,1,1,1,47,46,42,1,1,1,1,1,1,1,34,34,1,1,1,1
1,1,1,1,1,1,1,1,1,46,46,42,1,1,1,1,1,1,1,34,45,1,1,1
1,1,1,1,1,1,1,1,1,1,46,46,42,1,1,1,1,1,1,45,1,1,1,1
1,1,1,1,1,1,1,1,1,1,1,46,46,42,1,1,1,1,1,1,1,1,1,1
1,1,1,1,42,1,1,1,1,1,1,34,46,46,42,1,1,1,1,1,1,1,1,1
1,1,1,47,46,42,1,1,1,1,1,34,25,35,46,42,1,1,1,1,1,1,1,1
1,1,1,1,46,46,42,1,1,1,1,1,25,36,46,46,42,1,1,1,1,1,1,1
1,1,1,1,1,46,46,42,1,1,1,1,1,34,34,46,46,42,1,1,1,1,1,1
1,1,1,1,1,1,46,46,42,1,1,1,1,1,1,1,46,46,42,1,1,1,1,1
1,1,1,1,1,1,34,46,46,42,1,1,1,1,1,1,1,46,46,42,1,1,1,1
1,1,1,1,1,1,34,25,35,46,42,1,1,1,1,1,1,1,48,1,1,1,1,1
1,1,1,1,1,0,0,25,36,46,46,42,1,1,1,1,1,1,1,1,1,1,1,1
1,1,1,1,1,0,0,0,34,34,46,46,42,1,1,1,1,1,1,1,1,1,1,1
1,1,1,1,1,1,0,0,1,1,1,46,46,42,1,1,1,1,1,1,1,1,1,1
1,1,1,1,34,1,1,1,1,1,1,1,46,46,42,1,1,1,1,1,1,1,1,1
1,1,1,1,34,34,45,1,1,1,1,1,1,48,1,1,1,1,1,1,1,1,1,1
1,1,1,1,1,45,1,1,1,1,1,1,1,1,1,1,1,1,1,1,1,1,1,1
1,1,1,1,1,1,1,1,1,1,1,1,1,1,1,1,1,1,1,1,1,1,1,1
1,1,1,1,1,1,1,1,1,1,1,1,1,1,1,1,1,1,1,1,1,1,1,1
endlayer

layer
1,1,1,1,1,1,1,1,1,1,1,1,1,1,1,1,1,1,1,1,1,1,1,1
1,1,1,1,1,1,1,1,1,1,1,1,1,1,1,1,1,1,1,1,1,1,1,1
1,1,1,1,1,1,1,1,1,1,1,1,1,1,1,1,1,1,1,1,1,1,1,1
1,1,1,1,1,1,1,1,1,1,1,1,1,1,1,1,1,1,1,1,1,1,1,1
1,1,1,1,1,1,1,1,1,1,1,1,1,1,1,1,1,1,1,1,1,1,1,1
1,1,1,1,1,1,1,1,1,1,1,1,1,1,1,1,1,1,34,1,1,1,1,1
1,1,1,1,1,1,1,1,1,1,1,1,1,1,1,1,1,1,1,34,1,1,1,1
1,1,1,1,1,1,1,1,1,1,1,1,1,1,1,1,1,1,1,34,45,1,1,1
1,1,1,1,1,1,1,1,1,1,1,1,1,1,1,1,1,1,1,45,1,1,1,1
1,1,1,1,1,1,1,1,1,1,1,34,0,0,0,1,1,1,1,1,1,1,1,1
1,1,1,1,1,1,1,1,1,1,1,34,0,35,0,1,1,1,1,1,1,1,1,1
1,1,1,1,1,1,1,1,1,1,1,34,0,0,0,1,1,1,1,1,1,1,1,1
1,1,1,1,1,1,1,1,1,1,1,1,34,34,34,1,1,1,1,1,1,1,1,1
1,1,1,1,1,1,1,1,1,1,1,1,1,1,1,1,1,1,1,1,1,1,1,1
1,1,1,1,1,1,34,0,0,0,1,1,1,1,1,1,1,1,1,1,1,1,1,1
1,1,1,1,1,1,34,0,35,0,1,1,1,1,1,1,1,1,1,1,1,1,1,1
1,1,1,1,1,1,34,0,0,0,1,1,1,1,1,1,1,1,1,1,1,1,1,1
1,1,1,1,1,1,1,34,34,34,1,1,1,1,1,1,1,1,1,1,1,1,1,1
1,1,1,1,1,1,1,1,1,1,1,1,1,1,1,1,1,1,1,1,1,1,1,1
1,1,1,1,34,1,1,1,1,1,1,1,1,1,1,1,1,1,1,1,1,1,1,1
1,1,1,1,1,34,34,45,1,1,1,1,1,1,1,1,1,1,1,1,1,1,1,1
1,1,1,1,1,1,45,1,1,1,1,1,1,1,1,1,1,1,1,1,1,1,1,1
1,1,1,1,1,1,1,1,1,1,1,1,1,1,1,1,1,1,1,1,1,1,1,1
1,1,1,1,1,1,1,1,1,1,1,1,1,1,1,1,1,1,1,1,1,1,1,1
endlayer

layer
1,1,1,1,1,1,1,1,1,1,1,1,1,1,1,1,1,1,1,1,1,1,1,1
1,1,1,1,1,1,1,1,1,1,1,1,1,1,1,1,1,1,1,1,1,1,1,1
1,1,1,1,1,1,1,1,1,1,1,1,1,1,1,1,1,1,1,1,1,1,1,1
1,1,1,1,1,1,1,1,1,1,1,1,1,1,1,1,1,1,1,1,1,1,1,1
1,1,1,1,1,1,1,1,1,1,1,1,1,1,1,1,1,1,1,1,1,1,1,1
1,1,1,1,1,1,1,1,1,1,1,1,1,1,1,1,1,1,1,1,1,1,1,1
1,1,1,1,1,1,1,1,1,1,1,1,1,1,1,1,1,1,1,1,1,1,1,1
1,1,1,1,1,1,1,1,1,1,1,1,1,1,1,1,1,1,1,34,1,1,1,1
1,1,1,1,1,1,1,1,1,1,1,1,1,1,1,1,1,1,1,1,1,1,1,1
1,1,1,1,1,1,1,1,1,1,1,1,0,0,0,1,1,1,1,1,1,1,1,1
1,1,1,1,1,1,1,1,1,1,1,1,0,35,0,1,1,1,1,1,1,1,1,1
1,1,1,1,1,1,1,1,1,1,1,1,0,0,0,1,1,1,1,1,1,1,1,1
1,1,1,1,1,1,1,1,1,1,1,1,1,1,1,1,1,1,1,1,1,1,1,1
1,1,1,1,1,1,1,1,1,1,1,1,1,1,1,1,1,1,1,1,1,1,1,1
1,1,1,1,1,1,1,0,0,0,1,1,1,1,1,1,1,1,1,1,1,1,1,1
1,1,1,1,1,1,1,0,35,0,1,1,1,1,1,1,1,1,1,1,1,1,1,1
1,1,1,1,1,1,1,0,0,0,1,1,1,1,1,1,1,1,1,1,1,1,1,1
1,1,1,1,1,1,1,1,1,1,1,1,1,1,1,1,1,1,1,1,1,1,1,1
1,1,1,1,1,1,1,1,1,1,1,1,1,1,1,1,1,1,1,1,1,1,1,1
1,1,1,1,34,1,1,1,1,1,1,1,1,1,1,1,1,1,1,1,1,1,1,1
1,1,1,1,1,1,34,1,1,1,1,1,1,1,1,1,1,1,1,1,1,1,1,1
1,1,1,1,1,1,1,1,1,1,1,1,1,1,1,1,1,1,1,1,1,1,1,1
1,1,1,1,1,1,1,1,1,1,1,1,1,1,1,1,1,1,1,1,1,1,1,1
1,1,1,1,1,1,1,1,1,1,1,1,1,1,1,1,1,1,1,1,1,1,1,1
endlayer

layer
1,1,1,1,1,1,1,1,1,1,1,1,1,1,1,1,1,1,1,1,1,1,1,1
1,1,1,1,1,1,1,1,1,1,1,1,1,1,1,1,1,1,1,1,1,1,1,1
1,1,1,1,1,1,1,1,1,1,1,1,1,1,1,1,1,1,1,1,1,1,1,1
1,1,1,1,1,1,1,1,1,1,1,1,1,1,1,1,1,1,1,1,1,1,1,1
1,1,1,1,1,1,1,1,1,1,1,1,1,1,1,1,1,1,1,1,1,1,1,1
1,1,1,1,1,1,1,1,1,1,1,1,1,1,1,1,1,1,1,1,1,1,1,1
1,1,1,1,1,1,1,1,1,1,1,1,1,1,1,1,1,1,1,1,1,1,1,1
1,1,1,1,1,1,1,1,1,1,1,1,1,1,1,1,1,1,1,1,1,1,1,1
1,1,1,1,1,1,1,1,1,1,1,1,1,1,1,1,1,1,1,1,1,1,1,1
1,1,1,1,1,1,1,1,1,1,1,1,0,0,0,1,1,1,1,1,1,1,1,1
1,1,1,1,1,1,1,1,1,1,1,1,0,35,0,1,1,1,1,1,1,1,1,1
1,1,1,1,1,1,1,1,1,1,1,1,0,0,0,1,1,1,1,1,1,1,1,1
1,1,1,1,1,1,1,1,1,1,1,1,1,1,1,1,1,1,1,1,1,1,1,1
1,1,1,1,1,1,1,1,1,1,1,1,1,1,1,1,1,1,1,1,1,1,1,1
1,1,1,1,1,1,1,0,0,0,1,1,1,1,1,1,1,1,1,1,1,1,1,1
1,1,1,1,1,1,1,0,35,0,1,1,1,1,1,1,1,1,1,1,1,1,1,1
1,1,1,1,1,1,1,0,0,0,1,1,1,1,1,1,1,1,1,1,1,1,1,1
1,1,1,1,1,1,1,1,1,1,1,1,1,1,1,1,1,1,1,1,1,1,1,1
1,1,1,1,1,1,1,1,1,1,1,1,1,1,1,1,1,1,1,1,1,1,1,1
1,1,1,1,1,1,1,1,1,1,1,1,1,1,1,1,1,1,1,1,1,1,1,1
1,1,1,1,1,1,1,1,1,1,1,1,1,1,1,1,1,1,1,1,1,1,1,1
1,1,1,1,1,1,1,1,1,1,1,1,1,1,1,1,1,1,1,1,1,1,1,1
1,1,1,1,1,1,1,1,1,1,1,1,1,1,1,1,1,1,1,1,1,1,1,1
1,1,1,1,1,1,1,1,1,1,1,1,1,1,1,1,1,1,1,1,1,1,1,1
endlayer

