
# Created by Ruins mod version 16.7 Ingame Parser
# authoring Player: lafuller

weight=1
embed_into_distance=4
acceptable_target_blocks=
unacceptable_target_blocks=flowing_water,water,flowing_lava,lava,ice,bedrock,netherrack,nether_brick,nether_brick_fence,soul_sand,quartz_ore,end_stone,obsidian,iron_bars,cloud,flesh,ash_block,slime_grass,slime_congealed,slime_dirt
biomesToSpawnIn=plains,prarie,meadow,tundra,brushland,shrubland,woodland,woodlands,lavender_fields,flower_field,sunflower_plains,ice_flats,ice_plains
dimensions=21,16,16
allowable_overhang=0
max_leveling=4
leveling_buffer=-1
preserve_water=0
preserve_lava=0

rule1=0,100,preserveBlock
rule2=0,100,minecraft:stone-6
rule3=0,100,stonebrick-0,stonebrick-0,stonebrick-0,stonebrick-0,stonebrick-1,stonebrick-2,stonebrick-2,stone-5,stone-6,cobblestone
rule4=0,100,stonebrick-0,stonebrick-2,stonebrick-2,stonebrick-2,stonebrick-1,cobblestone
rule5=0,100,stonebrick-0,stonebrick-1,stonebrick-2,stonebrick-2,stone-5,stone-5,stone-6,stone-6
rule6=0,100,minecraft:stone_brick_stairs-0
rule7=0,100,stonebrick-0,stonebrick-0,stonebrick-0,stonebrick-0,stonebrick-1,stonebrick-2,stonebrick-2,stone-5,stone-6,cobblestone,gravel
rule8=0,100,stonebrick-0,stonebrick-2,stonebrick-0,stonebrick-1,stonebrick-1,cobblestone
rule9=0,100,minecraft:dirt-0
rule10=0,100,minecraft:stone_brick_stairs-3
rule11=0,100,minecraft:stone_brick_stairs-1
rule12=0,100,minecraft:stone-5
rule13=0,100,minecraft:cobblestone_wall-0
rule14=0,100,minecraft:log-0
rule15=0,100,minecraft:wooden_slab-9
rule16=0,100,minecraft:web-0,air,air,air
rule17=0,100,minecraft:wooden_slab-1
rule18=0,100,minecraft:spruce_stairs-0
rule19=0,100,minecraft:planks-1
rule20=0,100,ChestGenHook:chests/spawn_bonus_chest:5-4,ChestGenHook:chests/village_blacksmith:5-4,ChestGenHook:chests/simple_dungeon:5-4,ChestGenHook:chests/abandoned_mineshaft:5-4,ChestGenHook:chests/stronghold_library:5-4,ChestGenHook:chests/stronghold_corridor:5-4,ChestGenHook:chests/stronghold_crossing:5-3,ChestGenHook:chests/igloo_chest:5-4
rule21=0,100,minecraft:spruce_stairs-2
rule22=0,100,minecraft:spruce_stairs-7
rule23=0,100,minecraft:log-7
rule24=0,100,minecraft:log-11
rule25=0,100,minecraft:planks-0
rule26=0,100,minecraft:wooden_slab-8
rule27=0,100,minecraft:oak_stairs-5
rule28=0,100,minecraft:spruce_stairs-5
rule29=0,100,minecraft:stone_slab-3
rule30=0,100,minecraft:oak_stairs-4
rule31=0,100,minecraft:spruce_stairs-4
rule32=0,100,minecraft:stone-2
rule33=0,100,minecraft:spruce_fence_gate-5
rule34=0,100,minecraft:spruce_fence_gate-6
rule35=0,100,minecraft:stone_brick_stairs-6
rule36=0,100,minecraft:spruce_door-1
rule37=0,100,minecraft:spruce_door-3
rule38=0,100,minecraft:spruce_fence-0
rule39=0,100,minecraft:fence-0
rule40=0,100,minecraft:carpet-7
rule41=0,100,minecraft:stone_brick_stairs-7
rule42=0,100,minecraft:stone_brick_stairs-2
rule43=0,100,IInventory;minecraft:furnace;minecraft:coal#3#1#1-2
rule44=0,100,minecraft:spruce_door-8
rule45=0,100,minecraft:oak_stairs-7
rule46=0,100,minecraft:oak_stairs-6
rule47=0,100,minecraft:trapdoor-0
rule48=0,100,minecraft:stone_brick_stairs-4
rule49=0,100,minecraft:stone_slab-5
rule50=0,100,minecraft:spruce_fence_gate-0
rule51=0,100,minecraft:spruce_fence_gate-2
rule52=0,100,minecraft:wooden_slab-13
rule53=0,100,minecraft:dark_oak_stairs-6
rule54=0,100,minecraft:dark_oak_stairs-4
rule55=0,100,minecraft:double_wooden_slab-5
rule56=0,100,minecraft:dark_oak_stairs-3
rule57=0,100,minecraft:dark_oak_stairs-7
rule58=0,100,minecraft:stone_slab-13
rule59=0,100,minecraft:dark_oak_fence-0
rule60=0,100,minecraft:spruce_stairs-3
rule61=0,100,minecraft:dark_oak_stairs-5
rule62=0,100,minecraft:spruce_stairs-1
rule63=0,100,minecraft:dark_oak_stairs-2
rule64=0,100,minecraft:dark_oak_stairs-0
rule65=0,100,minecraft:wooden_slab-5
rule66=0,100,minecraft:planks-5
rule67=0,100,minecraft:spruce_stairs-6
rule68=0,100,minecraft:dark_oak_stairs-1
rule69=0,100,minecraft:stone_brick_stairs-5
rule70=0,100,minecraft:trapdoor-11
rule71=0,100,minecraft:iron_bars-0

layer
1,1,1,1,1,1,1,1,1,1,1,1,1,1,1,1
1,1,1,1,1,1,1,1,3,3,3,2,1,1,1,1
1,1,1,1,3,3,3,2,2,4,4,2,2,1,1,1
1,1,1,3,3,2,4,4,4,5,4,4,3,1,1,1
1,1,1,3,4,4,5,5,5,5,4,4,3,6,6,6
1,1,1,3,4,2,8,5,8,8,5,4,3,3,3,3
1,3,3,3,4,5,8,8,8,5,5,4,2,3,3,3
3,3,9,9,3,4,5,8,8,8,5,5,4,3,2,3
3,9,9,9,3,2,4,5,8,8,8,8,5,4,3,3
3,9,9,3,3,3,3,4,5,5,8,8,5,4,3,3
3,9,9,9,9,3,3,4,5,8,8,8,5,4,3,3
3,3,3,3,3,3,3,4,5,8,8,5,4,3,2,3
10,3,3,3,3,3,3,2,4,5,5,5,4,3,3,3
10,3,3,3,3,3,3,3,4,4,4,4,4,3,3,3
1,1,1,1,1,1,1,3,3,3,3,3,3,3,11,11
1,1,1,1,1,1,1,1,1,1,1,1,1,1,1,1
endlayer

layer
1,1,1,1,1,1,1,1,1,1,1,1,1,1,1,1
1,1,1,1,1,1,1,1,7,13,7,12,1,1,1,1
1,1,1,1,7,7,7,12,14,15,15,14,12,1,1,1
1,1,1,7,7,14,16,0,0,0,0,16,13,1,1,1
1,1,1,13,15,0,0,0,0,0,0,0,7,1,1,1
1,1,1,7,15,0,0,0,0,0,0,0,7,7,6,6
1,7,7,7,15,0,0,0,0,0,0,0,14,7,7,7
7,7,9,9,7,16,0,0,0,0,0,0,16,7,12,7
7,9,9,9,7,14,16,0,0,0,0,0,0,15,13,7
7,9,9,7,7,7,7,0,0,0,0,0,0,15,7,7
7,9,9,9,9,7,7,0,0,0,0,0,0,14,7,7
7,7,7,7,7,7,7,16,0,0,0,0,0,7,12,7
1,10,7,7,7,7,7,14,0,0,0,0,0,7,7,7
1,10,7,7,7,7,7,7,20,0,19,18,17,7,11,11
1,1,1,1,1,1,1,7,13,7,13,7,13,7,1,1
1,1,1,1,1,1,1,1,1,1,1,1,1,1,1,1
endlayer

layer
1,1,1,1,1,1,1,1,1,1,1,1,1,1,1,1
1,1,1,1,1,1,1,1,7,13,7,2,1,1,1,1
1,1,1,1,7,7,7,2,14,16,16,14,2,1,1,1
1,1,1,7,7,14,16,16,0,0,0,16,13,1,1,1
1,1,1,13,16,16,0,0,0,0,0,16,7,1,1,1
1,1,1,7,16,0,0,0,0,0,0,0,7,7,1,1
1,7,7,7,16,16,0,0,0,0,0,0,14,7,6,6
7,7,9,9,7,16,0,0,0,0,0,0,16,7,2,7
7,9,9,9,7,14,16,0,0,0,0,0,0,16,13,7
7,9,9,7,7,7,7,0,0,0,0,0,0,16,7,7
7,9,9,9,9,7,7,16,0,0,0,0,0,14,7,7
7,7,7,7,7,7,7,16,0,0,0,0,0,7,2,7
1,1,10,7,7,7,7,14,16,0,0,0,0,7,11,11
1,1,10,7,7,7,7,7,0,22,21,0,0,13,1,1
1,1,1,1,1,1,1,7,13,7,13,7,13,7,1,1
1,1,1,1,1,1,1,1,1,1,1,1,1,1,1,1
endlayer

layer
1,1,1,1,1,1,1,1,1,1,1,1,1,1,1,1
1,1,1,1,1,1,1,1,7,13,7,12,1,1,1,1
1,1,1,1,7,7,7,12,14,16,16,14,12,1,1,1
1,1,1,7,7,23,16,16,16,0,16,16,13,1,1,1
1,1,1,13,16,23,16,0,0,0,0,16,7,1,1,1
1,1,1,7,24,23,0,0,0,0,0,16,7,7,1,1
1,7,7,7,16,23,16,0,0,0,0,16,14,7,1,1
7,7,9,9,7,23,16,16,0,0,0,16,16,7,12,6
7,9,9,9,7,23,16,0,0,0,0,0,16,16,13,7
7,9,9,7,7,7,7,16,16,0,0,0,0,16,7,7
7,9,9,9,9,7,7,16,0,0,0,0,16,14,7,7
7,7,7,7,7,7,7,16,16,0,0,0,0,7,12,11
1,1,1,10,7,7,7,14,16,0,0,0,0,7,1,1
1,1,1,10,7,7,7,7,22,21,0,0,0,13,1,1
1,1,1,1,1,1,1,7,13,7,13,7,7,7,1,1
1,1,1,1,1,1,1,1,1,1,1,1,1,1,1,1
endlayer

layer
1,1,1,1,1,1,1,1,1,1,1,1,1,1,1,1
1,1,1,1,1,1,1,1,7,7,7,2,1,1,1,1
1,1,1,1,1,7,7,2,25,26,26,25,2,1,1,1
1,1,1,1,2,12,12,27,27,28,28,27,7,1,1,1
1,1,1,7,12,12,12,15,15,15,26,26,7,1,1,1
1,1,1,7,12,12,12,15,26,26,15,26,2,1,1,1
1,12,12,12,12,12,12,26,26,15,15,26,25,7,1,1
3,12,29,29,12,12,12,27,27,27,28,28,27,2,2,1
3,2,29,29,12,12,12,15,26,26,15,26,15,26,7,6
10,2,2,12,12,12,2,30,31,30,30,30,31,30,7,2
10,3,3,3,12,3,3,26,15,15,26,26,15,25,7,11
7,11,11,11,11,3,3,30,31,30,30,31,30,2,2,1
1,1,1,1,10,2,7,25,26,15,15,15,26,7,1,1
1,1,1,1,10,2,2,2,17,0,0,0,0,7,1,1
1,1,1,1,1,1,1,1,7,7,7,7,7,1,1,1
1,1,1,1,1,1,1,1,1,1,1,1,1,1,1,1
endlayer

layer
1,1,1,1,1,1,1,1,1,1,1,1,1,1,1,1
1,1,1,1,1,1,1,1,32,32,32,2,1,1,1,1
1,1,1,1,1,32,32,2,0,33,33,0,32,1,1,1
1,1,1,1,2,0,33,33,0,0,0,0,32,1,1,1
1,1,1,32,32,0,0,0,0,0,0,34,32,1,1,1
1,1,1,32,32,0,0,0,0,0,0,34,2,1,1,1
1,12,2,2,6,0,0,0,0,0,0,0,0,32,1,1
2,2,0,0,35,0,0,0,0,0,0,0,0,2,32,1
2,0,0,0,7,32,32,32,32,0,0,0,0,0,32,1
1,0,0,2,2,2,2,0,0,0,0,0,0,0,36,1
1,0,0,0,0,0,32,0,0,0,0,0,0,0,32,1
1,1,0,0,0,0,37,0,0,0,0,0,0,32,32,1
1,1,1,1,1,0,32,0,0,0,38,38,38,32,1,1
1,1,1,1,1,1,1,2,0,0,0,0,0,32,1,1
1,1,1,1,1,1,1,1,32,32,32,32,2,1,1,1
1,1,1,1,1,1,1,1,1,1,1,1,1,1,1,1
endlayer

layer
1,1,1,1,1,1,1,1,1,1,1,1,1,1,1,1
1,1,1,1,1,1,1,1,39,0,39,14,38,1,1,1
1,1,1,1,39,0,39,14,0,40,40,0,39,1,1,1
1,1,1,39,14,0,40,40,0,0,0,0,0,1,1,1
1,1,1,39,0,0,0,0,0,0,0,40,39,1,1,1
1,1,41,6,0,0,0,0,0,0,0,40,14,1,1,1
1,6,35,7,42,0,0,0,0,0,0,0,0,39,1,1
1,13,0,0,43,0,0,0,0,0,0,0,0,14,1,1
1,0,0,0,35,0,0,0,0,0,0,0,0,0,25,1
1,0,0,13,10,13,14,0,0,0,0,0,0,0,44,1
1,0,0,0,0,0,25,0,0,0,0,0,0,0,25,1
1,1,0,0,0,0,44,0,0,0,0,0,0,14,1,1
1,1,1,1,1,0,25,0,0,0,0,0,0,39,1,1
1,1,1,1,1,1,0,14,0,0,0,0,0,39,1,1
1,1,1,1,1,1,1,38,39,39,0,39,14,1,1,1
1,1,1,1,1,1,1,1,1,1,1,1,1,1,1,1
endlayer

layer
1,1,1,1,1,1,1,1,1,1,1,1,1,1,1,1
1,1,1,1,1,1,1,45,30,30,30,14,1,1,1,1
1,1,1,1,45,30,30,14,0,0,0,0,46,1,1,1
1,1,1,1,14,0,0,0,0,0,0,0,46,1,1,1
1,1,1,45,47,0,0,0,0,0,0,0,46,1,1,1
1,1,6,7,47,0,0,0,0,0,0,0,14,1,1,1
1,10,7,7,48,0,0,0,0,0,0,0,0,46,1,1
1,7,35,0,42,0,0,0,0,0,0,0,0,14,30,1
1,0,0,48,49,0,15,15,15,0,0,0,0,0,46,1
1,1,0,10,7,13,14,0,0,0,0,0,0,0,50,1
1,1,0,0,0,0,45,0,0,0,0,0,0,0,46,1
1,1,1,0,0,0,51,0,0,0,0,0,0,14,27,1
1,1,1,1,1,0,45,0,0,0,0,0,0,46,1,1
1,1,1,1,1,1,0,14,0,0,0,0,0,46,1,1
1,1,1,1,1,1,1,1,27,27,27,27,14,1,1,1
1,1,1,1,1,1,1,1,1,1,1,1,1,1,1,1
endlayer

layer
1,1,1,1,1,1,1,52,1,1,1,52,52,1,1,1
1,1,1,1,52,1,1,54,18,18,18,14,53,1,1,1
1,1,1,56,55,18,18,14,38,38,38,38,21,1,1,1
1,1,52,22,14,38,38,0,0,0,0,0,21,1,1,1
1,1,57,19,38,0,0,0,0,0,0,0,21,1,1,1
1,1,6,7,0,0,0,0,0,0,0,0,14,31,52,1
1,48,7,7,58,0,0,0,0,0,0,0,38,21,1,1
1,10,7,0,35,0,0,0,0,0,0,0,0,14,54,52
1,1,58,7,42,0,59,0,59,0,0,0,0,38,21,1
1,1,0,11,10,13,14,0,0,0,0,0,0,38,21,1
1,1,1,0,0,0,60,0,0,0,0,0,0,38,21,1
1,1,1,1,0,0,60,0,0,0,0,0,0,14,61,52
1,1,1,1,1,22,19,0,0,0,0,0,0,21,1,1
1,1,1,1,1,1,61,14,38,38,38,38,38,21,1,1
1,1,1,1,1,1,52,57,19,62,62,62,14,61,1,1
1,1,1,1,1,1,1,1,52,1,1,1,52,1,1,1
endlayer

layer
1,1,1,1,1,1,1,1,65,64,64,63,1,1,1,1
1,1,1,1,1,65,64,66,66,66,66,14,63,1,1,1
1,1,1,1,64,66,66,14,28,28,28,28,66,65,1,1
1,1,1,56,14,28,28,0,0,0,0,22,66,63,1,1
1,1,65,66,67,0,0,0,0,0,0,28,66,64,1,1
1,1,1,35,48,0,0,0,0,0,0,0,14,66,1,1
1,1,41,7,7,35,0,0,0,0,0,0,28,66,65,1
1,1,41,0,7,35,0,0,0,0,0,0,0,14,63,1
1,1,11,11,7,35,59,0,59,0,0,0,0,22,66,65
1,1,1,1,65,68,14,0,0,0,0,0,0,22,66,63
1,1,1,1,65,56,66,31,0,0,0,0,0,22,66,65
1,1,1,1,65,66,66,67,0,0,0,0,0,14,63,1
1,1,1,1,65,56,66,67,0,0,0,0,31,66,65,1
1,1,1,1,1,65,68,14,31,31,31,31,22,66,65,1
1,1,1,1,1,1,1,56,66,66,66,66,68,1,1,1
1,1,1,1,1,1,1,1,1,65,68,65,1,1,1,1
endlayer

layer
1,1,1,1,1,1,1,1,1,1,1,1,1,1,1,1
1,1,1,1,1,1,1,1,56,64,64,64,1,1,1,1
1,1,1,1,1,1,64,64,66,66,66,66,64,1,1,1
1,1,1,1,65,56,66,28,28,28,28,66,63,1,1,1
1,1,1,1,65,56,66,67,15,15,22,66,63,1,1,1
1,1,1,1,65,56,66,67,0,0,0,22,66,63,1,1
1,1,58,48,7,56,66,67,0,0,0,22,66,63,1,1
1,1,10,0,7,56,66,67,0,0,0,28,22,63,1,1
1,1,10,69,69,68,66,67,59,0,0,15,22,66,1,1
1,1,1,1,1,1,68,31,31,31,31,31,31,66,63,1
1,1,1,1,1,1,56,66,67,15,15,15,22,66,68,1
1,1,1,1,1,1,56,66,67,15,1,15,31,63,1,1
1,1,1,1,1,1,65,56,31,31,31,22,66,63,1,1
1,1,1,1,1,1,1,56,66,66,66,66,63,1,1,1
1,1,1,1,1,1,1,1,68,68,68,68,1,1,1,1
1,1,1,1,1,1,1,1,1,1,1,1,1,1,1,1
endlayer

layer
1,1,1,1,1,1,1,1,1,1,1,1,1,1,1,1
1,1,1,1,1,1,1,1,1,1,1,1,1,1,1,1
1,1,1,1,1,1,1,1,65,64,65,1,1,1,1,1
1,1,1,1,1,1,1,64,66,66,66,65,1,1,1,1
1,1,1,1,1,1,65,66,66,66,66,63,1,1,1,1
1,1,1,1,1,1,56,66,66,66,66,66,65,1,1,1
1,1,10,48,48,1,56,66,66,70,66,66,63,1,1,1
1,1,10,0,42,1,56,66,66,66,66,66,63,1,1,1
1,1,69,11,69,1,1,66,66,66,66,66,66,1,1,1
1,1,1,1,1,1,1,66,66,66,66,66,66,65,1,1
1,1,1,1,1,1,1,56,66,66,66,66,66,1,1,1
1,1,1,1,1,1,1,1,66,66,38,66,66,1,1,1
1,1,1,1,1,1,1,1,68,66,66,66,65,1,1,1
1,1,1,1,1,1,1,1,1,68,68,65,1,1,1,1
1,1,1,1,1,1,1,1,1,1,1,1,1,1,1,1
1,1,1,1,1,1,1,1,1,1,1,1,1,1,1,1
endlayer

layer
1,1,1,1,1,1,1,1,1,1,1,1,1,1,1,1
1,1,1,1,1,1,1,1,1,1,1,1,1,1,1,1
1,1,1,1,1,1,1,1,1,1,1,1,1,1,1,1
1,1,1,1,1,1,1,1,59,59,59,1,1,1,1,1
1,1,1,1,1,1,1,59,59,1,59,1,1,1,1,1
1,1,1,1,1,1,1,59,1,1,1,59,1,1,1,1
1,1,6,6,35,1,1,59,1,1,1,59,1,1,1,1
1,1,41,0,35,1,1,59,1,1,1,59,1,1,1,1
1,1,41,11,11,1,1,59,1,1,1,59,59,1,1,1
1,1,1,1,1,1,1,59,59,1,1,1,59,1,1,1
1,1,1,1,1,1,1,1,59,1,1,1,59,1,1,1
1,1,1,1,1,1,1,1,59,59,1,59,1,1,1,1
1,1,1,1,1,1,1,1,1,59,59,59,1,1,1,1
1,1,1,1,1,1,1,1,1,1,1,1,1,1,1,1
1,1,1,1,1,1,1,1,1,1,1,1,1,1,1,1
1,1,1,1,1,1,1,1,1,1,1,1,1,1,1,1
endlayer

layer
1,1,1,1,1,1,1,1,1,1,1,1,1,1,1,1
1,1,1,1,1,1,1,1,1,1,1,1,1,1,1,1
1,1,1,1,1,1,1,1,1,1,1,1,1,1,1,1
1,1,1,1,1,1,1,1,1,1,1,1,1,1,1,1
1,1,1,1,1,1,1,1,1,1,1,1,1,1,1,1
1,1,1,1,1,1,1,1,1,1,1,1,1,1,1,1
1,1,1,7,6,1,1,1,1,1,1,1,1,1,1,1
1,1,10,0,7,1,1,1,1,1,1,1,1,1,1,1
1,1,69,7,11,1,1,1,1,1,1,1,1,1,1,1
1,1,1,1,1,1,1,1,1,1,1,1,1,1,1,1
1,1,1,1,1,1,1,1,1,1,1,1,1,1,1,1
1,1,1,1,1,1,1,1,1,1,1,1,1,1,1,1
1,1,1,1,1,1,1,1,1,1,1,1,1,1,1,1
1,1,1,1,1,1,1,1,1,1,1,1,1,1,1,1
1,1,1,1,1,1,1,1,1,1,1,1,1,1,1,1
1,1,1,1,1,1,1,1,1,1,1,1,1,1,1,1
endlayer

layer
1,1,1,1,1,1,1,1,1,1,1,1,1,1,1,1
1,1,1,1,1,1,1,1,1,1,1,1,1,1,1,1
1,1,1,1,1,1,1,1,1,1,1,1,1,1,1,1
1,1,1,1,1,1,1,1,1,1,1,1,1,1,1,1
1,1,1,1,1,1,1,1,1,1,1,1,1,1,1,1
1,1,1,1,1,1,1,1,1,1,1,1,1,1,1,1
1,1,41,7,42,1,1,1,1,1,1,1,1,1,1,1
1,1,10,0,7,1,1,1,1,1,1,1,1,1,1,1
1,1,1,11,1,1,1,1,1,1,1,1,1,1,1,1
1,1,1,1,1,1,1,1,1,1,1,1,1,1,1,1
1,1,1,1,1,1,1,1,1,1,1,1,1,1,1,1
1,1,1,1,1,1,1,1,1,1,1,1,1,1,1,1
1,1,1,1,1,1,1,1,1,1,1,1,1,1,1,1
1,1,1,1,1,1,1,1,1,1,1,1,1,1,1,1
1,1,1,1,1,1,1,1,1,1,1,1,1,1,1,1
1,1,1,1,1,1,1,1,1,1,1,1,1,1,1,1
endlayer

layer
1,1,1,1,1,1,1,1,1,1,1,1,1,1,1,1
1,1,1,1,1,1,1,1,1,1,1,1,1,1,1,1
1,1,1,1,1,1,1,1,1,1,1,1,1,1,1,1
1,1,1,1,1,1,1,1,1,1,1,1,1,1,1,1
1,1,1,1,1,1,1,1,1,1,1,1,1,1,1,1
1,1,1,1,1,1,1,1,1,1,1,1,1,1,1,1
1,1,6,7,1,1,1,1,1,1,1,1,1,1,1,1
1,1,7,0,42,1,1,1,1,1,1,1,1,1,1,1
1,1,1,69,1,1,1,1,1,1,1,1,1,1,1,1
1,1,1,1,1,1,1,1,1,1,1,1,1,1,1,1
1,1,1,1,1,1,1,1,1,1,1,1,1,1,1,1
1,1,1,1,1,1,1,1,1,1,1,1,1,1,1,1
1,1,1,1,1,1,1,1,1,1,1,1,1,1,1,1
1,1,1,1,1,1,1,1,1,1,1,1,1,1,1,1
1,1,1,1,1,1,1,1,1,1,1,1,1,1,1,1
1,1,1,1,1,1,1,1,1,1,1,1,1,1,1,1
endlayer

layer
1,1,1,1,1,1,1,1,1,1,1,1,1,1,1,1
1,1,1,1,1,1,1,1,1,1,1,1,1,1,1,1
1,1,1,1,1,1,1,1,1,1,1,1,1,1,1,1
1,1,1,1,1,1,1,1,1,1,1,1,1,1,1,1
1,1,1,1,1,1,1,1,1,1,1,1,1,1,1,1
1,1,1,1,1,1,1,1,1,1,1,1,1,1,1,1
1,1,1,48,1,1,1,1,1,1,1,1,1,1,1,1
1,1,7,0,35,1,1,1,1,1,1,1,1,1,1,1
1,1,10,7,1,1,1,1,1,1,1,1,1,1,1,1
1,1,1,1,1,1,1,1,1,1,1,1,1,1,1,1
1,1,1,1,1,1,1,1,1,1,1,1,1,1,1,1
1,1,1,1,1,1,1,1,1,1,1,1,1,1,1,1
1,1,1,1,1,1,1,1,1,1,1,1,1,1,1,1
1,1,1,1,1,1,1,1,1,1,1,1,1,1,1,1
1,1,1,1,1,1,1,1,1,1,1,1,1,1,1,1
1,1,1,1,1,1,1,1,1,1,1,1,1,1,1,1
endlayer

layer
1,1,1,1,1,1,1,1,1,1,1,1,1,1,1,1
1,1,1,1,1,1,1,1,1,1,1,1,1,1,1,1
1,1,1,1,1,1,1,1,1,1,1,1,1,1,1,1
1,1,1,1,1,1,1,1,1,1,1,1,1,1,1,1
1,1,1,1,1,1,1,1,1,1,1,1,1,1,1,1
1,1,1,1,1,1,1,1,1,1,1,1,1,1,1,1
1,1,1,48,1,1,1,1,1,1,1,1,1,1,1,1
1,1,10,0,7,1,1,1,1,1,1,1,1,1,1,1
1,1,1,7,49,1,1,1,1,1,1,1,1,1,1,1
1,1,1,1,1,1,1,1,1,1,1,1,1,1,1,1
1,1,1,1,1,1,1,1,1,1,1,1,1,1,1,1
1,1,1,1,1,1,1,1,1,1,1,1,1,1,1,1
1,1,1,1,1,1,1,1,1,1,1,1,1,1,1,1
1,1,1,1,1,1,1,1,1,1,1,1,1,1,1,1
1,1,1,1,1,1,1,1,1,1,1,1,1,1,1,1
1,1,1,1,1,1,1,1,1,1,1,1,1,1,1,1
endlayer

layer
1,1,1,1,1,1,1,1,1,1,1,1,1,1,1,1
1,1,1,1,1,1,1,1,1,1,1,1,1,1,1,1
1,1,1,1,1,1,1,1,1,1,1,1,1,1,1,1
1,1,1,1,1,1,1,1,1,1,1,1,1,1,1,1
1,1,1,1,1,1,1,1,1,1,1,1,1,1,1,1
1,1,1,1,1,1,1,1,1,1,1,1,1,1,1,1
1,1,1,7,1,1,1,1,1,1,1,1,1,1,1,1
1,1,41,0,42,1,1,1,1,1,1,1,1,1,1,1
1,1,1,69,1,1,1,1,1,1,1,1,1,1,1,1
1,1,1,1,1,1,1,1,1,1,1,1,1,1,1,1
1,1,1,1,1,1,1,1,1,1,1,1,1,1,1,1
1,1,1,1,1,1,1,1,1,1,1,1,1,1,1,1
1,1,1,1,1,1,1,1,1,1,1,1,1,1,1,1
1,1,1,1,1,1,1,1,1,1,1,1,1,1,1,1
1,1,1,1,1,1,1,1,1,1,1,1,1,1,1,1
1,1,1,1,1,1,1,1,1,1,1,1,1,1,1,1
endlayer

layer
1,1,1,1,1,1,1,1,1,1,1,1,1,1,1,1
1,1,1,1,1,1,1,1,1,1,1,1,1,1,1,1
1,1,1,1,1,1,1,1,1,1,1,1,1,1,1,1
1,1,1,1,1,1,1,1,1,1,1,1,1,1,1,1
1,1,1,1,1,1,1,1,1,1,1,1,1,1,1,1
1,1,1,1,1,1,1,1,1,1,1,1,1,1,1,1
1,1,1,6,1,1,1,1,1,1,1,1,1,1,1,1
1,1,10,71,42,1,1,1,1,1,1,1,1,1,1,1
1,1,1,69,1,1,1,1,1,1,1,1,1,1,1,1
1,1,1,1,1,1,1,1,1,1,1,1,1,1,1,1
1,1,1,1,1,1,1,1,1,1,1,1,1,1,1,1
1,1,1,1,1,1,1,1,1,1,1,1,1,1,1,1
1,1,1,1,1,1,1,1,1,1,1,1,1,1,1,1
1,1,1,1,1,1,1,1,1,1,1,1,1,1,1,1
1,1,1,1,1,1,1,1,1,1,1,1,1,1,1,1
1,1,1,1,1,1,1,1,1,1,1,1,1,1,1,1
endlayer

layer
1,1,1,1,1,1,1,1,1,1,1,1,1,1,1,1
1,1,1,1,1,1,1,1,1,1,1,1,1,1,1,1
1,1,1,1,1,1,1,1,1,1,1,1,1,1,1,1
1,1,1,1,1,1,1,1,1,1,1,1,1,1,1,1
1,1,1,1,1,1,1,1,1,1,1,1,1,1,1,1
1,1,1,1,1,1,1,1,1,1,1,1,1,1,1,1
1,1,1,49,1,1,1,1,1,1,1,1,1,1,1,1
1,1,49,0,49,1,1,1,1,1,1,1,1,1,1,1
1,1,1,49,1,1,1,1,1,1,1,1,1,1,1,1
1,1,1,1,1,1,1,1,1,1,1,1,1,1,1,1
1,1,1,1,1,1,1,1,1,1,1,1,1,1,1,1
1,1,1,1,1,1,1,1,1,1,1,1,1,1,1,1
1,1,1,1,1,1,1,1,1,1,1,1,1,1,1,1
1,1,1,1,1,1,1,1,1,1,1,1,1,1,1,1
1,1,1,1,1,1,1,1,1,1,1,1,1,1,1,1
1,1,1,1,1,1,1,1,1,1,1,1,1,1,1,1
endlayer

