
# Created by Ruins mod version 16.7 Ingame Parser
# authoring Player: lafuller

weight=1
embed_into_distance=4
acceptable_target_blocks=
unacceptable_target_blocks=flowing_water,water,flowing_lava,lava,ice,bedrock,netherrack,nether_brick,nether_brick_fence,soul_sand,quartz_ore,end_stone,obsidian,iron_bars,cloud,flesh,ash_block,slime_grass,slime_congealed,slime_dirt
biomesToSpawnIn=plains,prarie,meadow,tundra,brushland,shrubland,woodland,woodlands,lavender_fields,flower_field,sunflower_plains,ice_flats,ice_plains
dimensions=20,12,13
allowable_overhang=0
max_leveling=4
leveling_buffer=-1
preserve_water=0
preserve_lava=0

rule1=0,100,preserveBlock
rule2=0,100,stonebrick-0,stonebrick-0,stonebrick-0,stonebrick-0,stonebrick-1,stonebrick-2,stonebrick-2,stone-5,stone-6,cobblestone
rule3=0,100,minecraft:stone-6
rule4=0,100,stonebrick-0,stonebrick-2,stonebrick-1,stonebrick-1,stonebrick-1,cobblestone
rule5=0,100,stonebrick-0,stonebrick-1,stonebrick-2,stonebrick-2,stone-5,stone-5,stone-6,stone-6
rule6=0,100,stonebrick-0,stonebrick-2,stonebrick-0,stonebrick-1,stonebrick-1,cobblestone
rule7=0,100,minecraft:stone_brick_stairs-0
rule8=0,100,minecraft:stone_brick_stairs-3
rule9=0,100,stonebrick-0,stonebrick-0,stonebrick-0,stonebrick-0,stonebrick-1,stonebrick-2,stonebrick-2,stone-5,stone-6,cobblestone,gravel
rule10=0,100,minecraft:cobblestone_wall-0
rule11=0,100,minecraft:stone-5
rule12=0,100,minecraft:log-0
rule13=0,100,minecraft:wooden_slab-9
rule14=0,100,minecraft:stone_brick_stairs-1
rule15=0,100,minecraft:web-0,air,air,air
rule16=0,100,minecraft:stone_brick_stairs-2
rule17=0,100,minecraft:stone_brick_stairs-6
rule18=0,100,minecraft:lit_pumpkin-0
rule19=0,100,minecraft:mycelium-0
rule20=0,100,minecraft:stone-3
rule21=0,100,minecraft:stone-4
rule22=0,100,minecraft:stained_hardened_clay-9
rule23=0,100,minecraft:oak_stairs-4
rule24=0,100,minecraft:stone_brick_stairs-4
rule25=0,100,minecraft:stone_brick_stairs-7
rule26=0,100,minecraft:cauldron-0
rule27=0,100,minecraft:oak_stairs-1
rule28=0,100,minecraft:oak_stairs-0
rule29=0,100,minecraft:oak_stairs-3
rule30=0,100,ChestGenHook:chests/spawn_bonus_chest:5-2
rule31=0,100,minecraft:oak_stairs-2
rule32=0,100,minecraft:double_stone_slab-8
rule33=0,100,minecraft:planks-0
rule34=0,100,minecraft:jungle_door-2
rule35=0,100,minecraft:furnace-5
rule36=0,100,minecraft:stone_brick_stairs-5
rule37=0,100,minecraft:oak_stairs-6
rule38=0,100,minecraft:fence-0
rule39=0,100,minecraft:oak_stairs-7
rule40=0,100,minecraft:oak_stairs-5
rule41=0,100,minecraft:jungle_door-9
rule42=0,100,minecraft:jungle_door-8
rule43=0,100,minecraft:wooden_slab-13
rule44=0,100,minecraft:dark_oak_stairs-3
rule45=0,100,minecraft:planks-1
rule46=0,100,minecraft:stone_slab-13
rule47=0,100,minecraft:wooden_slab-8
rule48=0,100,minecraft:wooden_slab-0
rule49=0,100,minecraft:dark_oak_stairs-7
rule50=0,100,minecraft:spruce_stairs-6
rule51=0,100,minecraft:spruce_stairs-7
rule52=0,100,minecraft:dark_oak_stairs-1
rule53=0,100,minecraft:dark_oak_stairs-2
rule54=0,100,minecraft:spruce_stairs-5
rule55=0,100,minecraft:spruce_fence_gate-1
rule56=0,100,minecraft:planks-5
rule57=0,100,minecraft:dark_oak_stairs-4
rule58=0,100,minecraft:wooden_slab-5
rule59=0,100,minecraft:spruce_stairs-4
rule60=0,100,minecraft:dark_oak_stairs-0
rule61=0,100,minecraft:dark_oak_stairs-5
rule62=0,100,minecraft:log-11
rule63=0,100,minecraft:trapdoor-13
rule64=0,100,minecraft:spruce_stairs-3
rule65=0,100,minecraft:log-7
rule66=0,100,minecraft:dark_oak_fence-0
rule67=0,100,minecraft:jungle_door-3
rule68=0,100,minecraft:spruce_fence_gate-2
rule69=0,100,minecraft:iron_bars-0
rule70=0,100,minecraft:stone_slab-0

layer
1,1,1,1,1,1,2,2,2,2,2,2,1
1,1,3,2,2,2,2,2,2,2,2,2,2
1,2,4,4,4,4,4,4,4,2,2,2,2
1,2,4,4,4,4,5,4,4,2,2,2,2
1,2,4,5,4,5,5,5,4,4,4,2,1
1,2,4,5,5,6,6,6,5,5,4,2,1
1,2,4,5,6,6,6,6,5,4,4,3,1
1,2,4,4,5,5,5,6,5,4,4,2,1
1,2,4,4,4,5,4,5,5,4,4,2,1
1,1,3,4,4,4,4,4,4,4,4,2,7
1,1,8,2,2,2,3,2,2,2,2,2,2
1,1,8,2,2,2,2,2,2,2,2,2,2
endlayer

layer
1,1,1,1,1,1,9,9,9,9,9,9,1
1,1,11,9,9,10,9,10,9,9,9,9,9
1,9,9,9,9,13,13,13,12,9,9,9,9
1,9,14,12,0,0,0,0,0,9,9,9,9
1,9,0,0,0,0,0,0,0,0,12,9,1
1,10,0,0,0,0,0,0,0,0,13,10,1
1,9,0,0,0,0,0,0,0,0,13,11,1
1,10,15,0,0,0,0,0,0,0,13,9,1
1,9,12,0,0,0,0,0,0,0,13,10,1
1,1,11,12,13,13,12,13,13,13,12,9,1
1,1,1,9,9,10,11,10,9,10,9,9,7
1,1,1,8,9,9,9,9,9,9,9,9,16
endlayer

layer
1,1,1,1,1,1,9,9,9,9,9,9,1
1,1,3,9,9,10,9,10,9,9,9,9,9
1,9,0,8,9,15,0,15,12,9,9,9,9
1,9,0,12,15,0,0,0,15,9,9,9,9
1,9,0,0,0,0,0,0,0,15,12,9,1
1,10,0,0,0,0,0,0,0,0,15,10,1
1,9,0,0,0,0,0,0,0,0,0,3,1
1,10,15,0,0,0,0,0,0,0,0,9,1
1,9,12,15,0,0,0,0,0,0,15,10,1
1,1,3,12,15,15,12,15,0,15,12,9,1
1,1,1,9,9,10,3,10,9,10,9,16,1
1,1,1,1,8,9,9,9,9,9,9,16,1
endlayer

layer
1,1,1,1,1,1,9,9,9,9,9,9,1
1,1,11,10,9,9,9,10,9,9,9,9,9
1,9,0,0,8,17,15,15,12,9,9,9,9
1,10,0,12,15,15,0,15,15,9,9,9,9
1,9,0,0,15,0,0,0,15,15,12,9,1
1,10,0,0,0,0,0,0,0,15,15,10,1
1,9,15,0,0,0,0,0,0,0,15,11,1
1,10,15,15,0,0,0,0,0,0,15,9,1
1,9,12,15,15,0,15,0,0,15,15,10,1
1,1,11,12,15,15,12,15,15,15,12,9,1
1,1,1,9,9,9,11,10,9,10,9,1,1
1,1,1,1,1,8,9,9,9,9,16,1,1
endlayer

layer
1,1,1,1,1,1,2,2,2,9,9,9,1
1,1,3,2,2,2,9,9,9,9,19,18,9
1,2,0,0,0,8,3,3,3,3,19,19,9
1,2,0,20,21,20,21,20,21,20,3,9,9
1,2,23,22,3,3,3,3,3,3,3,2,1
1,2,22,22,22,22,22,22,22,22,22,2,1
1,2,22,22,22,22,22,22,22,22,22,3,1
1,2,22,22,22,22,22,22,22,22,22,2,1
1,2,22,22,22,22,22,22,22,22,22,2,1
1,1,3,22,22,22,22,22,22,22,22,2,1
1,1,1,2,2,2,3,22,22,2,2,1,1
1,1,1,1,1,1,8,9,9,16,1,1,1
endlayer

layer
1,1,1,1,1,1,25,7,24,9,9,9,1
1,1,12,28,28,27,14,3,3,3,0,26,9
1,29,0,0,0,0,0,0,0,0,0,0,9
1,29,23,30,0,0,0,0,0,0,0,3,14
1,29,33,33,12,32,32,32,0,0,0,31,1
1,29,27,27,31,0,0,0,0,0,0,31,1
1,29,0,0,0,0,0,0,0,0,0,12,1
1,29,0,0,0,0,0,0,0,0,0,31,1
1,29,0,0,0,0,0,0,0,0,0,31,1
1,1,12,0,0,0,0,0,0,0,12,31,1
1,1,1,27,27,27,12,34,34,27,27,1,1
1,1,1,1,1,1,1,1,1,1,1,1,1
endlayer

layer
1,1,1,1,1,1,7,7,7,9,9,9,1
1,1,12,23,0,0,36,35,35,35,0,0,9
1,38,37,0,0,0,0,0,0,0,0,0,9
1,39,33,0,0,0,0,0,0,0,0,9,17
1,39,27,27,12,0,0,0,0,0,0,38,1
1,38,0,0,0,0,0,0,0,0,0,0,1
1,0,0,0,0,0,0,0,0,0,0,12,1
1,38,0,0,0,0,0,0,0,0,0,0,1
1,39,0,0,0,0,0,0,0,0,0,38,1
1,1,12,0,0,0,0,0,0,0,12,38,1
1,1,1,38,0,38,12,42,41,40,38,1,1
1,1,1,1,1,1,1,1,1,1,1,1,1
endlayer

layer
1,1,44,43,1,1,16,7,7,9,9,9,1
1,1,12,45,45,45,8,16,14,14,0,0,9
1,39,48,29,47,0,0,0,0,0,46,0,9
49,45,48,27,47,0,0,0,0,0,0,9,14
1,45,0,0,12,0,0,0,0,0,0,50,1
1,51,0,0,0,0,0,0,0,0,0,50,1
1,51,0,0,0,0,0,0,0,0,0,12,1
1,51,0,0,0,0,0,0,0,0,0,50,1
43,51,0,0,0,0,0,0,0,0,0,50,1
1,52,12,0,0,0,0,0,0,0,12,50,43
1,1,56,54,54,54,12,55,55,54,54,53,1
1,1,43,1,1,1,1,1,1,1,43,1,1
endlayer

layer
1,1,1,58,57,49,56,8,7,7,9,9,1
1,59,12,45,45,45,45,9,9,9,9,0,9
1,51,0,0,29,37,0,0,25,36,9,9,9
1,51,0,0,29,37,0,0,0,25,36,9,16
60,45,0,0,12,0,0,0,0,0,59,56,58
43,45,0,0,0,0,0,0,0,0,51,56,61
43,45,0,0,0,0,0,0,0,0,51,12,43
52,45,59,0,0,0,0,0,0,0,51,56,43
1,44,50,0,0,0,0,0,0,0,51,52,58
1,1,56,59,59,59,59,59,59,59,56,53,1
1,1,58,52,56,56,56,56,56,52,52,1,1
1,1,1,58,43,43,58,43,43,58,1,1,1
endlayer

layer
1,1,1,1,1,58,1,1,1,1,25,9,1
63,62,62,12,62,62,62,62,62,62,9,0,9
1,64,0,0,0,29,33,33,33,33,9,9,16
1,64,0,0,0,29,45,45,45,33,45,14,1
1,64,0,0,12,28,33,33,45,33,45,1,1
1,44,0,0,33,33,45,45,33,33,56,60,1
1,44,45,45,33,45,45,33,33,33,56,53,1
1,52,45,45,33,33,45,45,33,33,52,58,1
1,1,44,45,33,33,33,33,33,33,53,1,1
1,1,1,52,65,45,45,45,45,52,58,1,1
1,1,1,1,44,52,52,52,53,1,1,1,1
1,1,1,1,1,1,1,1,1,1,1,1,1
endlayer

layer
1,1,1,1,1,1,1,1,1,1,7,9,1
1,1,23,12,28,28,28,12,28,28,9,0,9
1,39,0,0,0,0,0,0,0,0,9,9,14
1,29,0,0,0,0,0,0,0,0,31,1,1
1,29,0,0,12,0,0,0,0,0,31,1,1
1,1,27,27,29,0,0,0,0,12,27,1,1
1,1,66,0,31,0,0,0,0,31,1,1,1
1,1,66,0,67,0,0,0,0,31,1,1,1
1,1,0,66,12,0,0,0,12,27,1,1,1
1,1,1,1,1,27,27,27,31,1,1,1,1
1,1,1,1,1,1,1,1,1,1,1,1,1
1,1,1,1,1,1,1,1,1,1,1,1,1
endlayer

layer
1,1,1,1,1,1,1,1,1,1,8,9,1
1,1,23,12,38,0,38,12,0,38,9,0,9
1,29,0,0,0,0,0,0,0,0,9,9,16
1,38,0,0,0,0,0,0,0,0,38,1,1
1,39,0,0,12,0,0,0,0,0,0,1,1
1,1,40,27,29,0,0,0,0,12,38,1,1
1,1,0,0,37,0,0,0,0,38,1,1,1
1,1,0,0,41,0,0,0,0,0,1,1,1
1,1,0,0,12,0,0,0,12,38,1,1,1
1,1,1,1,1,38,0,38,38,1,1,1,1
1,1,1,1,1,1,1,1,1,1,1,1,1
1,1,1,1,1,1,1,1,1,1,1,1,1
endlayer

layer
1,1,43,1,1,1,1,1,1,1,24,9,1
1,49,59,12,59,59,59,12,59,59,9,0,9
1,51,0,0,0,0,0,0,0,0,9,9,36
1,51,0,0,0,0,0,0,0,0,50,1,1
1,51,0,0,12,0,0,0,0,0,50,1,1
1,52,54,54,51,0,0,0,0,12,50,1,1
1,1,1,0,51,0,0,0,0,50,61,1,1
1,1,1,0,68,0,0,0,0,50,1,1,1
1,1,1,0,12,0,0,0,12,54,1,1,1
1,1,1,43,57,54,54,54,51,52,1,1,1
1,1,1,1,43,1,1,1,1,1,1,1,1
1,1,1,1,1,1,1,1,1,1,1,1,1
endlayer

layer
1,1,1,58,43,43,43,58,43,43,25,9,1
1,1,60,12,56,56,56,12,56,56,9,0,9
58,56,50,54,54,54,54,54,54,54,56,9,16
43,56,50,0,0,13,0,0,0,51,56,43,1
58,56,59,59,12,13,0,0,0,51,56,43,1
1,1,44,56,56,50,0,0,0,12,56,52,1
1,1,1,43,56,50,13,13,59,56,56,1,1
1,1,1,43,56,50,13,13,51,56,56,1,1
1,1,1,58,44,50,59,59,12,52,58,1,1
1,1,1,1,58,52,56,56,52,1,1,1,1
1,1,1,1,1,58,43,43,58,1,1,1,1
1,1,1,1,1,1,1,1,1,1,1,1,1
endlayer

layer
1,1,1,1,1,58,1,1,1,58,7,9,1
1,1,1,58,60,56,56,56,60,53,9,0,9
1,1,60,56,56,56,56,56,56,60,53,9,14
1,58,56,66,45,45,45,45,45,56,53,58,1
1,1,52,56,56,56,45,45,45,45,56,1,1
1,1,1,58,44,56,45,45,45,56,53,1,1
1,1,1,1,52,56,56,45,45,56,58,1,1
1,1,1,1,58,44,56,56,56,53,1,1,1
1,1,1,1,1,58,56,56,58,1,1,1,1
1,1,1,1,1,1,52,53,1,1,1,1,1
1,1,1,1,1,1,1,1,1,1,1,1,1
1,1,1,1,1,1,1,1,1,1,1,1,1
endlayer

layer
1,1,1,1,1,1,1,1,1,1,1,9,1
1,1,1,1,1,66,66,66,66,1,9,0,9
1,1,1,66,66,58,58,58,58,66,1,9,1
1,1,66,66,58,58,58,58,58,58,66,1,1
1,1,1,66,66,58,58,58,58,58,66,1,1
1,1,1,1,1,66,58,58,58,66,1,1,1
1,1,1,1,1,66,58,58,58,66,1,1,1
1,1,1,1,1,1,66,58,66,1,1,1,1
1,1,1,1,1,1,66,66,1,1,1,1,1
1,1,1,1,1,1,1,1,1,1,1,1,1
1,1,1,1,1,1,1,1,1,1,1,1,1
1,1,1,1,1,1,1,1,1,1,1,1,1
endlayer

layer
1,1,1,1,1,1,1,1,1,1,1,9,1
1,1,1,1,1,1,1,1,1,1,9,0,9
1,1,1,1,1,1,1,1,1,1,1,9,1
1,1,1,1,1,1,1,1,1,1,1,1,1
1,1,1,1,1,1,1,1,1,1,1,1,1
1,1,1,1,1,1,1,1,1,1,1,1,1
1,1,1,1,1,1,1,1,1,1,1,1,1
1,1,1,1,1,1,1,1,1,1,1,1,1
1,1,1,1,1,1,1,1,1,1,1,1,1
1,1,1,1,1,1,1,1,1,1,1,1,1
1,1,1,1,1,1,1,1,1,1,1,1,1
1,1,1,1,1,1,1,1,1,1,1,1,1
endlayer

layer
1,1,1,1,1,1,1,1,1,1,1,9,1
1,1,1,1,1,1,1,1,1,1,9,0,9
1,1,1,1,1,1,1,1,1,1,1,9,1
1,1,1,1,1,1,1,1,1,1,1,1,1
1,1,1,1,1,1,1,1,1,1,1,1,1
1,1,1,1,1,1,1,1,1,1,1,1,1
1,1,1,1,1,1,1,1,1,1,1,1,1
1,1,1,1,1,1,1,1,1,1,1,1,1
1,1,1,1,1,1,1,1,1,1,1,1,1
1,1,1,1,1,1,1,1,1,1,1,1,1
1,1,1,1,1,1,1,1,1,1,1,1,1
1,1,1,1,1,1,1,1,1,1,1,1,1
endlayer

layer
1,1,1,1,1,1,1,1,1,1,1,7,1
1,1,1,1,1,1,1,1,1,1,8,69,16
1,1,1,1,1,1,1,1,1,1,1,14,1
1,1,1,1,1,1,1,1,1,1,1,1,1
1,1,1,1,1,1,1,1,1,1,1,1,1
1,1,1,1,1,1,1,1,1,1,1,1,1
1,1,1,1,1,1,1,1,1,1,1,1,1
1,1,1,1,1,1,1,1,1,1,1,1,1
1,1,1,1,1,1,1,1,1,1,1,1,1
1,1,1,1,1,1,1,1,1,1,1,1,1
1,1,1,1,1,1,1,1,1,1,1,1,1
1,1,1,1,1,1,1,1,1,1,1,1,1
endlayer

layer
1,1,1,1,1,1,1,1,1,1,1,70,1
1,1,1,1,1,1,1,1,1,1,70,0,70
1,1,1,1,1,1,1,1,1,1,1,70,1
1,1,1,1,1,1,1,1,1,1,1,1,1
1,1,1,1,1,1,1,1,1,1,1,1,1
1,1,1,1,1,1,1,1,1,1,1,1,1
1,1,1,1,1,1,1,1,1,1,1,1,1
1,1,1,1,1,1,1,1,1,1,1,1,1
1,1,1,1,1,1,1,1,1,1,1,1,1
1,1,1,1,1,1,1,1,1,1,1,1,1
1,1,1,1,1,1,1,1,1,1,1,1,1
1,1,1,1,1,1,1,1,1,1,1,1,1
endlayer

