
# Created by Ruins mod version 16.7 Ingame Parser
# authoring Player: lafuller

weight=1
embed_into_distance=4
acceptable_target_blocks=
unacceptable_target_blocks=flowing_water,water,flowing_lava,lava,ice,bedrock,netherrack,nether_brick,nether_brick_fence,soul_sand,quartz_ore,end_stone,obsidian,iron_bars,cloud,flesh,ash_block,slime_grass,slime_congealed,slime_dirt
biomesToSpawnIn=plains,prarie,meadow,tundra,brushland,shrubland,woodland,woodlands,lavender_fields,flower_field,sunflower_plains,ice_flats,ice_plains
dimensions=20,16,14
allowable_overhang=0
max_leveling=4
leveling_buffer=-1
preserve_water=0
preserve_lava=0

rule1=0,100,preserveBlock
rule2=0,100,minecraft:stone-6
rule3=0,100,stonebrick-0,stonebrick-0,stonebrick-0,stonebrick-0,stonebrick-1,stonebrick-2,stonebrick-2,stone-5,stone-6,cobblestone
rule4=0,100,stonebrick-0,stonebrick-2,stonebrick-1,stonebrick-1,stonebrick-1,cobblestone
rule5=0,100,stonebrick-0,stonebrick-1,stonebrick-2,stonebrick-2,stone-5,stone-5,stone-6,stone-6
rule6=0,100,stonebrick-0,stonebrick-2,stonebrick-0,stonebrick-1,stonebrick-1,cobblestone
rule7=0,100,minecraft:stone_brick_stairs-0
rule8=0,100,minecraft:stone_brick_stairs-2
rule9=0,100,minecraft:stone-5
rule10=0,100,stonebrick-0,stonebrick-0,stonebrick-0,stonebrick-0,stonebrick-1,stonebrick-2,stonebrick-2,stone-5,stone-6,cobblestone,gravel
rule11=0,100,minecraft:cobblestone_wall-0
rule12=0,100,minecraft:log-0
rule13=0,100,minecraft:wooden_slab-9
rule14=0,100,minecraft:ladder-2
rule15=0,100,minecraft:planks-1
rule16=0,100,ChestGenHook:chests/spawn_bonus_chest:5-3
rule17=0,100,minecraft:web-0,air,air,air
rule18=0,100,minecraft:stone_brick_stairs-3
rule19=0,100,minecraft:stone_brick_stairs-1
rule20=0,100,minecraft:stained_hardened_clay-8
rule21=0,100,minecraft:stained_hardened_clay-6
rule22=0,100,minecraft:hardened_clay-0
rule23=0,100,minecraft:stone-4
rule24=0,100,minecraft:dirt-0
rule25=0,100,minecraft:mycelium-0
rule26=0,100,minecraft:lit_pumpkin-1
rule27=0,100,minecraft:oak_stairs-0
rule28=0,100,minecraft:oak_stairs-1
rule29=0,100,minecraft:oak_stairs-3
rule30=0,100,minecraft:oak_stairs-2
rule31=0,100,minecraft:spruce_stairs-4
rule32=0,100,minecraft:planks-0
rule33=0,100,minecraft:fence-0
rule34=0,100,minecraft:spruce_stairs-5
rule35=0,100,minecraft:spruce_fence-0
rule36=0,100,minecraft:double_stone_slab-8
rule37=0,100,minecraft:jungle_door-2
rule38=0,100,minecraft:oak_stairs-7
rule39=0,100,minecraft:oak_stairs-5
rule40=0,100,minecraft:oak_stairs-4
rule41=0,100,minecraft:furnace-3
rule42=0,100,minecraft:jungle_door-9
rule43=0,100,minecraft:jungle_door-8
rule44=0,100,minecraft:stone_brick_stairs-6
rule45=0,100,minecraft:wooden_slab-13
rule46=0,100,minecraft:dark_oak_stairs-0
rule47=0,100,minecraft:dark_oak_stairs-7
rule48=0,100,minecraft:planks-5
rule49=0,100,minecraft:spruce_stairs-6
rule50=0,100,minecraft:wooden_slab-8
rule51=0,100,minecraft:wooden_slab-0
rule52=2,100,minecraft:torch-4
rule53=0,100,minecraft:dark_oak_stairs-1
rule54=0,100,minecraft:oak_stairs-6
rule55=0,100,minecraft:spruce_stairs-7
rule56=0,100,minecraft:stone_slab-13
rule57=0,100,minecraft:spruce_fence_gate-1
rule58=0,100,minecraft:dark_oak_stairs-3
rule59=0,100,minecraft:wooden_slab-5
rule60=0,100,minecraft:double_wooden_slab-5
rule61=0,100,minecraft:dark_oak_stairs-2
rule62=0,100,minecraft:spruce_stairs-0
rule63=0,100,minecraft:spruce_stairs-3
rule64=0,100,minecraft:spruce_stairs-2
rule65=0,100,minecraft:stone_brick_stairs-7
rule66=0,100,minecraft:stone_brick_stairs-5
rule67=0,100,minecraft:log-11
rule68=0,100,minecraft:log-7
rule69=0,100,minecraft:trapdoor-13
rule70=0,100,minecraft:stone_brick_stairs-4
rule71=0,100,minecraft:dark_oak_fence-0
rule72=0,100,minecraft:jungle_door-3
rule73=0,100,minecraft:spruce_stairs-1
rule74=0,100,minecraft:furnace-4
rule75=0,100,minecraft:dark_oak_stairs-5
rule76=0,100,minecraft:spruce_fence_gate-2
rule77=0,100,minecraft:iron_bars-0
rule78=0,100,minecraft:stone_slab-0

layer
1,1,1,1,1,1,1,1,1,1,1,1,1,1
1,1,1,1,1,1,1,1,3,3,3,2,1,1
1,1,1,1,1,1,1,2,2,4,4,2,3,1
1,1,1,1,2,3,3,4,4,4,4,4,3,1
1,1,1,3,2,4,4,4,5,5,5,4,3,1
1,1,1,3,2,4,5,5,6,6,5,4,3,1
1,1,1,3,4,5,6,6,6,5,4,2,3,1
1,1,2,3,4,5,5,6,5,5,4,2,1,1
1,3,2,4,5,6,5,6,5,4,4,3,1,1
1,3,4,5,6,6,6,6,5,4,2,3,1,1
7,3,4,5,5,6,6,5,5,4,3,3,3,1
3,3,4,4,5,5,5,5,4,3,3,3,3,1
3,3,2,4,4,2,4,4,4,3,3,3,3,1
3,3,3,3,3,3,2,4,4,3,3,3,3,1
3,3,3,3,3,3,2,3,3,3,1,1,1,1
3,3,3,3,3,3,3,3,8,1,1,1,1,1
endlayer

layer
1,1,1,1,1,1,1,1,1,1,1,1,1,1
1,1,1,1,1,1,1,1,10,11,10,9,1,1
1,1,1,1,1,1,1,9,12,13,13,12,10,1
1,1,1,1,9,10,10,0,0,0,0,13,11,1
1,1,1,10,12,14,0,0,0,0,0,13,10,1
1,1,1,10,12,14,0,0,0,0,0,13,11,1
1,1,1,11,0,0,0,0,0,0,0,12,10,1
1,1,9,10,0,0,0,0,0,0,0,9,1,1
1,10,12,0,0,0,0,0,0,0,0,11,1,1
1,10,13,0,0,0,0,0,0,0,12,10,1,1
1,11,13,0,0,15,0,0,0,0,10,10,10,1
7,10,13,0,0,15,0,0,0,10,10,10,10,1
10,10,12,13,13,12,1,1,16,10,10,10,10,1
10,10,10,10,10,10,12,13,13,10,10,10,10,1
10,10,10,10,10,10,9,10,11,10,1,1,1,1
10,10,10,10,10,10,10,8,1,1,1,1,1,1
endlayer

layer
1,1,1,1,1,1,1,1,1,1,1,1,1,1
1,1,1,1,1,1,1,1,10,11,10,2,1,1
1,1,1,1,1,1,1,2,12,17,17,12,10,1
1,1,1,1,2,10,10,17,0,0,0,17,11,1
1,1,1,10,12,14,0,0,0,0,0,0,10,1
1,1,1,10,12,14,0,0,0,0,0,17,11,1
1,1,1,11,17,0,0,0,0,0,0,12,10,1
1,1,2,10,0,0,0,0,0,0,0,2,1,1
1,10,12,17,0,0,0,0,0,0,17,11,1,1
1,10,17,0,0,0,0,0,0,0,12,10,1,1
1,11,0,0,0,0,0,0,0,17,10,10,10,1
1,10,17,0,0,0,0,0,0,10,10,10,10,1
7,10,12,17,17,12,17,1,1,10,10,10,10,1
18,10,10,10,10,10,12,17,17,10,10,10,10,1
18,10,10,10,10,10,2,10,11,10,1,1,1,1
18,19,19,19,19,19,8,1,1,1,1,1,1,1
endlayer

layer
1,1,1,1,1,1,1,1,1,1,1,1,1,1
1,1,1,1,1,1,1,1,10,11,10,9,1,1
1,1,1,1,1,1,1,9,12,17,17,12,10,1
1,1,1,1,9,10,10,17,17,0,17,17,11,1
1,1,1,10,12,14,0,0,0,0,0,17,10,1
1,1,1,10,12,14,0,0,0,0,0,17,11,1
1,1,1,11,17,17,0,0,0,0,0,12,10,1
1,1,9,10,17,0,0,0,0,0,17,9,1,1
1,10,12,17,17,0,0,0,0,17,17,11,1,1
1,10,17,17,0,0,0,0,0,17,12,10,1,1
1,11,17,0,0,13,0,0,17,17,10,10,10,1
1,10,17,17,0,13,17,0,0,10,10,10,10,1
1,18,12,17,17,12,17,1,17,10,10,10,10,1
1,18,10,10,10,10,12,17,17,10,10,10,10,1
1,18,19,19,19,19,9,10,11,10,1,1,1,1
1,1,1,1,1,1,1,1,1,1,1,1,1,1
endlayer

layer
1,1,1,1,1,1,1,1,1,1,1,1,1,1
1,1,1,1,1,1,1,1,3,3,3,2,1,1
1,1,1,1,1,1,1,2,20,20,20,20,3,1
1,1,1,1,2,3,3,20,20,21,20,20,3,1
1,1,1,3,12,14,22,22,21,22,21,20,3,1
1,1,1,3,12,14,22,22,21,22,21,20,3,1
1,1,1,3,20,20,20,22,21,22,21,20,3,1
1,1,2,3,20,20,20,22,21,22,20,2,1,1
1,3,20,20,21,22,22,22,20,20,22,3,1,1
1,3,20,21,22,21,22,20,2,2,23,3,1,1
1,3,20,21,21,21,20,2,23,23,2,10,3,1
1,3,20,20,22,22,20,2,23,2,25,24,3,1
1,1,2,22,22,10,22,23,2,10,24,26,3,1
1,1,18,19,19,19,10,10,10,10,3,3,3,1
1,1,1,1,1,1,2,3,3,3,1,1,1,1
1,1,1,1,1,1,1,1,1,1,1,1,1,1
endlayer

layer
1,1,1,1,1,1,1,1,1,1,1,1,1,1
1,1,1,1,1,1,1,1,27,27,27,27,1,1
1,1,1,1,1,1,1,29,0,0,0,12,28,1
1,1,1,1,12,27,27,12,0,0,0,31,30,1
1,1,1,33,32,14,0,0,0,0,0,0,30,1
1,1,1,29,32,14,0,0,0,0,0,0,30,1
1,1,1,29,32,32,12,0,0,0,0,34,30,1
1,35,12,30,28,30,0,0,0,0,0,12,1,1
1,28,31,0,0,0,0,0,0,0,36,30,1,1
1,29,0,0,0,0,0,0,0,0,36,8,1,1
1,29,0,0,0,0,0,0,0,0,0,10,7,1
1,27,34,0,0,0,0,0,0,0,0,0,10,1
1,35,12,37,37,12,36,0,0,10,0,0,10,1
1,1,1,1,1,1,12,36,36,10,10,10,19,1
1,1,1,1,1,1,35,28,28,12,1,1,1,1
1,1,1,1,1,1,1,1,1,1,1,1,1,1
endlayer

layer
1,1,1,1,1,1,1,1,1,1,1,1,1,1
1,1,1,1,1,1,1,1,33,0,33,38,1,1
1,1,1,1,1,1,1,33,0,0,0,12,39,1
1,1,1,1,12,27,40,12,0,0,0,0,33,1
1,1,1,33,32,0,0,0,0,0,0,0,0,1
1,1,1,29,32,0,0,0,0,0,0,0,33,1
1,1,1,38,28,28,12,0,0,0,0,0,40,1
1,35,12,28,0,0,0,0,0,0,0,12,1,1
1,39,0,0,0,0,0,0,0,0,0,33,1,1
1,33,0,0,0,0,0,0,0,0,0,11,1,1
1,33,0,0,0,0,0,0,0,0,0,41,8,1
1,40,0,0,0,0,0,0,0,0,0,0,10,1
1,35,12,43,42,12,0,0,0,11,0,0,10,1
1,1,1,1,1,1,12,0,0,10,10,10,44,1
1,1,1,1,1,1,35,0,33,12,1,1,1,1
1,1,1,1,1,1,1,1,1,1,1,1,1,1
endlayer

layer
1,1,1,1,1,1,1,1,45,1,1,45,1,1
1,1,1,1,1,1,1,47,15,15,15,15,46,1
1,1,1,1,1,1,47,48,0,0,0,12,15,45
1,1,1,1,12,27,32,12,0,0,0,0,49,1
1,1,1,38,51,51,50,50,0,0,0,0,49,1
1,1,1,38,51,51,50,50,0,0,0,0,49,1
1,1,1,38,0,0,12,52,0,0,0,0,15,45
1,46,12,54,0,0,0,0,0,0,0,12,53,1
45,15,0,0,0,0,0,0,0,0,0,49,1,1
1,55,0,0,0,0,0,0,0,0,0,44,1,1
1,55,0,0,0,0,0,0,0,0,0,10,7,1
45,15,0,0,0,0,0,0,0,0,56,0,10,1
1,53,12,57,57,12,0,0,0,11,0,0,10,1
1,1,1,1,1,1,12,0,0,10,10,10,19,1
1,1,1,1,1,1,58,34,34,12,45,1,1,1
1,1,1,1,1,1,1,45,45,45,1,1,1,1
endlayer

layer
1,1,1,1,1,1,1,1,1,46,59,1,1,1
1,1,1,1,1,1,1,1,1,48,60,46,1,1
1,1,1,1,1,1,1,46,34,34,34,12,61,1
1,1,1,35,12,62,62,12,0,0,0,55,60,59
1,1,1,63,0,0,0,29,54,0,0,55,60,61
1,1,1,63,0,0,0,29,54,0,0,55,60,59
1,1,46,63,0,0,12,0,0,0,0,55,61,1
1,46,12,34,0,0,0,0,0,0,0,12,53,1
1,58,49,0,0,0,0,0,0,0,0,64,1,1
58,60,49,0,0,0,0,0,0,0,0,8,1,1
59,60,49,0,0,0,0,0,0,0,65,10,8,1
1,58,49,0,0,0,0,0,0,0,10,66,10,1
1,53,12,67,67,12,0,0,0,10,44,0,10,1
1,1,58,45,45,53,12,31,31,10,10,10,8,1
1,1,1,1,1,1,58,53,48,53,61,1,1,1
1,1,1,1,1,1,1,1,1,1,1,1,1,1
endlayer

layer
1,1,1,1,1,1,1,1,1,1,1,1,1,1
1,1,1,1,1,1,1,1,1,46,46,1,1,1
1,1,1,1,1,1,1,1,58,67,67,48,1,1
1,1,69,67,12,67,67,67,67,67,67,68,61,1
1,1,1,68,0,0,0,0,29,32,15,68,61,1
1,1,1,68,0,0,0,0,29,32,15,68,61,1
1,1,1,68,0,0,12,27,27,15,15,68,53,1
1,1,58,67,67,67,68,67,67,67,67,12,1,1
1,46,48,15,15,15,68,15,32,32,15,68,1,1
1,58,48,15,15,15,68,15,32,15,15,68,1,1
1,58,48,15,15,15,68,15,32,15,15,68,1,1
1,53,48,48,48,48,68,15,15,15,10,10,70,1
1,1,58,48,61,53,15,67,67,15,10,0,10,1
1,1,1,53,1,1,53,58,48,48,66,10,66,1
1,1,1,1,1,1,1,58,53,61,1,1,1,1
1,1,1,1,1,1,1,1,1,1,1,1,1,1
endlayer

layer
1,1,1,1,1,1,1,1,1,1,1,1,1,1
1,1,1,1,1,1,1,1,1,1,1,1,1,1
1,1,1,1,1,1,38,40,40,27,27,1,1,1
1,1,1,27,12,27,12,0,0,0,12,30,1,1
1,1,1,29,0,0,0,0,0,0,0,30,1,1
1,1,1,27,0,0,0,0,0,0,0,30,1,1
1,1,1,12,0,0,12,0,0,0,0,30,1,1
1,1,71,0,28,39,29,0,0,0,0,12,1,1
1,1,71,0,0,0,12,0,0,0,0,30,1,1
1,1,71,0,0,0,72,0,0,0,0,30,1,1
1,1,71,0,0,0,29,0,0,0,0,30,1,1
1,1,71,71,0,0,38,0,0,0,70,10,44,1
1,1,1,71,71,71,73,28,28,12,10,0,10,1
1,1,1,1,1,1,71,71,59,1,18,10,8,1
1,1,1,1,1,1,1,1,1,1,1,1,1,1
1,1,1,1,1,1,1,1,1,1,1,1,1,1
endlayer

layer
1,1,1,1,1,1,1,1,1,1,1,1,1,1
1,1,1,1,1,1,1,1,1,1,1,1,1,1
1,1,1,1,1,1,33,33,0,33,33,1,1,1
1,1,1,38,12,40,12,0,0,0,12,33,1,1
1,1,1,39,0,0,0,0,0,0,0,33,1,1
1,1,1,40,0,0,0,0,0,0,0,0,1,1
1,1,1,12,0,0,12,0,0,0,0,33,1,1
1,1,1,0,39,28,38,0,0,0,0,12,1,1
1,1,1,0,0,0,12,0,0,0,0,33,1,1
1,1,1,0,0,0,43,0,0,0,0,0,1,1
1,1,1,0,0,0,38,0,0,0,0,33,1,1
1,1,1,1,0,0,29,0,0,0,74,10,7,1
1,1,1,1,1,1,55,33,0,12,10,0,10,1
1,1,1,1,1,1,1,1,1,1,19,10,19,1
1,1,1,1,1,1,1,1,1,1,1,1,1,1
1,1,1,1,1,1,1,1,1,1,1,1,1,1
endlayer

layer
1,1,1,1,1,1,1,1,1,1,1,1,1,1
1,1,1,1,1,1,45,1,1,1,45,1,1,1
1,1,45,45,1,45,55,31,31,31,31,46,1,1
1,1,45,15,12,34,12,0,0,0,12,49,45,1
1,1,1,55,0,0,0,0,0,0,0,49,1,1
1,1,1,55,0,0,0,0,0,0,0,49,1,1
1,1,1,12,0,0,12,0,0,0,0,49,1,1
1,1,45,45,73,31,64,0,0,0,0,12,45,1
1,1,1,1,0,75,12,0,0,0,0,49,1,1
1,1,1,1,0,0,76,0,0,0,0,49,1,1
1,1,1,1,0,0,63,0,0,0,0,49,45,1
1,1,1,1,1,0,63,0,0,0,7,10,8,1
1,1,1,1,1,45,48,34,34,12,44,0,10,1
1,1,1,1,1,1,45,1,1,47,65,10,8,1
1,1,1,1,1,1,1,1,1,1,1,1,1,1
1,1,1,1,1,1,1,1,1,1,1,1,1,1
endlayer

layer
1,1,1,1,1,1,1,1,1,1,1,1,1,1
1,1,1,1,1,1,1,58,46,61,1,1,1,1
1,1,1,59,58,46,58,67,67,67,61,1,1,1
1,1,59,46,12,15,12,34,13,34,12,46,1,1
1,1,58,48,49,13,13,0,0,0,55,68,59,1
1,1,58,48,49,13,13,0,0,0,13,68,61,1
1,1,59,48,49,31,12,0,0,0,13,68,59,1
1,1,1,53,48,48,68,67,67,67,67,67,67,71
1,1,1,59,58,53,68,49,0,0,13,68,59,1
1,1,1,1,1,58,68,13,0,0,13,68,61,1
1,1,1,1,1,58,68,31,0,0,55,68,59,1
1,1,1,1,1,53,68,49,31,31,15,10,70,1
1,1,1,1,1,1,53,48,15,12,10,0,10,1
1,1,1,1,1,1,1,53,53,61,66,10,1,1
1,1,1,1,1,1,1,1,1,1,1,1,1,1
1,1,1,1,1,1,1,1,1,1,1,1,1,1
endlayer

layer
1,1,1,1,1,1,1,1,1,1,1,1,1,1
1,1,1,1,1,1,1,1,1,1,1,1,1,1
1,1,1,1,1,1,1,59,61,46,1,1,1,1
1,1,1,1,59,61,48,48,48,48,46,1,1,1
1,1,1,46,48,48,48,15,15,48,48,61,1,1
1,1,1,53,48,48,48,15,15,15,48,46,1,1
1,1,1,58,48,48,48,15,15,15,48,53,1,1
1,1,1,1,58,58,48,48,48,48,48,61,1,1
1,1,1,1,1,1,53,48,15,15,48,46,1,1
1,1,1,1,1,1,53,48,15,15,48,53,1,1
1,1,1,1,1,1,53,48,15,15,48,61,1,1
1,1,1,1,1,1,59,58,48,48,48,10,7,1
1,1,1,1,1,1,1,58,61,53,10,0,10,1
1,1,1,1,1,1,1,1,1,1,18,10,1,1
1,1,1,1,1,1,1,1,1,1,1,1,1,1
1,1,1,1,1,1,1,1,1,1,1,1,1,1
endlayer

layer
1,1,1,1,1,1,1,1,1,1,1,1,1,1
1,1,1,1,1,1,1,1,1,1,1,1,1,1
1,1,1,1,1,1,1,1,1,1,1,1,1,1
1,1,1,1,1,1,71,71,71,71,1,1,1,1
1,1,1,1,71,71,71,59,59,71,71,1,1,1
1,1,1,1,71,59,59,59,59,59,71,1,1,1
1,1,1,1,71,71,71,59,59,59,71,1,1,1
1,1,1,1,1,1,71,71,59,59,71,1,1,1
1,1,1,1,1,1,1,71,59,59,71,1,1,1
1,1,1,1,1,1,1,71,59,59,71,1,1,1
1,1,1,1,1,1,1,71,59,59,71,1,1,1
1,1,1,1,1,1,1,1,71,71,71,10,1,1
1,1,1,1,1,1,1,1,1,1,10,0,10,1
1,1,1,1,1,1,1,1,1,1,1,10,1,1
1,1,1,1,1,1,1,1,1,1,1,1,1,1
1,1,1,1,1,1,1,1,1,1,1,1,1,1
endlayer

layer
1,1,1,1,1,1,1,1,1,1,1,1,1,1
1,1,1,1,1,1,1,1,1,1,1,1,1,1
1,1,1,1,1,1,1,1,1,1,1,1,1,1
1,1,1,1,1,1,1,1,1,1,1,1,1,1
1,1,1,1,1,1,1,1,1,1,1,1,1,1
1,1,1,1,1,1,1,1,1,1,1,1,1,1
1,1,1,1,1,1,1,1,1,1,1,1,1,1
1,1,1,1,1,1,1,1,1,1,1,1,1,1
1,1,1,1,1,1,1,1,1,1,1,1,1,1
1,1,1,1,1,1,1,1,1,1,1,1,1,1
1,1,1,1,1,1,1,1,1,1,1,1,1,1
1,1,1,1,1,1,1,1,1,1,1,10,1,1
1,1,1,1,1,1,1,1,1,1,10,0,10,1
1,1,1,1,1,1,1,1,1,1,1,66,1,1
1,1,1,1,1,1,1,1,1,1,1,1,1,1
1,1,1,1,1,1,1,1,1,1,1,1,1,1
endlayer

layer
1,1,1,1,1,1,1,1,1,1,1,1,1,1
1,1,1,1,1,1,1,1,1,1,1,1,1,1
1,1,1,1,1,1,1,1,1,1,1,1,1,1
1,1,1,1,1,1,1,1,1,1,1,1,1,1
1,1,1,1,1,1,1,1,1,1,1,1,1,1
1,1,1,1,1,1,1,1,1,1,1,1,1,1
1,1,1,1,1,1,1,1,1,1,1,1,1,1
1,1,1,1,1,1,1,1,1,1,1,1,1,1
1,1,1,1,1,1,1,1,1,1,1,1,1,1
1,1,1,1,1,1,1,1,1,1,1,1,1,1
1,1,1,1,1,1,1,1,1,1,1,1,1,1
1,1,1,1,1,1,1,1,1,1,1,70,1,1
1,1,1,1,1,1,1,1,1,1,65,0,8,1
1,1,1,1,1,1,1,1,1,1,1,66,1,1
1,1,1,1,1,1,1,1,1,1,1,1,1,1
1,1,1,1,1,1,1,1,1,1,1,1,1,1
endlayer

layer
1,1,1,1,1,1,1,1,1,1,1,1,1,1
1,1,1,1,1,1,1,1,1,1,1,1,1,1
1,1,1,1,1,1,1,1,1,1,1,1,1,1
1,1,1,1,1,1,1,1,1,1,1,1,1,1
1,1,1,1,1,1,1,1,1,1,1,1,1,1
1,1,1,1,1,1,1,1,1,1,1,1,1,1
1,1,1,1,1,1,1,1,1,1,1,1,1,1
1,1,1,1,1,1,1,1,1,1,1,1,1,1
1,1,1,1,1,1,1,1,1,1,1,1,1,1
1,1,1,1,1,1,1,1,1,1,1,1,1,1
1,1,1,1,1,1,1,1,1,1,1,1,1,1
1,1,1,1,1,1,1,1,1,1,1,70,1,1
1,1,1,1,1,1,1,1,1,1,65,77,8,1
1,1,1,1,1,1,1,1,1,1,1,66,1,1
1,1,1,1,1,1,1,1,1,1,1,1,1,1
1,1,1,1,1,1,1,1,1,1,1,1,1,1
endlayer

layer
1,1,1,1,1,1,1,1,1,1,1,1,1,1
1,1,1,1,1,1,1,1,1,1,1,1,1,1
1,1,1,1,1,1,1,1,1,1,1,1,1,1
1,1,1,1,1,1,1,1,1,1,1,1,1,1
1,1,1,1,1,1,1,1,1,1,1,1,1,1
1,1,1,1,1,1,1,1,1,1,1,1,1,1
1,1,1,1,1,1,1,1,1,1,1,1,1,1
1,1,1,1,1,1,1,1,1,1,1,1,1,1
1,1,1,1,1,1,1,1,1,1,1,1,1,1
1,1,1,1,1,1,1,1,1,1,1,1,1,1
1,1,1,1,1,1,1,1,1,1,1,1,1,1
1,1,1,1,1,1,1,1,1,1,1,78,1,1
1,1,1,1,1,1,1,1,1,1,78,0,78,1
1,1,1,1,1,1,1,1,1,1,1,78,1,1
1,1,1,1,1,1,1,1,1,1,1,1,1,1
1,1,1,1,1,1,1,1,1,1,1,1,1,1
endlayer

