
# Created by Ruins mod version 16.7 Ingame Parser
# authoring Player: lafuller

weight=1
embed_into_distance=4
acceptable_target_blocks=
unacceptable_target_blocks=flowing_water,water,flowing_lava,lava,ice,bedrock,netherrack,nether_brick,nether_brick_fence,soul_sand,quartz_ore,end_stone,obsidian,iron_bars,cloud,flesh,ash_block,slime_grass,slime_congealed,slime_dirt
biomesToSpawnIn=plains,prarie,meadow,tundra,brushland,shrubland,woodland,woodlands,lavender_fields,flower_field,sunflower_plains,ice_flats,ice_plains
dimensions=13,9,9
allowable_overhang=0
max_leveling=4
leveling_buffer=-1
preserve_water=0
preserve_lava=0

rule1=0,100,preserveBlock
rule2=0,100,stonebrick-0,stonebrick-0,stonebrick-0,stonebrick-0,stonebrick-1,stonebrick-2,stonebrick-2,stone-5,stone-6,cobblestone
rule3=0,100,minecraft:dirt-0
rule4=0,100,minecraft:stone_brick_stairs-0
rule5=0,100,minecraft:stone_brick_stairs-3
rule6=0,100,stonebrick-0,stonebrick-0,stonebrick-0,stonebrick-0,stonebrick-1,stonebrick-2,stonebrick-2,stone-5,stone-6,cobblestone,gravel
rule7=0,100,minecraft:cobblestone_wall-0
rule8=0,100,minecraft:stone_brick_stairs-2
rule9=0,100,minecraft:planks-0
rule10=0,100,minecraft:planks-1
rule11=0,100,minecraft:fence-0
rule12=0,100,minecraft:log-0
rule13=0,100,minecraft:oak_stairs-0
rule14=0,100,minecraft:oak_stairs-2
rule15=0,100,minecraft:stone_brick_stairs-5
rule16=0,100,minecraft:oak_stairs-3
rule17=0,100,minecraft:oak_stairs-1
rule18=0,100,minecraft:jungle_door-2
rule19=0,100,minecraft:furnace-5
rule20=0,100,minecraft:oak_stairs-7
rule21=0,100,minecraft:oak_stairs-5
rule22=0,100,minecraft:jungle_door-8
rule23=0,100,minecraft:wooden_slab-13
rule24=0,100,minecraft:dark_oak_stairs-6
rule25=0,100,minecraft:spruce_stairs-4
rule26=0,100,minecraft:dark_oak_stairs-7
rule27=0,100,minecraft:spruce_stairs-6
rule28=0,100,minecraft:spruce_stairs-7
rule29=0,100,minecraft:spruce_stairs-5
rule30=0,100,minecraft:spruce_fence_gate-1
rule31=0,100,minecraft:dark_oak_stairs-5
rule32=0,100,minecraft:wooden_slab-5
rule33=0,100,minecraft:dark_oak_stairs-0
rule34=0,100,minecraft:planks-5
rule35=0,100,minecraft:spruce_stairs-3
rule36=0,100,minecraft:wooden_slab-9
rule37=0,100,minecraft:dark_oak_stairs-2
rule38=0,100,minecraft:dark_oak_stairs-3
rule39=0,100,minecraft:dark_oak_stairs-1
rule40=0,100,minecraft:dark_oak_fence-0
rule41=0,100,ChestGenHook:chests/spawn_bonus_chest:5-4

layer
1,1,1,1,1,1,1,1,1
1,1,2,2,2,2,2,1,1
1,2,3,3,3,3,2,2,1
2,3,3,3,3,3,3,2,1
2,3,3,3,3,3,3,2,1
2,3,3,3,3,3,3,2,4
2,3,3,3,3,3,3,2,2
5,2,2,2,2,2,2,2,2
5,2,2,2,2,2,2,2,2
endlayer

layer
1,1,1,1,1,1,1,1,1
1,1,6,6,7,6,6,1,1
1,6,3,3,3,3,6,6,1
6,3,3,3,3,3,3,6,1
6,3,3,3,3,3,3,7,1
7,3,3,3,3,3,3,6,1
6,3,3,3,3,3,3,6,4
1,6,6,6,6,6,6,6,6
1,5,6,6,6,6,6,6,6
endlayer

layer
1,1,1,1,1,1,1,1,1
1,1,6,6,7,6,6,1,1
1,6,3,3,3,3,6,6,1
6,3,3,3,3,3,3,6,1
6,3,3,3,3,3,3,7,1
7,3,3,3,3,3,3,6,1
6,3,3,3,3,3,3,6,1
1,6,6,6,6,6,6,6,4
1,1,5,6,6,6,6,6,8
endlayer

layer
1,1,1,1,1,1,1,1,1
1,1,6,6,7,6,6,1,1
1,6,3,3,3,3,6,6,1
6,3,3,3,3,3,3,6,1
6,3,3,3,3,3,3,7,1
7,3,3,3,3,3,3,6,1
6,3,3,3,3,3,3,6,1
1,6,6,6,6,6,6,8,1
1,1,1,5,6,6,6,8,1
endlayer

layer
1,1,1,1,1,1,1,1,1
1,1,2,2,2,2,2,1,1
1,2,9,9,9,9,6,2,1
2,9,10,10,10,10,9,2,1
2,9,10,9,9,10,9,2,1
2,9,10,10,10,10,9,2,1
2,9,9,9,9,9,9,2,1
1,2,2,2,2,6,2,1,1
1,1,1,1,5,6,8,1,1
endlayer

layer
1,1,1,1,1,1,1,1,1
1,11,12,13,13,13,12,11,1
1,16,41,0,0,0,15,14,1
11,12,0,0,0,0,0,14,1
16,0,0,0,0,0,0,14,1
16,0,0,0,0,0,0,14,1
12,0,0,0,0,0,0,12,1
11,17,17,17,12,18,17,1,1
1,1,1,1,1,1,1,1,1
endlayer

layer
1,1,1,1,1,1,1,1,1
1,11,12,11,0,11,12,11,1
1,20,0,0,0,0,19,11,1
11,12,0,0,0,0,0,0,1
0,0,0,0,0,0,0,11,1
11,0,0,0,0,0,0,11,1
12,0,0,0,0,0,0,12,1
11,11,0,11,12,22,21,1,1
1,1,1,1,1,1,1,1,1
endlayer

layer
1,23,1,1,1,1,1,23,1
1,26,12,25,25,25,12,24,23
26,10,0,0,0,0,7,27,1
23,12,0,0,0,0,0,27,1
28,0,0,0,0,0,0,27,1
28,0,0,0,0,0,0,27,1
12,0,0,0,0,0,0,12,23
31,29,29,29,12,30,29,23,1
23,1,1,1,1,1,1,23,1
endlayer

layer
1,1,32,23,23,23,32,1,1
1,33,12,34,34,34,12,33,1
1,35,29,29,29,29,7,34,32
33,12,36,0,0,0,28,34,23
34,27,0,0,0,0,28,34,23
34,27,0,0,0,36,28,34,32
12,25,25,25,25,25,28,34,1
38,34,34,34,12,34,34,37,1
32,24,23,23,23,31,37,1,1
endlayer

layer
1,1,1,1,1,1,1,1,1
1,1,32,33,33,33,32,1,1
1,33,34,34,34,34,34,32,1
1,38,34,10,10,10,34,37,1
32,34,10,10,10,10,34,37,1
38,34,10,10,10,34,34,39,1
38,34,34,34,34,34,39,1,1
1,39,38,37,37,39,37,1,1
1,1,39,39,32,1,1,1,1
endlayer

layer
1,1,1,1,1,1,1,1,1
1,1,1,1,1,1,1,1,1
1,1,40,40,40,40,7,1,1
1,1,40,32,32,32,40,1,1
1,40,32,32,32,32,40,1,1
1,40,32,32,32,40,40,1,1
1,40,40,40,40,40,1,1,1
1,1,1,1,1,1,1,1,1
1,1,1,1,1,1,1,1,1
endlayer

layer
1,1,1,1,1,1,1,1,1
1,1,1,1,1,1,1,1,1
1,1,1,1,1,1,7,1,1
1,1,1,1,1,1,1,1,1
1,1,1,1,1,1,1,1,1
1,1,1,1,1,1,1,1,1
1,1,1,1,1,1,1,1,1
1,1,1,1,1,1,1,1,1
1,1,1,1,1,1,1,1,1
endlayer

layer
1,1,1,1,1,1,1,1,1
1,1,1,1,1,1,1,1,1
1,1,1,1,1,1,7,1,1
1,1,1,1,1,1,1,1,1
1,1,1,1,1,1,1,1,1
1,1,1,1,1,1,1,1,1
1,1,1,1,1,1,1,1,1
1,1,1,1,1,1,1,1,1
1,1,1,1,1,1,1,1,1
endlayer

