
# Created by Ruins mod version 16.7 Ingame Parser
# authoring Player: lafuller

weight=1
embed_into_distance=2
acceptable_target_blocks=water
unacceptable_target_blocks=
biomesToSpawnIn=ocean,deep ocean,ocean oil field,kelp forest
dimensions=16,13,13
allowable_overhang=0
max_leveling=0
leveling_buffer=-1
preserve_water=0
preserve_lava=0

rule1=0,100,preserveBlock
rule2=0,100,minecraft:planks-5
rule3=0,100,minecraft:wooden_slab-9
rule4=0,100,minecraft:spruce_stairs-4
rule5=0,100,minecraft:spruce_stairs-6
rule6=0,100,minecraft:planks-1
rule7=0,100,minecraft:ladder-3
rule8=0,100,minecraft:spruce_stairs-7
rule9=0,100,minecraft:ladder-5
rule10=0,100,minecraft:spruce_stairs-5
rule11=0,100,minecraft:trapdoor-14
rule12=0,100,minecraft:wooden_slab-1
rule13=0,100,minecraft:trapdoor-12
rule14=0,100,minecraft:spruce_fence-0
rule15=0,100,minecraft:trapdoor-13
rule16=0,100,minecraft:fence-0
rule17=0,100,minecraft:trapdoor-15
rule18=0,100,minecraft:wool-0

layer
1,1,1,1,1,1,1,1,1,1,1,1,1
1,1,1,1,1,1,1,1,1,1,1,1,1
1,1,1,1,1,1,1,1,1,1,1,1,1
1,1,1,1,1,1,1,1,1,1,1,1,1
1,1,1,1,1,1,1,1,1,1,1,1,1
1,1,1,1,1,1,2,2,1,1,1,1,1
1,1,1,1,1,2,2,2,1,1,1,1,1
1,1,1,1,2,2,2,1,1,1,1,1,1
1,1,1,1,2,2,1,1,1,1,1,1,1
1,1,1,1,1,1,1,1,1,1,1,1,1
1,1,1,1,1,1,1,1,1,1,1,1,1
1,1,1,1,1,1,1,1,1,1,1,1,1
1,1,1,1,1,1,1,1,1,1,1,1,1
endlayer

layer
1,1,1,1,1,1,1,1,1,1,1,1,1
1,1,1,1,1,1,1,1,1,1,1,1,1
1,1,1,1,1,1,1,1,1,1,1,1,1
1,1,1,1,1,1,1,1,1,1,1,1,1
1,1,1,1,1,1,1,2,2,1,1,1,1
1,1,1,1,1,2,2,2,2,1,1,1,1
1,1,1,1,2,2,2,2,1,1,1,1,1
1,1,1,2,2,2,2,2,1,1,1,1,1
1,1,1,2,2,2,2,1,1,1,1,1,1
1,1,1,2,2,2,1,1,1,1,1,1,1
1,1,1,1,1,1,1,1,1,1,1,1,1
1,1,1,1,1,1,1,1,1,1,1,1,1
1,1,1,1,1,1,1,1,1,1,1,1,1
endlayer

layer
1,1,1,1,1,1,1,1,1,1,1,1,1
1,1,1,1,1,1,1,1,1,1,1,1,1
1,1,1,1,1,1,1,1,1,1,1,1,1
1,1,1,1,1,1,1,4,4,3,1,1,1
1,1,1,1,1,4,6,6,6,5,1,1,1
1,1,1,1,4,6,6,6,6,5,1,1,1
1,1,7,6,6,6,6,6,6,1,1,1,1
1,1,1,6,6,6,6,6,5,1,1,1,1
1,1,8,6,6,6,6,5,1,1,1,1,1
1,1,6,6,6,6,6,1,1,1,1,1,1
1,1,3,6,10,1,9,1,1,1,1,1,1
1,1,1,1,1,1,1,1,1,1,1,1,1
1,1,1,1,1,1,1,1,1,1,1,1,1
endlayer

layer
1,1,1,1,1,1,1,1,1,1,1,1,1
1,1,1,1,1,1,1,1,1,1,1,1,1
1,1,1,1,1,1,1,11,4,4,3,1,1
1,1,1,1,1,11,4,6,6,6,5,1,1
1,1,1,1,4,6,0,0,12,6,5,1,1
1,1,1,8,14,0,0,0,0,6,13,1,1
1,1,15,6,0,0,0,0,0,5,1,1,1
1,1,8,0,0,16,0,0,6,13,1,1,1
1,8,6,0,0,0,0,14,5,1,1,1,1
15,6,6,12,0,0,6,10,1,1,1,1,1
1,6,6,6,6,10,17,1,1,1,1,1,1
1,3,6,6,10,1,1,1,1,1,1,1,1
1,1,1,17,1,1,1,1,1,1,1,1,1
endlayer

layer
0,0,0,0,0,0,0,0,0,0,0,0,0
0,0,0,0,0,0,0,0,0,0,4,3,0
0,0,0,0,0,0,0,0,0,12,6,5,0
0,0,0,0,0,0,0,14,14,12,12,0,0
0,0,0,0,0,0,0,0,0,14,0,0,0
0,0,0,0,0,0,0,0,0,14,0,0,0
0,0,0,0,0,0,0,0,0,0,0,0,0
0,0,0,0,0,16,0,0,0,0,0,0,0
0,12,14,0,0,0,0,0,0,0,0,0,0
8,12,14,0,0,0,0,0,0,0,0,0,0
8,12,12,14,14,0,0,0,0,0,0,0,0
0,6,12,12,12,0,0,0,0,0,0,0,0
0,0,10,10,0,0,0,0,0,0,0,0,0
endlayer

layer
0,0,0,0,0,0,0,0,0,0,0,4,4
0,0,0,0,0,0,0,0,0,0,0,12,5
0,0,0,0,0,0,0,0,0,0,14,0,0
0,0,0,0,0,0,0,0,0,0,0,0,0
0,0,0,0,0,0,0,0,0,0,0,0,0
0,0,0,0,0,0,0,0,0,0,0,0,0
0,0,0,0,0,0,0,0,0,0,0,0,0
0,0,0,0,0,16,0,0,0,0,0,0,0
0,0,0,0,0,0,0,0,0,0,0,0,0
14,0,0,0,0,0,0,0,0,0,0,0,0
14,0,0,0,0,0,0,0,0,0,0,0,0
0,14,0,0,0,0,0,0,0,0,0,0,0
0,0,14,14,0,0,0,0,0,0,0,0,0
endlayer

layer
0,0,0,0,0,0,0,0,0,0,0,0,0
0,0,0,0,0,0,0,0,0,0,0,0,0
0,0,0,0,0,0,0,0,0,0,0,0,0
0,0,0,0,0,0,0,0,0,0,0,0,0
0,0,0,0,0,0,0,0,0,0,0,0,0
0,0,0,0,0,18,0,0,0,0,0,0,0
0,0,0,0,0,16,18,0,0,0,0,0,0
0,0,0,0,0,16,16,18,0,0,0,0,0
0,0,0,0,0,0,0,0,0,0,0,0,0
0,0,0,0,0,0,0,0,0,0,0,0,0
0,0,0,0,0,0,0,0,0,0,0,0,0
0,0,0,0,0,0,0,0,0,0,0,0,0
0,0,0,0,0,0,0,0,0,0,0,0,0
endlayer

layer
0,0,0,0,0,0,0,0,0,0,0,0,0
0,0,0,0,0,0,0,0,0,0,0,0,0
0,0,0,0,0,0,0,0,0,0,0,0,0
0,0,0,0,0,0,0,0,0,0,0,0,0
0,0,0,0,18,0,0,0,0,0,0,0,0
0,0,0,0,0,18,18,0,0,0,0,0,0
0,0,0,0,0,0,0,18,0,0,0,0,0
0,0,0,0,0,16,0,18,0,0,0,0,0
0,0,0,0,0,0,0,0,18,0,0,0,0
0,0,0,0,0,0,0,0,0,0,0,0,0
0,0,0,0,0,0,0,0,0,0,0,0,0
0,0,0,0,0,0,0,0,0,0,0,0,0
0,0,0,0,0,0,0,0,0,0,0,0,0
endlayer

layer
0,0,0,0,0,0,0,0,0,0,0,0,0
0,0,0,0,0,0,0,0,0,0,0,0,0
0,0,0,0,0,0,0,0,0,0,0,0,0
0,0,0,0,18,0,0,0,0,0,0,0,0
0,0,0,0,18,18,0,0,0,0,0,0,0
0,0,0,0,0,0,18,0,0,0,0,0,0
0,0,0,0,0,0,0,18,0,0,0,0,0
0,0,0,0,0,16,0,0,18,0,0,0,0
0,0,0,0,0,0,0,0,18,18,0,0,0
0,0,0,0,0,0,0,0,0,0,0,0,0
0,0,0,0,0,0,0,0,0,0,0,0,0
0,0,0,0,0,0,0,0,0,0,0,0,0
0,0,0,0,0,0,0,0,0,0,0,0,0
endlayer

layer
0,0,0,0,0,0,0,0,0,0,0,0,0
0,0,0,0,0,0,0,0,0,0,0,0,0
0,0,0,0,0,0,0,0,0,0,0,0,0
0,0,0,18,18,0,0,0,0,0,0,0,0
0,0,0,0,0,18,0,0,0,0,0,0,0
0,0,0,0,0,0,18,0,0,0,0,0,0
0,0,0,0,0,0,0,18,0,0,0,0,0
0,0,0,0,0,16,0,0,18,0,0,0,0
0,0,0,0,0,0,0,0,0,18,0,0,0
0,0,0,0,0,0,0,0,0,18,0,0,0
0,0,0,0,0,0,0,0,0,0,0,0,0
0,0,0,0,0,0,0,0,0,0,0,0,0
0,0,0,0,0,0,0,0,0,0,0,0,0
endlayer

layer
0,0,0,0,0,0,0,0,0,0,0,0,0
0,0,0,0,0,0,0,0,0,0,0,0,0
0,0,0,0,0,0,0,0,0,0,0,0,0
0,0,0,18,0,0,0,0,0,0,0,0,0
0,0,0,0,18,18,0,0,0,0,0,0,0
0,0,0,0,0,0,18,0,0,0,0,0,0
0,0,0,0,0,0,0,18,0,0,0,0,0
0,0,0,0,0,16,0,0,18,0,0,0,0
0,0,0,0,0,0,0,0,18,0,0,0,0
0,0,0,0,0,0,0,0,0,18,0,0,0
0,0,0,0,0,0,0,0,0,0,0,0,0
0,0,0,0,0,0,0,0,0,0,0,0,0
0,0,0,0,0,0,0,0,0,0,0,0,0
endlayer

layer
0,0,0,0,0,0,0,0,0,0,0,0,0
0,0,0,0,0,0,0,0,0,0,0,0,0
0,0,0,0,0,0,0,0,0,0,0,0,0
0,0,0,0,0,0,0,0,0,0,0,0,0
0,0,0,18,18,0,0,0,0,0,0,0,0
0,0,0,0,0,18,18,0,0,0,0,0,0
0,0,0,0,0,0,0,18,0,0,0,0,0
0,0,0,0,0,16,0,18,0,0,0,0,0
0,0,0,0,0,0,0,0,18,0,0,0,0
0,0,0,0,0,0,0,0,18,0,0,0,0
0,0,0,0,0,0,0,0,0,0,0,0,0
0,0,0,0,0,0,0,0,0,0,0,0,0
0,0,0,0,0,0,0,0,0,0,0,0,0
endlayer

layer
0,0,0,0,0,0,0,0,0,0,0,0,0
0,0,0,0,0,0,0,0,0,0,0,0,0
0,0,0,0,0,0,0,0,0,0,0,0,0
0,0,0,0,0,0,0,0,0,0,0,0,0
0,0,0,18,18,0,0,0,0,0,0,0,0
0,0,0,0,0,18,0,0,0,0,0,0,0
0,0,0,0,0,0,18,0,0,0,0,0,0
0,0,0,0,0,16,0,18,0,0,0,0,0
0,0,0,0,0,0,0,0,18,0,0,0,0
0,0,0,0,0,0,0,0,18,0,0,0,0
0,0,0,0,0,0,0,0,0,0,0,0,0
0,0,0,0,0,0,0,0,0,0,0,0,0
0,0,0,0,0,0,0,0,0,0,0,0,0
endlayer

layer
0,0,0,0,0,0,0,0,0,0,0,0,0
0,0,0,0,0,0,0,0,0,0,0,0,0
0,0,0,0,0,0,0,0,0,0,0,0,0
0,0,0,0,0,0,0,0,0,0,0,0,0
0,0,0,16,16,0,0,0,0,0,0,0,0
0,0,0,0,16,16,0,0,0,0,0,0,0
0,0,0,0,0,16,16,0,0,0,0,0,0
0,0,0,0,0,16,16,16,0,0,0,0,0
0,0,0,0,0,0,0,16,16,0,0,0,0
0,0,0,0,0,0,0,0,16,0,0,0,0
0,0,0,0,0,0,0,0,0,0,0,0,0
0,0,0,0,0,0,0,0,0,0,0,0,0
0,0,0,0,0,0,0,0,0,0,0,0,0
endlayer

layer
0,0,0,0,0,0,0,0,0,0,0,0,0
0,0,0,0,0,0,0,0,0,0,0,0,0
0,0,0,0,0,0,0,0,0,0,0,0,0
0,0,0,0,0,0,0,0,0,0,0,0,0
0,0,0,0,0,0,0,0,0,0,0,0,0
0,0,0,0,0,0,0,0,0,0,0,0,0
0,0,0,0,0,16,0,0,0,0,0,0,0
0,0,0,0,0,16,16,0,0,0,0,0,0
0,0,0,0,0,0,0,0,0,0,0,0,0
0,0,0,0,0,0,0,0,0,0,0,0,0
0,0,0,0,0,0,0,0,0,0,0,0,0
0,0,0,0,0,0,0,0,0,0,0,0,0
0,0,0,0,0,0,0,0,0,0,0,0,0
endlayer

layer
0,0,0,0,0,0,0,0,0,0,0,0,0
0,0,0,0,0,0,0,0,0,0,0,0,0
0,0,0,0,0,0,0,0,0,0,0,0,0
0,0,0,0,0,0,0,0,0,0,0,0,0
0,0,0,0,0,0,0,0,0,0,0,0,0
0,0,0,0,0,0,0,0,0,0,0,0,0
0,0,0,0,0,0,0,0,0,0,0,0,0
0,0,0,0,0,16,0,0,0,0,0,0,0
0,0,0,0,0,0,0,0,0,0,0,0,0
0,0,0,0,0,0,0,0,0,0,0,0,0
0,0,0,0,0,0,0,0,0,0,0,0,0
0,0,0,0,0,0,0,0,0,0,0,0,0
0,0,0,0,0,0,0,0,0,0,0,0,0
endlayer

